Workbook

Sheet راهنما
B2: راهنمای فایل پایش اقدامات اصلاحی / پیشگیرانه
B4: ساختار ستون‌ها
B5: ستون‌های اول شیت «ورودی اقدامات» دقیقاً همان ستون‌های گرید سیستم هستند: شماره فرم، نوع، اصلاحی (منشأ)، موضوع عدم تطابق، درخواست‌کننده، نام فرآیند مرتبط، مهلت انجام اقدام، اثر بخشی، نظریه نهایی نماینده مدیریت، شماره اقدام مجدد، تاریخ ایجاد فرم، وضعیت (سیستم) و نسخه. ستون‌های واحد، تاریخ تکمیل، مسئول/نظریه ریشه‌یابی، مسئول اقدام و شرح اقدامات برای تحلیل تکمیلی اضافه شده‌اند.
B7: تاریخ‌ها
B8: همه تاریخ‌ها شمسی و به‌صورت متن سال/ماه/روز وارد می‌شوند (مثال 1404/7/4). تبدیل به میلادی برای محاسبه تاخیر به‌صورت خودکار و در ستون‌های پنهان (W تا AJ) انجام می‌شود.
B10: وضعیت پایش (خودکار)
B11: «بسته»: ستون اثر بخشی پر باشد یا تاریخ تکمیل ثبت شده باشد. «تاخیر»: مهلت گذشته و بسته نشده. «در حال انجام»: بقیه. این ستون با ستون «وضعیت (سیستم)» که مرحله گردش‌کار در سیستم است فرق دارد.
B13: اثر بخشی
B14: مقدارهای «می‌باشد»، «نمی‌باشد» و «تایید» مطابق مقادیر دیده‌شده در سیستم است و هر مقدار ثبت‌شده، اقدام را بسته می‌کند. اگر معنای «می‌باشد» در سیستم شما متفاوت است، فرمول ستون U را اصلاح کنید.
B16: لیست‌ها و داشبورد
B17: فهرست‌های کشویی از شیت «لیست‌ها» می‌آیند (ستون‌های P تا T پنهان و فقط برای تقویم شمسی است). داشبورد به‌صورت خودکار به‌روز می‌شود. ظرفیت فایل ۱۲۰۰ ردیف است. این فایل فقط اقدامات سال ۱۴۰۵ را شامل می‌شود.
B19: داشبورد مدیریتی
B20: بالای داشبورد یک جمله خلاصه خودکار (خلاصه مدیریتی)، شاخص‌های کلیدی، جدول «۱۰ اقدام با بیشترین تاخیر» برای پیگیری فوری و تفکیک تاخیرها بر اساس مدت (۱ تا ۳۰، ۳۱ تا ۶۰، ۶۱ تا ۹۰ و بیش از ۹۰ روز) اضافه شده است. این شیت برای چاپ/خروجی PDF تنظیم شده (Landscape، تناسب با عرض صفحه) — کافیست از منوی File در اکسل گزینه Export یا Print to PDF را روی همین شیت بزنید.

Sheet ورودی اقدامات
A1: پایش اقدامات اصلاحی / پیشگیرانه — ستون‌ها مطابق گرید سیستم «فرم اقدام اصلاحی/پیشگیرانه»
A2: خودکار | B2: ورودی | C2: ورودی | D2: ورودی | E2: ورودی | F2: ورودی | G2: ورودی | H2: ورودی | I2: ورودی | J2: ورودی | K2: ورودی | L2: ورودی | M2: ورودی | N2: ورودی | O2: ورودی | P2: ورودی | Q2: ورودی | R2: ورودی | S2: ورودی | T2: ورودی | U2: خودکار | V2: خودکار
A3: ردیف | B3: شماره فرم | C3: نوع | D3: اصلاحی (منشأ) | E3: موضوع عدم تطابق | F3: درخواست‌کننده | G3: نام فرآیند مرتبط | H3: مهلت انجام اقدام | I3: اثر بخشی | J3: نظریه نهایی نماینده مدیریت | K3: شماره اقدام مجدد | L3: تاریخ ایجاد فرم | M3: وضعیت (سیستم) | N3: نسخه | O3: واحد درخواست‌کننده | P3: تاریخ تکمیل اقدام | Q3: مسئول ریشه‌یابی | R3: نظریه ریشه‌یابی | S3: مسئول اقدام | T3: شرح اقدامات | U3: وضعیت پایش | V3: روزهای تاخیر
A4: =IF(B4="","",ROW()-3) -> 1 | B4: PL\05\1 | C4: اقدام اصلاحی | D4: سایر | E4: انحراف از مصرف مواد smc به میزان2.2... | F4: حمید بیات | G4: برنامه‌ریزی | L4: 1405/1/19 | M4: جهت اطلاع | U4: =IF(B4="","",IF(OR(P4<>"",I4="می‌باشد"),"بسته",IF(AND(L4<>"",W4=""),"خطای فرمت تاریخ ایجاد",IF(AND(H4<>"",AA4=""),"خطای فرمت مهلت",IF(AND(H4<>"",AD4<>"",TODAY()>AD4),"تاخیر",IF(L4<>"","در حال انجام","")))))) -> در حال انجام | V4: =IF(U4="تاخیر",TODAY()-AD4,IF(AND(U4="بسته",AH4<>"",AD4<>"",AH4>AD4),AH4-AD4,0)) -> 0 | W4: =IF(L4="","",VALUE(LEFT(L4,FIND("/",L4)-1))) -> 1405 | X4: =IF(L4="","",VALUE(MID(L4,FIND("/",L4)+1,FIND("/",L4,FIND("/",L4)+1)-FIND("/",L4)-1))) -> 1 | Y4: =IF(L4="","",VALUE(MID(L4,FIND("/",L4,FIND("/",L4)+1)+1,LEN(L4)-FIND("/",L4,FIND("/",L4)+1)))) -> 19 | Z4: =IF(OR(L4="",W4=""),"",IFERROR(INDEX('لیست‌ها'!$Q$3:$Q$53,MATCH(W4,'لیست‌ها'!$P$3:$P$53,0))+IF(X4<=6,(X4-1)*31+Y4,IF(X4<=11,186+(X4-7)*30+Y4,336+Y4))-1,"")) -> 46120 | AA4: =IF(H4="","",VALUE(LEFT(H4,FIND("/",H4)-1))) | AB4: =IF(H4="","",VALUE(MID(H4,FIND("/",H4)+1,FIND("/",H4,FIND("/",H4)+1)-FIND("/",H4)-1))) | AC4: =IF(H4="","",VALUE(MID(H4,FIND("/",H4,FIND("/",H4)+1)+1,LEN(H4)-FIND("/",H4,FIND("/",H4)+1)))) | AD4: =IF(OR(H4="",AA4=""),"",IFERROR(INDEX('لیست‌ها'!$Q$3:$Q$53,MATCH(AA4,'لیست‌ها'!$P$3:$P$53,0))+IF(AB4<=6,(AB4-1)*31+AC4,IF(AB4<=11,186+(AB4-7)*30+AC4,336+AC4))-1,"")) | AE4: =IF(P4="","",VALUE(LEFT(P4,FIND("/",P4)-1))) | AF4: =IF(P4="","",VALUE(MID(P4,FIND("/",P4)+1,FIND("/",P4,FIND("/",P4)+1)-FIND("/",P4)-1))) | AG4: =IF(P4="","",VALUE(MID(P4,FIND("/",P4,FIND("/",P4)+1)+1,LEN(P4)-FIND("/",P4,FIND("/",P4)+1)))) | AH4: =IF(OR(P4="",AE4=""),"",IFERROR(INDEX('لیست‌ها'!$Q$3:$Q$53,MATCH(AE4,'لیست‌ها'!$P$3:$P$53,0))+IF(AF4<=6,(AF4-1)*31+AG4,IF(AF4<=11,186+(AF4-7)*30+AG4,336+AG4))-1,"")) | AI4: =IF(W4="","",W4&"-"&TEXT(X4,"00")) -> 1405-01 | AJ4: =IF(W4="","",W4*12+X4) -> 16861 | AK4: =IF(U4="تاخیر",V4+ROW()/100000,"")
A5: =IF(B5="","",ROW()-3) -> 2 | B5: SALE\05\2 | C5: اقدام اصلاحی | D5: کلیم | E5: کلیم 1 قطعه سینی فن سمند در سایت کر... | F5: میلاد زارع | G5: بازرسی آزمون | H5: 1405/2/31 | I5: می‌باشد | L5: 1405/1/22 | M5: جهت اطلاع | U5: =IF(B5="","",IF(OR(P5<>"",I5="می‌باشد"),"بسته",IF(AND(L5<>"",W5=""),"خطای فرمت تاریخ ایجاد",IF(AND(H5<>"",AA5=""),"خطای فرمت مهلت",IF(AND(H5<>"",AD5<>"",TODAY()>AD5),"تاخیر",IF(L5<>"","در حال انجام","")))))) -> بسته | V5: =IF(U5="تاخیر",TODAY()-AD5,IF(AND(U5="بسته",AH5<>"",AD5<>"",AH5>AD5),AH5-AD5,0)) -> 0 | W5: =IF(L5="","",VALUE(LEFT(L5,FIND("/",L5)-1))) -> 1405 | X5: =IF(L5="","",VALUE(MID(L5,FIND("/",L5)+1,FIND("/",L5,FIND("/",L5)+1)-FIND("/",L5)-1))) -> 1 | Y5: =IF(L5="","",VALUE(MID(L5,FIND("/",L5,FIND("/",L5)+1)+1,LEN(L5)-FIND("/",L5,FIND("/",L5)+1)))) -> 22 | Z5: =IF(OR(L5="",W5=""),"",IFERROR(INDEX('لیست‌ها'!$Q$3:$Q$53,MATCH(W5,'لیست‌ها'!$P$3:$P$53,0))+IF(X5<=6,(X5-1)*31+Y5,IF(X5<=11,186+(X5-7)*30+Y5,336+Y5))-1,"")) -> 46123 | AA5: =IF(H5="","",VALUE(LEFT(H5,FIND("/",H5)-1))) -> 1405 | AB5: =IF(H5="","",VALUE(MID(H5,FIND("/",H5)+1,FIND("/",H5,FIND("/",H5)+1)-FIND("/",H5)-1))) -> 2 | AC5: =IF(H5="","",VALUE(MID(H5,FIND("/",H5,FIND("/",H5)+1)+1,LEN(H5)-FIND("/",H5,FIND("/",H5)+1)))) -> 31 | AD5: =IF(OR(H5="",AA5=""),"",IFERROR(INDEX('لیست‌ها'!$Q$3:$Q$53,MATCH(AA5,'لیست‌ها'!$P$3:$P$53,0))+IF(AB5<=6,(AB5-1)*31+AC5,IF(AB5<=11,186+(AB5-7)*30+AC5,336+AC5))-1,"")) -> 46163 | AE5: =IF(P5="","",VALUE(LEFT(P5,FIND("/",P5)-1))) | AF5: =IF(P5="","",VALUE(MID(P5,FIND("/",P5)+1,FIND("/",P5,FIND("/",P5)+1)-FIND("/",P5)-1))) | AG5: =IF(P5="","",VALUE(MID(P5,FIND("/",P5,FIND("/",P5)+1)+1,LEN(P5)-FIND("/",P5,FIND("/",P5)+1)))) | AH5: =IF(OR(P5="",AE5=""),"",IFERROR(INDEX('لیست‌ها'!$Q$3:$Q$53,MATCH(AE5,'لیست‌ها'!$P$3:$P$53,0))+IF(AF5<=6,(AF5-1)*31+AG5,IF(AF5<=11,186+(AF5-7)*30+AG5,336+AG5))-1,"")) | AI5: =IF(W5="","",W5&"-"&TEXT(X5,"00")) -> 1405-01 | AJ5: =IF(W5="","",W5*12+X5) -> 16861 | AK5: =IF(U5="تاخیر",V5+ROW()/100000,"")
A6: =IF(B6="","",ROW()-3) -> 3 | B6: SALE\05\3 | C6: اقدام اصلاحی | D6: کلیم | E6: کلیم 1 قطعه سینی فن سمند در سایت ته... | F6: میلاد زارع | G6: بازرسی آزمون | H6: 1405/2/31 | I6: می‌باشد | L6: 1405/1/22 | M6: جهت اطلاع | U6: =IF(B6="","",IF(OR(P6<>"",I6="می‌باشد"),"بسته",IF(AND(L6<>"",W6=""),"خطای فرمت تاریخ ایجاد",IF(AND(H6<>"",AA6=""),"خطای فرمت مهلت",IF(AND(H6<>"",AD6<>"",TODAY()>AD6),"تاخیر",IF(L6<>"","در حال انجام","")))))) -> بسته | V6: =IF(U6="تاخیر",TODAY()-AD6,IF(AND(U6="بسته",AH6<>"",AD6<>"",AH6>AD6),AH6-AD6,0)) -> 0 | W6: =IF(L6="","",VALUE(LEFT(L6,FIND("/",L6)-1))) -> 1405 | X6: =IF(L6="","",VALUE(MID(L6,FIND("/",L6)+1,FIND("/",L6,FIND("/",L6)+1)-FIND("/",L6)-1))) -> 1 | Y6: =IF(L6="","",VALUE(MID(L6,FIND("/",L6,FIND("/",L6)+1)+1,LEN(L6)-FIND("/",L6,FIND("/",L6)+1)))) -> 22 | Z6: =IF(OR(L6="",W6=""),"",IFERROR(INDEX('لیست‌ها'!$Q$3:$Q$53,MATCH(W6,'لیست‌ها'!$P$3:$P$53,0))+IF(X6<=6,(X6-1)*31+Y6,IF(X6<=11,186+(X6-7)*30+Y6,336+Y6))-1,"")) -> 46123 | AA6: =IF(H6="","",VALUE(LEFT(H6,FIND("/",H6)-1))) -> 1405 | AB6: =IF(H6="","",VALUE(MID(H6,FIND("/",H6)+1,FIND("/",H6,FIND("/",H6)+1)-FIND("/",H6)-1))) -> 2 | AC6: =IF(H6="","",VALUE(MID(H6,FIND("/",H6,FIND("/",H6)+1)+1,LEN(H6)-FIND("/",H6,FIND("/",H6)+1)))) -> 31 | AD6: =IF(OR(H6="",AA6=""),"",IFERROR(INDEX('لیست‌ها'!$Q$3:$Q$53,MATCH(AA6,'لیست‌ها'!$P$3:$P$53,0))+IF(AB6<=6,(AB6-1)*31+AC6,IF(AB6<=11,186+(AB6-7)*30+AC6,336+AC6))-1,"")) -> 46163 | AE6: =IF(P6="","",VALUE(LEFT(P6,FIND("/",P6)-1))) | AF6: =IF(P6="","",VALUE(MID(P6,FIND("/",P6)+1,FIND("/",P6,FIND("/",P6)+1)-FIND("/",P6)-1))) | AG6: =IF(P6="","",VALUE(MID(P6,FIND("/",P6,FIND("/",P6)+1)+1,LEN(P6)-FIND("/",P6,FIND("/",P6)+1)))) | AH6: =IF(OR(P6="",AE6=""),"",IFERROR(INDEX('لیست‌ها'!$Q$3:$Q$53,MATCH(AE6,'لیست‌ها'!$P$3:$P$53,0))+IF(AF6<=6,(AF6-1)*31+AG6,IF(AF6<=11,186+(AF6-7)*30+AG6,336+AG6))-1,"")) | AI6: =IF(W6="","",W6&"-"&TEXT(X6,"00")) -> 1405-01 | AJ6: =IF(W6="","",W6*12+X6) -> 16861 | AK6: =IF(U6="تاخیر",V6+ROW()/100000,"")
A7: =IF(B7="","",ROW()-3) -> 4 | B7: SALE\05\4 | C7: اقدام اصلاحی | D7: کلیم | E7: کلیم 6 قطعه سینی فن سمند در سایت ته... | F7: میلاد زارع | G7: بازرسی آزمون | H7: 1405/2/20 | I7: می‌باشد | L7: 1405/1/24 | M7: جهت اطلاع | U7: =IF(B7="","",IF(OR(P7<>"",I7="می‌باشد"),"بسته",IF(AND(L7<>"",W7=""),"خطای فرمت تاریخ ایجاد",IF(AND(H7<>"",AA7=""),"خطای فرمت مهلت",IF(AND(H7<>"",AD7<>"",TODAY()>AD7),"تاخیر",IF(L7<>"","در حال انجام","")))))) -> بسته | V7: =IF(U7="تاخیر",TODAY()-AD7,IF(AND(U7="بسته",AH7<>"",AD7<>"",AH7>AD7),AH7-AD7,0)) -> 0 | W7: =IF(L7="","",VALUE(LEFT(L7,FIND("/",L7)-1))) -> 1405 | X7: =IF(L7="","",VALUE(MID(L7,FIND("/",L7)+1,FIND("/",L7,FIND("/",L7)+1)-FIND("/",L7)-1))) -> 1 | Y7: =IF(L7="","",VALUE(MID(L7,FIND("/",L7,FIND("/",L7)+1)+1,LEN(L7)-FIND("/",L7,FIND("/",L7)+1)))) -> 24 | Z7: =IF(OR(L7="",W7=""),"",IFERROR(INDEX('لیست‌ها'!$Q$3:$Q$53,MATCH(W7,'لیست‌ها'!$P$3:$P$53,0))+IF(X7<=6,(X7-1)*31+Y7,IF(X7<=11,186+(X7-7)*30+Y7,336+Y7))-1,"")) -> 46125 | AA7: =IF(H7="","",VALUE(LEFT(H7,FIND("/",H7)-1))) -> 1405 | AB7: =IF(H7="","",VALUE(MID(H7,FIND("/",H7)+1,FIND("/",H7,FIND("/",H7)+1)-FIND("/",H7)-1))) -> 2 | AC7: =IF(H7="","",VALUE(MID(H7,FIND("/",H7,FIND("/",H7)+1)+1,LEN(H7)-FIND("/",H7,FIND("/",H7)+1)))) -> 20 | AD7: =IF(OR(H7="",AA7=""),"",IFERROR(INDEX('لیست‌ها'!$Q$3:$Q$53,MATCH(AA7,'لیست‌ها'!$P$3:$P$53,0))+IF(AB7<=6,(AB7-1)*31+AC7,IF(AB7<=11,186+(AB7-7)*30+AC7,336+AC7))-1,"")) -> 46152 | AE7: =IF(P7="","",VALUE(LEFT(P7,FIND("/",P7)-1))) | AF7: =IF(P7="","",VALUE(MID(P7,FIND("/",P7)+1,FIND("/",P7,FIND("/",P7)+1)-FIND("/",P7)-1))) | AG7: =IF(P7="","",VALUE(MID(P7,FIND("/",P7,FIND("/",P7)+1)+1,LEN(P7)-FIND("/",P7,FIND("/",P7)+1)))) | AH7: =IF(OR(P7="",AE7=""),"",IFERROR(INDEX('لیست‌ها'!$Q$3:$Q$53,MATCH(AE7,'لیست‌ها'!$P$3:$P$53,0))+IF(AF7<=6,(AF7-1)*31+AG7,IF(AF7<=11,186+(AF7-7)*30+AG7,336+AG7))-1,"")) | AI7: =IF(W7="","",W7&"-"&TEXT(X7,"00")) -> 1405-01 | AJ7: =IF(W7="","",W7*12+X7) -> 16861 | AK7: =IF(U7="تاخیر",V7+ROW()/100000,"")
A8: =IF(B8="","",ROW()-3) -> 5 | B8: SALE\05\5 | C8: اقدام اصلاحی | D8: کلیم | E8: کلیم 40 قطعه سینی فن 206 پلاس در... | F8: میلاد زارع | G8: بازرسی آزمون | H8: 1405/2/15 | I8: می‌باشد | L8: 1405/1/24 | M8: جهت اطلاع | U8: =IF(B8="","",IF(OR(P8<>"",I8="می‌باشد"),"بسته",IF(AND(L8<>"",W8=""),"خطای فرمت تاریخ ایجاد",IF(AND(H8<>"",AA8=""),"خطای فرمت مهلت",IF(AND(H8<>"",AD8<>"",TODAY()>AD8),"تاخیر",IF(L8<>"","در حال انجام","")))))) -> بسته | V8: =IF(U8="تاخیر",TODAY()-AD8,IF(AND(U8="بسته",AH8<>"",AD8<>"",AH8>AD8),AH8-AD8,0)) -> 0 | W8: =IF(L8="","",VALUE(LEFT(L8,FIND("/",L8)-1))) -> 1405 | X8: =IF(L8="","",VALUE(MID(L8,FIND("/",L8)+1,FIND("/",L8,FIND("/",L8)+1)-FIND("/",L8)-1))) -> 1 | Y8: =IF(L8="","",VALUE(MID(L8,FIND("/",L8,FIND("/",L8)+1)+1,LEN(L8)-FIND("/",L8,FIND("/",L8)+1)))) -> 24 | Z8: =IF(OR(L8="",W8=""),"",IFERROR(INDEX('لیست‌ها'!$Q$3:$Q$53,MATCH(W8,'لیست‌ها'!$P$3:$P$53,0))+IF(X8<=6,(X8-1)*31+Y8,IF(X8<=11,186+(X8-7)*30+Y8,336+Y8))-1,"")) -> 46125 | AA8: =IF(H8="","",VALUE(LEFT(H8,FIND("/",H8)-1))) -> 1405 | AB8: =IF(H8="","",VALUE(MID(H8,FIND("/",H8)+1,FIND("/",H8,FIND("/",H8)+1)-FIND("/",H8)-1))) -> 2 | AC8: =IF(H8="","",VALUE(MID(H8,FIND("/",H8,FIND("/",H8)+1)+1,LEN(H8)-FIND("/",H8,FIND("/",H8)+1)))) -> 15 | AD8: =IF(OR(H8="",AA8=""),"",IFERROR(INDEX('لیست‌ها'!$Q$3:$Q$53,MATCH(AA8,'لیست‌ها'!$P$3:$P$53,0))+IF(AB8<=6,(AB8-1)*31+AC8,IF(AB8<=11,186+(AB8-7)*30+AC8,336+AC8))-1,"")) -> 46147 | AE8: =IF(P8="","",VALUE(LEFT(P8,FIND("/",P8)-1))) | AF8: =IF(P8="","",VALUE(MID(P8,FIND("/",P8)+1,FIND("/",P8,FIND("/",P8)+1)-FIND("/",P8)-1))) | AG8: =IF(P8="","",VALUE(MID(P8,FIND("/",P8,FIND("/",P8)+1)+1,LEN(P8)-FIND("/",P8,FIND("/",P8)+1)))) | AH8: =IF(OR(P8="",AE8=""),"",IFERROR(INDEX('لیست‌ها'!$Q$3:$Q$53,MATCH(AE8,'لیست‌ها'!$P$3:$P$53,0))+IF(AF8<=6,(AF8-1)*31+AG8,IF(AF8<=11,186+(AF8-7)*30+AG8,336+AG8))-1,"")) | AI8: =IF(W8="","",W8&"-"&TEXT(X8,"00")) -> 1405-01 | AJ8: =IF(W8="","",W8*12+X8) -> 16861 | AK8: =IF(U8="تاخیر",V8+ROW()/100000,"")
A9: =IF(B9="","",ROW()-3) -> 6 | B9: SALE\05\6 | C9: اقدام اصلاحی | D9: کلیم | E9: کلیم 1 قطعه سینی فن دنا پلاس توربو... | F9: میلاد زارع | G9: بازرسی آزمون | H9: 1405/2/31 | I9: می‌باشد | L9: 1405/1/24 | M9: جهت اطلاع | U9: =IF(B9="","",IF(OR(P9<>"",I9="می‌باشد"),"بسته",IF(AND(L9<>"",W9=""),"خطای فرمت تاریخ ایجاد",IF(AND(H9<>"",AA9=""),"خطای فرمت مهلت",IF(AND(H9<>"",AD9<>"",TODAY()>AD9),"تاخیر",IF(L9<>"","در حال انجام","")))))) -> بسته | V9: =IF(U9="تاخیر",TODAY()-AD9,IF(AND(U9="بسته",AH9<>"",AD9<>"",AH9>AD9),AH9-AD9,0)) -> 0 | W9: =IF(L9="","",VALUE(LEFT(L9,FIND("/",L9)-1))) -> 1405 | X9: =IF(L9="","",VALUE(MID(L9,FIND("/",L9)+1,FIND("/",L9,FIND("/",L9)+1)-FIND("/",L9)-1))) -> 1 | Y9: =IF(L9="","",VALUE(MID(L9,FIND("/",L9,FIND("/",L9)+1)+1,LEN(L9)-FIND("/",L9,FIND("/",L9)+1)))) -> 24 | Z9: =IF(OR(L9="",W9=""),"",IFERROR(INDEX('لیست‌ها'!$Q$3:$Q$53,MATCH(W9,'لیست‌ها'!$P$3:$P$53,0))+IF(X9<=6,(X9-1)*31+Y9,IF(X9<=11,186+(X9-7)*30+Y9,336+Y9))-1,"")) -> 46125 | AA9: =IF(H9="","",VALUE(LEFT(H9,FIND("/",H9)-1))) -> 1405 | AB9: =IF(H9="","",VALUE(MID(H9,FIND("/",H9)+1,FIND("/",H9,FIND("/",H9)+1)-FIND("/",H9)-1))) -> 2 | AC9: =IF(H9="","",VALUE(MID(H9,FIND("/",H9,FIND("/",H9)+1)+1,LEN(H9)-FIND("/",H9,FIND("/",H9)+1)))) -> 31 | AD9: =IF(OR(H9="",AA9=""),"",IFERROR(INDEX('لیست‌ها'!$Q$3:$Q$53,MATCH(AA9,'لیست‌ها'!$P$3:$P$53,0))+IF(AB9<=6,(AB9-1)*31+AC9,IF(AB9<=11,186+(AB9-7)*30+AC9,336+AC9))-1,"")) -> 46163 | AE9: =IF(P9="","",VALUE(LEFT(P9,FIND("/",P9)-1))) | AF9: =IF(P9="","",VALUE(MID(P9,FIND("/",P9)+1,FIND("/",P9,FIND("/",P9)+1)-FIND("/",P9)-1))) | AG9: =IF(P9="","",VALUE(MID(P9,FIND("/",P9,FIND("/",P9)+1)+1,LEN(P9)-FIND("/",P9,FIND("/",P9)+1)))) | AH9: =IF(OR(P9="",AE9=""),"",IFERROR(INDEX('لیست‌ها'!$Q$3:$Q$53,MATCH(AE9,'لیست‌ها'!$P$3:$P$53,0))+IF(AF9<=6,(AF9-1)*31+AG9,IF(AF9<=11,186+(AF9-7)*30+AG9,336+AG9))-1,"")) | AI9: =IF(W9="","",W9&"-"&TEXT(X9,"00")) -> 1405-01 | AJ9: =IF(W9="","",W9*12+X9) -> 16861 | AK9: =IF(U9="تاخیر",V9+ROW()/100000,"")
A10: =IF(B10="","",ROW()-3) -> 7 | B10: SALE\05\7 | C10: اقدام اصلاحی | D10: کلیم | E10: کلیم 4 قطعه سینی فن دنا در سایت تهر... | F10: میلاد زارع | G10: بازرسی آزمون | H10: 1405/2/31 | I10: می‌باشد | L10: 1405/1/24 | M10: جهت اطلاع | U10: =IF(B10="","",IF(OR(P10<>"",I10="می‌باشد"),"بسته",IF(AND(L10<>"",W10=""),"خطای فرمت تاریخ ایجاد",IF(AND(H10<>"",AA10=""),"خطای فرمت مهلت",IF(AND(H10<>"",AD10<>"",TODAY()>AD10),"تاخیر",IF(L10<>"","در حال انجام","")))))) -> بسته | V10: =IF(U10="تاخیر",TODAY()-AD10,IF(AND(U10="بسته",AH10<>"",AD10<>"",AH10>AD10),AH10-AD10,0)) -> 0 | W10: =IF(L10="","",VALUE(LEFT(L10,FIND("/",L10)-1))) -> 1405 | X10: =IF(L10="","",VALUE(MID(L10,FIND("/",L10)+1,FIND("/",L10,FIND("/",L10)+1)-FIND("/",L10)-1))) -> 1 | Y10: =IF(L10="","",VALUE(MID(L10,FIND("/",L10,FIND("/",L10)+1)+1,LEN(L10)-FIND("/",L10,FIND("/",L10)+1)))) -> 24 | Z10: =IF(OR(L10="",W10=""),"",IFERROR(INDEX('لیست‌ها'!$Q$3:$Q$53,MATCH(W10,'لیست‌ها'!$P$3:$P$53,0))+IF(X10<=6,(X10-1)*31+Y10,IF(X10<=11,186+(X10-7)*30+Y10,336+Y10))-1,"")) -> 46125 | AA10: =IF(H10="","",VALUE(LEFT(H10,FIND("/",H10)-1))) -> 1405 | AB10: =IF(H10="","",VALUE(MID(H10,FIND("/",H10)+1,FIND("/",H10,FIND("/",H10)+1)-FIND("/",H10)-1))) -> 2 | AC10: =IF(H10="","",VALUE(MID(H10,FIND("/",H10,FIND("/",H10)+1)+1,LEN(H10)-FIND("/",H10,FIND("/",H10)+1)))) -> 31 | AD10: =IF(OR(H10="",AA10=""),"",IFERROR(INDEX('لیست‌ها'!$Q$3:$Q$53,MATCH(AA10,'لیست‌ها'!$P$3:$P$53,0))+IF(AB10<=6,(AB10-1)*31+AC10,IF(AB10<=11,186+(AB10-7)*30+AC10,336+AC10))-1,"")) -> 46163 | AE10: =IF(P10="","",VALUE(LEFT(P10,FIND("/",P10)-1))) | AF10: =IF(P10="","",VALUE(MID(P10,FIND("/",P10)+1,FIND("/",P10,FIND("/",P10)+1)-FIND("/",P10)-1))) | AG10: =IF(P10="","",VALUE(MID(P10,FIND("/",P10,FIND("/",P10)+1)+1,LEN(P10)-FIND("/",P10,FIND("/",P10)+1)))) | AH10: =IF(OR(P10="",AE10=""),"",IFERROR(INDEX('لیست‌ها'!$Q$3:$Q$53,MATCH(AE10,'لیست‌ها'!$P$3:$P$53,0))+IF(AF10<=6,(AF10-1)*31+AG10,IF(AF10<=11,186+(AF10-7)*30+AG10,336+AG10))-1,"")) | AI10: =IF(W10="","",W10&"-"&TEXT(X10,"00")) -> 1405-01 | AJ10: =IF(W10="","",W10*12+X10) -> 16861 | AK10: =IF(U10="تاخیر",V10+ROW()/100000,"")
A11: =IF(B11="","",ROW()-3) -> 8 | B11: SALE\05\8 | C11: اقدام اصلاحی | D11: کلیم | E11: کلیم 1 قطعه سینی زیرموتور XU در سایت... | F11: میلاد زارع | G11: بازرسی آزمون | H11: 1405/2/15 | L11: 1405/1/24 | M11: نظریه مسئول اقدام | U11: =IF(B11="","",IF(OR(P11<>"",I11="می‌باشد"),"بسته",IF(AND(L11<>"",W11=""),"خطای فرمت تاریخ ایجاد",IF(AND(H11<>"",AA11=""),"خطای فرمت مهلت",IF(AND(H11<>"",AD11<>"",TODAY()>AD11),"تاخیر",IF(L11<>"","در حال انجام","")))))) -> تاخیر | V11: =IF(U11="تاخیر",TODAY()-AD11,IF(AND(U11="بسته",AH11<>"",AD11<>"",AH11>AD11),AH11-AD11,0)) -> 148 | W11: =IF(L11="","",VALUE(LEFT(L11,FIND("/",L11)-1))) -> 1405 | X11: =IF(L11="","",VALUE(MID(L11,FIND("/",L11)+1,FIND("/",L11,FIND("/",L11)+1)-FIND("/",L11)-1))) -> 1 | Y11: =IF(L11="","",VALUE(MID(L11,FIND("/",L11,FIND("/",L11)+1)+1,LEN(L11)-FIND("/",L11,FIND("/",L11)+1)))) -> 24 | Z11: =IF(OR(L11="",W11=""),"",IFERROR(INDEX('لیست‌ها'!$Q$3:$Q$53,MATCH(W11,'لیست‌ها'!$P$3:$P$53,0))+IF(X11<=6,(X11-1)*31+Y11,IF(X11<=11,186+(X11-7)*30+Y11,336+Y11))-1,"")) -> 46125 | AA11: =IF(H11="","",VALUE(LEFT(H11,FIND("/",H11)-1))) -> 1405 | AB11: =IF(H11="","",VALUE(MID(H11,FIND("/",H11)+1,FIND("/",H11,FIND("/",H11)+1)-FIND("/",H11)-1))) -> 2 | AC11: =IF(H11="","",VALUE(MID(H11,FIND("/",H11,FIND("/",H11)+1)+1,LEN(H11)-FIND("/",H11,FIND("/",H11)+1)))) -> 15 | AD11: =IF(OR(H11="",AA11=""),"",IFERROR(INDEX('لیست‌ها'!$Q$3:$Q$53,MATCH(AA11,'لیست‌ها'!$P$3:$P$53,0))+IF(AB11<=6,(AB11-1)*31+AC11,IF(AB11<=11,186+(AB11-7)*30+AC11,336+AC11))-1,"")) -> 46147 | AE11: =IF(P11="","",VALUE(LEFT(P11,FIND("/",P11)-1))) | AF11: =IF(P11="","",VALUE(MID(P11,FIND("/",P11)+1,FIND("/",P11,FIND("/",P11)+1)-FIND("/",P11)-1))) | AG11: =IF(P11="","",VALUE(MID(P11,FIND("/",P11,FIND("/",P11)+1)+1,LEN(P11)-FIND("/",P11,FIND("/",P11)+1)))) | AH11: =IF(OR(P11="",AE11=""),"",IFERROR(INDEX('لیست‌ها'!$Q$3:$Q$53,MATCH(AE11,'لیست‌ها'!$P$3:$P$53,0))+IF(AF11<=6,(AF11-1)*31+AG11,IF(AF11<=11,186+(AF11-7)*30+AG11,336+AG11))-1,"")) | AI11: =IF(W11="","",W11&"-"&TEXT(X11,"00")) -> 1405-01 | AJ11: =IF(W11="","",W11*12+X11) -> 16861 | AK11: =IF(U11="تاخیر",V11+ROW()/100000,"") -> 148.00011
A12: =IF(B12="","",ROW()-3) -> 9 | B12: SALE\05\9 | C12: اقدام اصلاحی | D12: کلیم | E12: کلیم 4 قطعه سینی نگهدارنده رک را در... | F12: میلاد زارع | G12: بازرسی آزمون | H12: 1405/2/20 | I12: می‌باشد | L12: 1405/1/29 | M12: جهت اطلاع | U12: =IF(B12="","",IF(OR(P12<>"",I12="می‌باشد"),"بسته",IF(AND(L12<>"",W12=""),"خطای فرمت تاریخ ایجاد",IF(AND(H12<>"",AA12=""),"خطای فرمت مهلت",IF(AND(H12<>"",AD12<>"",TODAY()>AD12),"تاخیر",IF(L12<>"","در حال انجام","")))))) -> بسته | V12: =IF(U12="تاخیر",TODAY()-AD12,IF(AND(U12="بسته",AH12<>"",AD12<>"",AH12>AD12),AH12-AD12,0)) -> 0 | W12: =IF(L12="","",VALUE(LEFT(L12,FIND("/",L12)-1))) -> 1405 | X12: =IF(L12="","",VALUE(MID(L12,FIND("/",L12)+1,FIND("/",L12,FIND("/",L12)+1)-FIND("/",L12)-1))) -> 1 | Y12: =IF(L12="","",VALUE(MID(L12,FIND("/",L12,FIND("/",L12)+1)+1,LEN(L12)-FIND("/",L12,FIND("/",L12)+1)))) -> 29 | Z12: =IF(OR(L12="",W12=""),"",IFERROR(INDEX('لیست‌ها'!$Q$3:$Q$53,MATCH(W12,'لیست‌ها'!$P$3:$P$53,0))+IF(X12<=6,(X12-1)*31+Y12,IF(X12<=11,186+(X12-7)*30+Y12,336+Y12))-1,"")) -> 46130 | AA12: =IF(H12="","",VALUE(LEFT(H12,FIND("/",H12)-1))) -> 1405 | AB12: =IF(H12="","",VALUE(MID(H12,FIND("/",H12)+1,FIND("/",H12,FIND("/",H12)+1)-FIND("/",H12)-1))) -> 2 | AC12: =IF(H12="","",VALUE(MID(H12,FIND("/",H12,FIND("/",H12)+1)+1,LEN(H12)-FIND("/",H12,FIND("/",H12)+1)))) -> 20 | AD12: =IF(OR(H12="",AA12=""),"",IFERROR(INDEX('لیست‌ها'!$Q$3:$Q$53,MATCH(AA12,'لیست‌ها'!$P$3:$P$53,0))+IF(AB12<=6,(AB12-1)*31+AC12,IF(AB12<=11,186+(AB12-7)*30+AC12,336+AC12))-1,"")) -> 46152 | AE12: =IF(P12="","",VALUE(LEFT(P12,FIND("/",P12)-1))) | AF12: =IF(P12="","",VALUE(MID(P12,FIND("/",P12)+1,FIND("/",P12,FIND("/",P12)+1)-FIND("/",P12)-1))) | AG12: =IF(P12="","",VALUE(MID(P12,FIND("/",P12,FIND("/",P12)+1)+1,LEN(P12)-FIND("/",P12,FIND("/",P12)+1)))) | AH12: =IF(OR(P12="",AE12=""),"",IFERROR(INDEX('لیست‌ها'!$Q$3:$Q$53,MATCH(AE12,'لیست‌ها'!$P$3:$P$53,0))+IF(AF12<=6,(AF12-1)*31+AG12,IF(AF12<=11,186+(AF12-7)*30+AG12,336+AG12))-1,"")) | AI12: =IF(W12="","",W12&"-"&TEXT(X12,"00")) -> 1405-01 | AJ12: =IF(W12="","",W12*12+X12) -> 16861 | AK12: =IF(U12="تاخیر",V12+ROW()/100000,"")
A13: =IF(B13="","",ROW()-3) -> 10 | B13: SALE\05\10 | C13: اقدام اصلاحی | D13: کلیم | E13: کلیم 1 قطعه سینی زیر موتور تارا (K)... | F13: میلاد زارع | G13: بازرسی آزمون | H13: 1405/2/20 | I13: می‌باشد | L13: 1405/1/30 | M13: جهت اطلاع | U13: =IF(B13="","",IF(OR(P13<>"",I13="می‌باشد"),"بسته",IF(AND(L13<>"",W13=""),"خطای فرمت تاریخ ایجاد",IF(AND(H13<>"",AA13=""),"خطای فرمت مهلت",IF(AND(H13<>"",AD13<>"",TODAY()>AD13),"تاخیر",IF(L13<>"","در حال انجام","")))))) -> بسته | V13: =IF(U13="تاخیر",TODAY()-AD13,IF(AND(U13="بسته",AH13<>"",AD13<>"",AH13>AD13),AH13-AD13,0)) -> 0 | W13: =IF(L13="","",VALUE(LEFT(L13,FIND("/",L13)-1))) -> 1405 | X13: =IF(L13="","",VALUE(MID(L13,FIND("/",L13)+1,FIND("/",L13,FIND("/",L13)+1)-FIND("/",L13)-1))) -> 1 | Y13: =IF(L13="","",VALUE(MID(L13,FIND("/",L13,FIND("/",L13)+1)+1,LEN(L13)-FIND("/",L13,FIND("/",L13)+1)))) -> 30 | Z13: =IF(OR(L13="",W13=""),"",IFERROR(INDEX('لیست‌ها'!$Q$3:$Q$53,MATCH(W13,'لیست‌ها'!$P$3:$P$53,0))+IF(X13<=6,(X13-1)*31+Y13,IF(X13<=11,186+(X13-7)*30+Y13,336+Y13))-1,"")) -> 46131 | AA13: =IF(H13="","",VALUE(LEFT(H13,FIND("/",H13)-1))) -> 1405 | AB13: =IF(H13="","",VALUE(MID(H13,FIND("/",H13)+1,FIND("/",H13,FIND("/",H13)+1)-FIND("/",H13)-1))) -> 2 | AC13: =IF(H13="","",VALUE(MID(H13,FIND("/",H13,FIND("/",H13)+1)+1,LEN(H13)-FIND("/",H13,FIND("/",H13)+1)))) -> 20 | AD13: =IF(OR(H13="",AA13=""),"",IFERROR(INDEX('لیست‌ها'!$Q$3:$Q$53,MATCH(AA13,'لیست‌ها'!$P$3:$P$53,0))+IF(AB13<=6,(AB13-1)*31+AC13,IF(AB13<=11,186+(AB13-7)*30+AC13,336+AC13))-1,"")) -> 46152 | AE13: =IF(P13="","",VALUE(LEFT(P13,FIND("/",P13)-1))) | AF13: =IF(P13="","",VALUE(MID(P13,FIND("/",P13)+1,FIND("/",P13,FIND("/",P13)+1)-FIND("/",P13)-1))) | AG13: =IF(P13="","",VALUE(MID(P13,FIND("/",P13,FIND("/",P13)+1)+1,LEN(P13)-FIND("/",P13,FIND("/",P13)+1)))) | AH13: =IF(OR(P13="",AE13=""),"",IFERROR(INDEX('لیست‌ها'!$Q$3:$Q$53,MATCH(AE13,'لیست‌ها'!$P$3:$P$53,0))+IF(AF13<=6,(AF13-1)*31+AG13,IF(AF13<=11,186+(AF13-7)*30+AG13,336+AG13))-1,"")) | AI13: =IF(W13="","",W13&"-"&TEXT(X13,"00")) -> 1405-01 | AJ13: =IF(W13="","",W13*12+X13) -> 16861 | AK13: =IF(U13="تاخیر",V13+ROW()/100000,"")
A14: =IF(B14="","",ROW()-3) -> 11 | B14: SALE\05\11 | C14: اقدام اصلاحی | D14: کلیم | E14: کلیم 1 قطعه سینی فن سمند در سایت کر... | F14: میلاد زارع | G14: بازرسی آزمون | H14: 1405/2/20 | I14: می‌باشد | L14: 1405/1/31 | M14: جهت اطلاع | U14: =IF(B14="","",IF(OR(P14<>"",I14="می‌باشد"),"بسته",IF(AND(L14<>"",W14=""),"خطای فرمت تاریخ ایجاد",IF(AND(H14<>"",AA14=""),"خطای فرمت مهلت",IF(AND(H14<>"",AD14<>"",TODAY()>AD14),"تاخیر",IF(L14<>"","در حال انجام","")))))) -> بسته | V14: =IF(U14="تاخیر",TODAY()-AD14,IF(AND(U14="بسته",AH14<>"",AD14<>"",AH14>AD14),AH14-AD14,0)) -> 0 | W14: =IF(L14="","",VALUE(LEFT(L14,FIND("/",L14)-1))) -> 1405 | X14: =IF(L14="","",VALUE(MID(L14,FIND("/",L14)+1,FIND("/",L14,FIND("/",L14)+1)-FIND("/",L14)-1))) -> 1 | Y14: =IF(L14="","",VALUE(MID(L14,FIND("/",L14,FIND("/",L14)+1)+1,LEN(L14)-FIND("/",L14,FIND("/",L14)+1)))) -> 31 | Z14: =IF(OR(L14="",W14=""),"",IFERROR(INDEX('لیست‌ها'!$Q$3:$Q$53,MATCH(W14,'لیست‌ها'!$P$3:$P$53,0))+IF(X14<=6,(X14-1)*31+Y14,IF(X14<=11,186+(X14-7)*30+Y14,336+Y14))-1,"")) -> 46132 | AA14: =IF(H14="","",VALUE(LEFT(H14,FIND("/",H14)-1))) -> 1405 | AB14: =IF(H14="","",VALUE(MID(H14,FIND("/",H14)+1,FIND("/",H14,FIND("/",H14)+1)-FIND("/",H14)-1))) -> 2 | AC14: =IF(H14="","",VALUE(MID(H14,FIND("/",H14,FIND("/",H14)+1)+1,LEN(H14)-FIND("/",H14,FIND("/",H14)+1)))) -> 20 | AD14: =IF(OR(H14="",AA14=""),"",IFERROR(INDEX('لیست‌ها'!$Q$3:$Q$53,MATCH(AA14,'لیست‌ها'!$P$3:$P$53,0))+IF(AB14<=6,(AB14-1)*31+AC14,IF(AB14<=11,186+(AB14-7)*30+AC14,336+AC14))-1,"")) -> 46152 | AE14: =IF(P14="","",VALUE(LEFT(P14,FIND("/",P14)-1))) | AF14: =IF(P14="","",VALUE(MID(P14,FIND("/",P14)+1,FIND("/",P14,FIND("/",P14)+1)-FIND("/",P14)-1))) | AG14: =IF(P14="","",VALUE(MID(P14,FIND("/",P14,FIND("/",P14)+1)+1,LEN(P14)-FIND("/",P14,FIND("/",P14)+1)))) | AH14: =IF(OR(P14="",AE14=""),"",IFERROR(INDEX('لیست‌ها'!$Q$3:$Q$53,MATCH(AE14,'لیست‌ها'!$P$3:$P$53,0))+IF(AF14<=6,(AF14-1)*31+AG14,IF(AF14<=11,186+(AF14-7)*30+AG14,336+AG14))-1,"")) | AI14: =IF(W14="","",W14&"-"&TEXT(X14,"00")) -> 1405-01 | AJ14: =IF(W14="","",W14*12+X14) -> 16861 | AK14: =IF(U14="تاخیر",V14+ROW()/100000,"")
A15: =IF(B15="","",ROW()-3) -> 12 | B15: SALE\05\12 | C15: اقدام اصلاحی | D15: کلیم | E15: کلیم 1 قطعه سینی فن سمند در سایت فا... | F15: میلاد زارع | G15: بازرسی آزمون | H15: 1405/2/20 | I15: می‌باشد | L15: 1405/2/1 | M15: جهت اطلاع | U15: =IF(B15="","",IF(OR(P15<>"",I15="می‌باشد"),"بسته",IF(AND(L15<>"",W15=""),"خطای فرمت تاریخ ایجاد",IF(AND(H15<>"",AA15=""),"خطای فرمت مهلت",IF(AND(H15<>"",AD15<>"",TODAY()>AD15),"تاخیر",IF(L15<>"","در حال انجام","")))))) -> بسته | V15: =IF(U15="تاخیر",TODAY()-AD15,IF(AND(U15="بسته",AH15<>"",AD15<>"",AH15>AD15),AH15-AD15,0)) -> 0 | W15: =IF(L15="","",VALUE(LEFT(L15,FIND("/",L15)-1))) -> 1405 | X15: =IF(L15="","",VALUE(MID(L15,FIND("/",L15)+1,FIND("/",L15,FIND("/",L15)+1)-FIND("/",L15)-1))) -> 2 | Y15: =IF(L15="","",VALUE(MID(L15,FIND("/",L15,FIND("/",L15)+1)+1,LEN(L15)-FIND("/",L15,FIND("/",L15)+1)))) -> 1 | Z15: =IF(OR(L15="",W15=""),"",IFERROR(INDEX('لیست‌ها'!$Q$3:$Q$53,MATCH(W15,'لیست‌ها'!$P$3:$P$53,0))+IF(X15<=6,(X15-1)*31+Y15,IF(X15<=11,186+(X15-7)*30+Y15,336+Y15))-1,"")) -> 46133 | AA15: =IF(H15="","",VALUE(LEFT(H15,FIND("/",H15)-1))) -> 1405 | AB15: =IF(H15="","",VALUE(MID(H15,FIND("/",H15)+1,FIND("/",H15,FIND("/",H15)+1)-FIND("/",H15)-1))) -> 2 | AC15: =IF(H15="","",VALUE(MID(H15,FIND("/",H15,FIND("/",H15)+1)+1,LEN(H15)-FIND("/",H15,FIND("/",H15)+1)))) -> 20 | AD15: =IF(OR(H15="",AA15=""),"",IFERROR(INDEX('لیست‌ها'!$Q$3:$Q$53,MATCH(AA15,'لیست‌ها'!$P$3:$P$53,0))+IF(AB15<=6,(AB15-1)*31+AC15,IF(AB15<=11,186+(AB15-7)*30+AC15,336+AC15))-1,"")) -> 46152 | AE15: =IF(P15="","",VALUE(LEFT(P15,FIND("/",P15)-1))) | AF15: =IF(P15="","",VALUE(MID(P15,FIND("/",P15)+1,FIND("/",P15,FIND("/",P15)+1)-FIND("/",P15)-1))) | AG15: =IF(P15="","",VALUE(MID(P15,FIND("/",P15,FIND("/",P15)+1)+1,LEN(P15)-FIND("/",P15,FIND("/",P15)+1)))) | AH15: =IF(OR(P15="",AE15=""),"",IFERROR(INDEX('لیست‌ها'!$Q$3:$Q$53,MATCH(AE15,'لیست‌ها'!$P$3:$P$53,0))+IF(AF15<=6,(AF15-1)*31+AG15,IF(AF15<=11,186+(AF15-7)*30+AG15,336+AG15))-1,"")) | AI15: =IF(W15="","",W15&"-"&TEXT(X15,"00")) -> 1405-02 | AJ15: =IF(W15="","",W15*12+X15) -> 16862 | AK15: =IF(U15="تاخیر",V15+ROW()/100000,"")
A16: =IF(B16="","",ROW()-3) -> 13 | B16: SALE\05\13 | C16: اقدام اصلاحی | D16: کلیم | E16: کلیم 1 قطعه سینی زیرموتور XU در سایت... | F16: میلاد زارع | G16: بازرسی آزمون | H16: 1405/2/20 | I16: می‌باشد | L16: 1405/2/1 | M16: جهت اطلاع | U16: =IF(B16="","",IF(OR(P16<>"",I16="می‌باشد"),"بسته",IF(AND(L16<>"",W16=""),"خطای فرمت تاریخ ایجاد",IF(AND(H16<>"",AA16=""),"خطای فرمت مهلت",IF(AND(H16<>"",AD16<>"",TODAY()>AD16),"تاخیر",IF(L16<>"","در حال انجام","")))))) -> بسته | V16: =IF(U16="تاخیر",TODAY()-AD16,IF(AND(U16="بسته",AH16<>"",AD16<>"",AH16>AD16),AH16-AD16,0)) -> 0 | W16: =IF(L16="","",VALUE(LEFT(L16,FIND("/",L16)-1))) -> 1405 | X16: =IF(L16="","",VALUE(MID(L16,FIND("/",L16)+1,FIND("/",L16,FIND("/",L16)+1)-FIND("/",L16)-1))) -> 2 | Y16: =IF(L16="","",VALUE(MID(L16,FIND("/",L16,FIND("/",L16)+1)+1,LEN(L16)-FIND("/",L16,FIND("/",L16)+1)))) -> 1 | Z16: =IF(OR(L16="",W16=""),"",IFERROR(INDEX('لیست‌ها'!$Q$3:$Q$53,MATCH(W16,'لیست‌ها'!$P$3:$P$53,0))+IF(X16<=6,(X16-1)*31+Y16,IF(X16<=11,186+(X16-7)*30+Y16,336+Y16))-1,"")) -> 46133 | AA16: =IF(H16="","",VALUE(LEFT(H16,FIND("/",H16)-1))) -> 1405 | AB16: =IF(H16="","",VALUE(MID(H16,FIND("/",H16)+1,FIND("/",H16,FIND("/",H16)+1)-FIND("/",H16)-1))) -> 2 | AC16: =IF(H16="","",VALUE(MID(H16,FIND("/",H16,FIND("/",H16)+1)+1,LEN(H16)-FIND("/",H16,FIND("/",H16)+1)))) -> 20 | AD16: =IF(OR(H16="",AA16=""),"",IFERROR(INDEX('لیست‌ها'!$Q$3:$Q$53,MATCH(AA16,'لیست‌ها'!$P$3:$P$53,0))+IF(AB16<=6,(AB16-1)*31+AC16,IF(AB16<=11,186+(AB16-7)*30+AC16,336+AC16))-1,"")) -> 46152 | AE16: =IF(P16="","",VALUE(LEFT(P16,FIND("/",P16)-1))) | AF16: =IF(P16="","",VALUE(MID(P16,FIND("/",P16)+1,FIND("/",P16,FIND("/",P16)+1)-FIND("/",P16)-1))) | AG16: =IF(P16="","",VALUE(MID(P16,FIND("/",P16,FIND("/",P16)+1)+1,LEN(P16)-FIND("/",P16,FIND("/",P16)+1)))) | AH16: =IF(OR(P16="",AE16=""),"",IFERROR(INDEX('لیست‌ها'!$Q$3:$Q$53,MATCH(AE16,'لیست‌ها'!$P$3:$P$53,0))+IF(AF16<=6,(AF16-1)*31+AG16,IF(AF16<=11,186+(AF16-7)*30+AG16,336+AG16))-1,"")) | AI16: =IF(W16="","",W16&"-"&TEXT(X16,"00")) -> 1405-02 | AJ16: =IF(W16="","",W16*12+X16) -> 16862 | AK16: =IF(U16="تاخیر",V16+ROW()/100000,"")
A17: =IF(B17="","",ROW()-3) -> 14 | B17: PL\05\14 | C17: اقدام پیشگیرانه | D17: کلیم | E17: توقف خط به علت نبود منابع (خار کنسو...) | F17: حمید بیات | G17: برنامه‌ریزی | L17: 1405/2/2 | M17: ثبت فرم | U17: =IF(B17="","",IF(OR(P17<>"",I17="می‌باشد"),"بسته",IF(AND(L17<>"",W17=""),"خطای فرمت تاریخ ایجاد",IF(AND(H17<>"",AA17=""),"خطای فرمت مهلت",IF(AND(H17<>"",AD17<>"",TODAY()>AD17),"تاخیر",IF(L17<>"","در حال انجام","")))))) -> در حال انجام | V17: =IF(U17="تاخیر",TODAY()-AD17,IF(AND(U17="بسته",AH17<>"",AD17<>"",AH17>AD17),AH17-AD17,0)) -> 0 | W17: =IF(L17="","",VALUE(LEFT(L17,FIND("/",L17)-1))) -> 1405 | X17: =IF(L17="","",VALUE(MID(L17,FIND("/",L17)+1,FIND("/",L17,FIND("/",L17)+1)-FIND("/",L17)-1))) -> 2 | Y17: =IF(L17="","",VALUE(MID(L17,FIND("/",L17,FIND("/",L17)+1)+1,LEN(L17)-FIND("/",L17,FIND("/",L17)+1)))) -> 2 | Z17: =IF(OR(L17="",W17=""),"",IFERROR(INDEX('لیست‌ها'!$Q$3:$Q$53,MATCH(W17,'لیست‌ها'!$P$3:$P$53,0))+IF(X17<=6,(X17-1)*31+Y17,IF(X17<=11,186+(X17-7)*30+Y17,336+Y17))-1,"")) -> 46134 | AA17: =IF(H17="","",VALUE(LEFT(H17,FIND("/",H17)-1))) | AB17: =IF(H17="","",VALUE(MID(H17,FIND("/",H17)+1,FIND("/",H17,FIND("/",H17)+1)-FIND("/",H17)-1))) | AC17: =IF(H17="","",VALUE(MID(H17,FIND("/",H17,FIND("/",H17)+1)+1,LEN(H17)-FIND("/",H17,FIND("/",H17)+1)))) | AD17: =IF(OR(H17="",AA17=""),"",IFERROR(INDEX('لیست‌ها'!$Q$3:$Q$53,MATCH(AA17,'لیست‌ها'!$P$3:$P$53,0))+IF(AB17<=6,(AB17-1)*31+AC17,IF(AB17<=11,186+(AB17-7)*30+AC17,336+AC17))-1,"")) | AE17: =IF(P17="","",VALUE(LEFT(P17,FIND("/",P17)-1))) | AF17: =IF(P17="","",VALUE(MID(P17,FIND("/",P17)+1,FIND("/",P17,FIND("/",P17)+1)-FIND("/",P17)-1))) | AG17: =IF(P17="","",VALUE(MID(P17,FIND("/",P17,FIND("/",P17)+1)+1,LEN(P17)-FIND("/",P17,FIND("/",P17)+1)))) | AH17: =IF(OR(P17="",AE17=""),"",IFERROR(INDEX('لیست‌ها'!$Q$3:$Q$53,MATCH(AE17,'لیست‌ها'!$P$3:$P$53,0))+IF(AF17<=6,(AF17-1)*31+AG17,IF(AF17<=11,186+(AF17-7)*30+AG17,336+AG17))-1,"")) | AI17: =IF(W17="","",W17&"-"&TEXT(X17,"00")) -> 1405-02 | AJ17: =IF(W17="","",W17*12+X17) -> 16862 | AK17: =IF(U17="تاخیر",V17+ROW()/100000,"")
A18: =IF(B18="","",ROW()-3) -> 15 | B18: PL\05\15 | C18: اقدام اصلاحی | D18: سایر | E18: انحراف از مصرف مواد smc به میزان0.7... | F18: حمید بیات | G18: برنامه‌ریزی | L18: 1405/2/2 | M18: ثبت فرم | U18: =IF(B18="","",IF(OR(P18<>"",I18="می‌باشد"),"بسته",IF(AND(L18<>"",W18=""),"خطای فرمت تاریخ ایجاد",IF(AND(H18<>"",AA18=""),"خطای فرمت مهلت",IF(AND(H18<>"",AD18<>"",TODAY()>AD18),"تاخیر",IF(L18<>"","در حال انجام","")))))) -> در حال انجام | V18: =IF(U18="تاخیر",TODAY()-AD18,IF(AND(U18="بسته",AH18<>"",AD18<>"",AH18>AD18),AH18-AD18,0)) -> 0 | W18: =IF(L18="","",VALUE(LEFT(L18,FIND("/",L18)-1))) -> 1405 | X18: =IF(L18="","",VALUE(MID(L18,FIND("/",L18)+1,FIND("/",L18,FIND("/",L18)+1)-FIND("/",L18)-1))) -> 2 | Y18: =IF(L18="","",VALUE(MID(L18,FIND("/",L18,FIND("/",L18)+1)+1,LEN(L18)-FIND("/",L18,FIND("/",L18)+1)))) -> 2 | Z18: =IF(OR(L18="",W18=""),"",IFERROR(INDEX('لیست‌ها'!$Q$3:$Q$53,MATCH(W18,'لیست‌ها'!$P$3:$P$53,0))+IF(X18<=6,(X18-1)*31+Y18,IF(X18<=11,186+(X18-7)*30+Y18,336+Y18))-1,"")) -> 46134 | AA18: =IF(H18="","",VALUE(LEFT(H18,FIND("/",H18)-1))) | AB18: =IF(H18="","",VALUE(MID(H18,FIND("/",H18)+1,FIND("/",H18,FIND("/",H18)+1)-FIND("/",H18)-1))) | AC18: =IF(H18="","",VALUE(MID(H18,FIND("/",H18,FIND("/",H18)+1)+1,LEN(H18)-FIND("/",H18,FIND("/",H18)+1)))) | AD18: =IF(OR(H18="",AA18=""),"",IFERROR(INDEX('لیست‌ها'!$Q$3:$Q$53,MATCH(AA18,'لیست‌ها'!$P$3:$P$53,0))+IF(AB18<=6,(AB18-1)*31+AC18,IF(AB18<=11,186+(AB18-7)*30+AC18,336+AC18))-1,"")) | AE18: =IF(P18="","",VALUE(LEFT(P18,FIND("/",P18)-1))) | AF18: =IF(P18="","",VALUE(MID(P18,FIND("/",P18)+1,FIND("/",P18,FIND("/",P18)+1)-FIND("/",P18)-1))) | AG18: =IF(P18="","",VALUE(MID(P18,FIND("/",P18,FIND("/",P18)+1)+1,LEN(P18)-FIND("/",P18,FIND("/",P18)+1)))) | AH18: =IF(OR(P18="",AE18=""),"",IFERROR(INDEX('لیست‌ها'!$Q$3:$Q$53,MATCH(AE18,'لیست‌ها'!$P$3:$P$53,0))+IF(AF18<=6,(AF18-1)*31+AG18,IF(AF18<=11,186+(AF18-7)*30+AG18,336+AG18))-1,"")) | AI18: =IF(W18="","",W18&"-"&TEXT(X18,"00")) -> 1405-02 | AJ18: =IF(W18="","",W18*12+X18) -> 16862 | AK18: =IF(U18="تاخیر",V18+ROW()/100000,"")
A19: =IF(B19="","",ROW()-3) -> 16 | B19: des\05\16 | C19: اقدام اصلاحی | D19: پایش فرآیندها و تجزیه و تحلیل | E19: امپر 212B - MTTR (عقب بهمن ماه) | F19: مرضیه کاظم‌زاده | G19: مهندسی | H19: 1405/2/31 | I19: می‌باشد | L19: 1405/2/6 | M19: جهت اطلاع | U19: =IF(B19="","",IF(OR(P19<>"",I19="می‌باشد"),"بسته",IF(AND(L19<>"",W19=""),"خطای فرمت تاریخ ایجاد",IF(AND(H19<>"",AA19=""),"خطای فرمت مهلت",IF(AND(H19<>"",AD19<>"",TODAY()>AD19),"تاخیر",IF(L19<>"","در حال انجام","")))))) -> بسته | V19: =IF(U19="تاخیر",TODAY()-AD19,IF(AND(U19="بسته",AH19<>"",AD19<>"",AH19>AD19),AH19-AD19,0)) -> 0 | W19: =IF(L19="","",VALUE(LEFT(L19,FIND("/",L19)-1))) -> 1405 | X19: =IF(L19="","",VALUE(MID(L19,FIND("/",L19)+1,FIND("/",L19,FIND("/",L19)+1)-FIND("/",L19)-1))) -> 2 | Y19: =IF(L19="","",VALUE(MID(L19,FIND("/",L19,FIND("/",L19)+1)+1,LEN(L19)-FIND("/",L19,FIND("/",L19)+1)))) -> 6 | Z19: =IF(OR(L19="",W19=""),"",IFERROR(INDEX('لیست‌ها'!$Q$3:$Q$53,MATCH(W19,'لیست‌ها'!$P$3:$P$53,0))+IF(X19<=6,(X19-1)*31+Y19,IF(X19<=11,186+(X19-7)*30+Y19,336+Y19))-1,"")) -> 46138 | AA19: =IF(H19="","",VALUE(LEFT(H19,FIND("/",H19)-1))) -> 1405 | AB19: =IF(H19="","",VALUE(MID(H19,FIND("/",H19)+1,FIND("/",H19,FIND("/",H19)+1)-FIND("/",H19)-1))) -> 2 | AC19: =IF(H19="","",VALUE(MID(H19,FIND("/",H19,FIND("/",H19)+1)+1,LEN(H19)-FIND("/",H19,FIND("/",H19)+1)))) -> 31 | AD19: =IF(OR(H19="",AA19=""),"",IFERROR(INDEX('لیست‌ها'!$Q$3:$Q$53,MATCH(AA19,'لیست‌ها'!$P$3:$P$53,0))+IF(AB19<=6,(AB19-1)*31+AC19,IF(AB19<=11,186+(AB19-7)*30+AC19,336+AC19))-1,"")) -> 46163 | AE19: =IF(P19="","",VALUE(LEFT(P19,FIND("/",P19)-1))) | AF19: =IF(P19="","",VALUE(MID(P19,FIND("/",P19)+1,FIND("/",P19,FIND("/",P19)+1)-FIND("/",P19)-1))) | AG19: =IF(P19="","",VALUE(MID(P19,FIND("/",P19,FIND("/",P19)+1)+1,LEN(P19)-FIND("/",P19,FIND("/",P19)+1)))) | AH19: =IF(OR(P19="",AE19=""),"",IFERROR(INDEX('لیست‌ها'!$Q$3:$Q$53,MATCH(AE19,'لیست‌ها'!$P$3:$P$53,0))+IF(AF19<=6,(AF19-1)*31+AG19,IF(AF19<=11,186+(AF19-7)*30+AG19,336+AG19))-1,"")) | AI19: =IF(W19="","",W19&"-"&TEXT(X19,"00")) -> 1405-02 | AJ19: =IF(W19="","",W19*12+X19) -> 16862 | AK19: =IF(U19="تاخیر",V19+ROW()/100000,"")
A20: =IF(B20="","",ROW()-3) -> 17 | B20: des\05\17 | C20: اقدام اصلاحی | D20: پایش فرآیندها و تجزیه و تحلیل | E20: 405D - MTTR بهمن 1404 | F20: مرضیه کاظم‌زاده | G20: مهندسی | H20: 1405/2/31 | I20: می‌باشد | L20: 1405/2/6 | M20: جهت اطلاع | U20: =IF(B20="","",IF(OR(P20<>"",I20="می‌باشد"),"بسته",IF(AND(L20<>"",W20=""),"خطای فرمت تاریخ ایجاد",IF(AND(H20<>"",AA20=""),"خطای فرمت مهلت",IF(AND(H20<>"",AD20<>"",TODAY()>AD20),"تاخیر",IF(L20<>"","در حال انجام","")))))) -> بسته | V20: =IF(U20="تاخیر",TODAY()-AD20,IF(AND(U20="بسته",AH20<>"",AD20<>"",AH20>AD20),AH20-AD20,0)) -> 0 | W20: =IF(L20="","",VALUE(LEFT(L20,FIND("/",L20)-1))) -> 1405 | X20: =IF(L20="","",VALUE(MID(L20,FIND("/",L20)+1,FIND("/",L20,FIND("/",L20)+1)-FIND("/",L20)-1))) -> 2 | Y20: =IF(L20="","",VALUE(MID(L20,FIND("/",L20,FIND("/",L20)+1)+1,LEN(L20)-FIND("/",L20,FIND("/",L20)+1)))) -> 6 | Z20: =IF(OR(L20="",W20=""),"",IFERROR(INDEX('لیست‌ها'!$Q$3:$Q$53,MATCH(W20,'لیست‌ها'!$P$3:$P$53,0))+IF(X20<=6,(X20-1)*31+Y20,IF(X20<=11,186+(X20-7)*30+Y20,336+Y20))-1,"")) -> 46138 | AA20: =IF(H20="","",VALUE(LEFT(H20,FIND("/",H20)-1))) -> 1405 | AB20: =IF(H20="","",VALUE(MID(H20,FIND("/",H20)+1,FIND("/",H20,FIND("/",H20)+1)-FIND("/",H20)-1))) -> 2 | AC20: =IF(H20="","",VALUE(MID(H20,FIND("/",H20,FIND("/",H20)+1)+1,LEN(H20)-FIND("/",H20,FIND("/",H20)+1)))) -> 31 | AD20: =IF(OR(H20="",AA20=""),"",IFERROR(INDEX('لیست‌ها'!$Q$3:$Q$53,MATCH(AA20,'لیست‌ها'!$P$3:$P$53,0))+IF(AB20<=6,(AB20-1)*31+AC20,IF(AB20<=11,186+(AB20-7)*30+AC20,336+AC20))-1,"")) -> 46163 | AE20: =IF(P20="","",VALUE(LEFT(P20,FIND("/",P20)-1))) | AF20: =IF(P20="","",VALUE(MID(P20,FIND("/",P20)+1,FIND("/",P20,FIND("/",P20)+1)-FIND("/",P20)-1))) | AG20: =IF(P20="","",VALUE(MID(P20,FIND("/",P20,FIND("/",P20)+1)+1,LEN(P20)-FIND("/",P20,FIND("/",P20)+1)))) | AH20: =IF(OR(P20="",AE20=""),"",IFERROR(INDEX('لیست‌ها'!$Q$3:$Q$53,MATCH(AE20,'لیست‌ها'!$P$3:$P$53,0))+IF(AF20<=6,(AF20-1)*31+AG20,IF(AF20<=11,186+(AF20-7)*30+AG20,336+AG20))-1,"")) | AI20: =IF(W20="","",W20&"-"&TEXT(X20,"00")) -> 1405-02 | AJ20: =IF(W20="","",W20*12+X20) -> 16862 | AK20: =IF(U20="تاخیر",V20+ROW()/100000,"")
A21: =IF(B21="","",ROW()-3) -> 18 | B21: des\05\18 | C21: اقدام اصلاحی | D21: پایش فرآیندها و تجزیه و تحلیل | E21: سینی فن آریسان (PU1 اسفند 1404) - MTTR | F21: مرضیه کاظم‌زاده | G21: مهندسی | H21: 1405/2/31 | I21: می‌باشد | L21: 1405/2/6 | M21: جهت اطلاع | U21: =IF(B21="","",IF(OR(P21<>"",I21="می‌باشد"),"بسته",IF(AND(L21<>"",W21=""),"خطای فرمت تاریخ ایجاد",IF(AND(H21<>"",AA21=""),"خطای فرمت مهلت",IF(AND(H21<>"",AD21<>"",TODAY()>AD21),"تاخیر",IF(L21<>"","در حال انجام","")))))) -> بسته | V21: =IF(U21="تاخیر",TODAY()-AD21,IF(AND(U21="بسته",AH21<>"",AD21<>"",AH21>AD21),AH21-AD21,0)) -> 0 | W21: =IF(L21="","",VALUE(LEFT(L21,FIND("/",L21)-1))) -> 1405 | X21: =IF(L21="","",VALUE(MID(L21,FIND("/",L21)+1,FIND("/",L21,FIND("/",L21)+1)-FIND("/",L21)-1))) -> 2 | Y21: =IF(L21="","",VALUE(MID(L21,FIND("/",L21,FIND("/",L21)+1)+1,LEN(L21)-FIND("/",L21,FIND("/",L21)+1)))) -> 6 | Z21: =IF(OR(L21="",W21=""),"",IFERROR(INDEX('لیست‌ها'!$Q$3:$Q$53,MATCH(W21,'لیست‌ها'!$P$3:$P$53,0))+IF(X21<=6,(X21-1)*31+Y21,IF(X21<=11,186+(X21-7)*30+Y21,336+Y21))-1,"")) -> 46138 | AA21: =IF(H21="","",VALUE(LEFT(H21,FIND("/",H21)-1))) -> 1405 | AB21: =IF(H21="","",VALUE(MID(H21,FIND("/",H21)+1,FIND("/",H21,FIND("/",H21)+1)-FIND("/",H21)-1))) -> 2 | AC21: =IF(H21="","",VALUE(MID(H21,FIND("/",H21,FIND("/",H21)+1)+1,LEN(H21)-FIND("/",H21,FIND("/",H21)+1)))) -> 31 | AD21: =IF(OR(H21="",AA21=""),"",IFERROR(INDEX('لیست‌ها'!$Q$3:$Q$53,MATCH(AA21,'لیست‌ها'!$P$3:$P$53,0))+IF(AB21<=6,(AB21-1)*31+AC21,IF(AB21<=11,186+(AB21-7)*30+AC21,336+AC21))-1,"")) -> 46163 | AE21: =IF(P21="","",VALUE(LEFT(P21,FIND("/",P21)-1))) | AF21: =IF(P21="","",VALUE(MID(P21,FIND("/",P21)+1,FIND("/",P21,FIND("/",P21)+1)-FIND("/",P21)-1))) | AG21: =IF(P21="","",VALUE(MID(P21,FIND("/",P21,FIND("/",P21)+1)+1,LEN(P21)-FIND("/",P21,FIND("/",P21)+1)))) | AH21: =IF(OR(P21="",AE21=""),"",IFERROR(INDEX('لیست‌ها'!$Q$3:$Q$53,MATCH(AE21,'لیست‌ها'!$P$3:$P$53,0))+IF(AF21<=6,(AF21-1)*31+AG21,IF(AF21<=11,186+(AF21-7)*30+AG21,336+AG21))-1,"")) | AI21: =IF(W21="","",W21&"-"&TEXT(X21,"00")) -> 1405-02 | AJ21: =IF(W21="","",W21*12+X21) -> 16862 | AK21: =IF(U21="تاخیر",V21+ROW()/100000,"")
A22: =IF(B22="","",ROW()-3) -> 19 | B22: des\05\19 | C22: اقدام اصلاحی | D22: پایش فرآیندها و تجزیه و تحلیل | E22: سمند X7 اسفند 1404 - MTTR | F22: مرضیه کاظم‌زاده | G22: مهندسی | H22: 1405/2/31 | I22: می‌باشد | L22: 1405/2/6 | M22: جهت اطلاع | U22: =IF(B22="","",IF(OR(P22<>"",I22="می‌باشد"),"بسته",IF(AND(L22<>"",W22=""),"خطای فرمت تاریخ ایجاد",IF(AND(H22<>"",AA22=""),"خطای فرمت مهلت",IF(AND(H22<>"",AD22<>"",TODAY()>AD22),"تاخیر",IF(L22<>"","در حال انجام","")))))) -> بسته | V22: =IF(U22="تاخیر",TODAY()-AD22,IF(AND(U22="بسته",AH22<>"",AD22<>"",AH22>AD22),AH22-AD22,0)) -> 0 | W22: =IF(L22="","",VALUE(LEFT(L22,FIND("/",L22)-1))) -> 1405 | X22: =IF(L22="","",VALUE(MID(L22,FIND("/",L22)+1,FIND("/",L22,FIND("/",L22)+1)-FIND("/",L22)-1))) -> 2 | Y22: =IF(L22="","",VALUE(MID(L22,FIND("/",L22,FIND("/",L22)+1)+1,LEN(L22)-FIND("/",L22,FIND("/",L22)+1)))) -> 6 | Z22: =IF(OR(L22="",W22=""),"",IFERROR(INDEX('لیست‌ها'!$Q$3:$Q$53,MATCH(W22,'لیست‌ها'!$P$3:$P$53,0))+IF(X22<=6,(X22-1)*31+Y22,IF(X22<=11,186+(X22-7)*30+Y22,336+Y22))-1,"")) -> 46138 | AA22: =IF(H22="","",VALUE(LEFT(H22,FIND("/",H22)-1))) -> 1405 | AB22: =IF(H22="","",VALUE(MID(H22,FIND("/",H22)+1,FIND("/",H22,FIND("/",H22)+1)-FIND("/",H22)-1))) -> 2 | AC22: =IF(H22="","",VALUE(MID(H22,FIND("/",H22,FIND("/",H22)+1)+1,LEN(H22)-FIND("/",H22,FIND("/",H22)+1)))) -> 31 | AD22: =IF(OR(H22="",AA22=""),"",IFERROR(INDEX('لیست‌ها'!$Q$3:$Q$53,MATCH(AA22,'لیست‌ها'!$P$3:$P$53,0))+IF(AB22<=6,(AB22-1)*31+AC22,IF(AB22<=11,186+(AB22-7)*30+AC22,336+AC22))-1,"")) -> 46163 | AE22: =IF(P22="","",VALUE(LEFT(P22,FIND("/",P22)-1))) | AF22: =IF(P22="","",VALUE(MID(P22,FIND("/",P22)+1,FIND("/",P22,FIND("/",P22)+1)-FIND("/",P22)-1))) | AG22: =IF(P22="","",VALUE(MID(P22,FIND("/",P22,FIND("/",P22)+1)+1,LEN(P22)-FIND("/",P22,FIND("/",P22)+1)))) | AH22: =IF(OR(P22="",AE22=""),"",IFERROR(INDEX('لیست‌ها'!$Q$3:$Q$53,MATCH(AE22,'لیست‌ها'!$P$3:$P$53,0))+IF(AF22<=6,(AF22-1)*31+AG22,IF(AF22<=11,186+(AF22-7)*30+AG22,336+AG22))-1,"")) | AI22: =IF(W22="","",W22&"-"&TEXT(X22,"00")) -> 1405-02 | AJ22: =IF(W22="","",W22*12+X22) -> 16862 | AK22: =IF(U22="تاخیر",V22+ROW()/100000,"")
A23: =IF(B23="","",ROW()-3) -> 20 | B23: des\05\20 | C23: اقدام اصلاحی | D23: پایش فرآیندها و تجزیه و تحلیل | E23: رات 4 (بهمن ماه 1404) - MTTR | F23: مرضیه کاظم‌زاده | G23: مهندسی | H23: 1405/2/31 | L23: 1405/2/6 | M23: نظریه ریشه یاب | U23: =IF(B23="","",IF(OR(P23<>"",I23="می‌باشد"),"بسته",IF(AND(L23<>"",W23=""),"خطای فرمت تاریخ ایجاد",IF(AND(H23<>"",AA23=""),"خطای فرمت مهلت",IF(AND(H23<>"",AD23<>"",TODAY()>AD23),"تاخیر",IF(L23<>"","در حال انجام","")))))) -> تاخیر | V23: =IF(U23="تاخیر",TODAY()-AD23,IF(AND(U23="بسته",AH23<>"",AD23<>"",AH23>AD23),AH23-AD23,0)) -> 132 | W23: =IF(L23="","",VALUE(LEFT(L23,FIND("/",L23)-1))) -> 1405 | X23: =IF(L23="","",VALUE(MID(L23,FIND("/",L23)+1,FIND("/",L23,FIND("/",L23)+1)-FIND("/",L23)-1))) -> 2 | Y23: =IF(L23="","",VALUE(MID(L23,FIND("/",L23,FIND("/",L23)+1)+1,LEN(L23)-FIND("/",L23,FIND("/",L23)+1)))) -> 6 | Z23: =IF(OR(L23="",W23=""),"",IFERROR(INDEX('لیست‌ها'!$Q$3:$Q$53,MATCH(W23,'لیست‌ها'!$P$3:$P$53,0))+IF(X23<=6,(X23-1)*31+Y23,IF(X23<=11,186+(X23-7)*30+Y23,336+Y23))-1,"")) -> 46138 | AA23: =IF(H23="","",VALUE(LEFT(H23,FIND("/",H23)-1))) -> 1405 | AB23: =IF(H23="","",VALUE(MID(H23,FIND("/",H23)+1,FIND("/",H23,FIND("/",H23)+1)-FIND("/",H23)-1))) -> 2 | AC23: =IF(H23="","",VALUE(MID(H23,FIND("/",H23,FIND("/",H23)+1)+1,LEN(H23)-FIND("/",H23,FIND("/",H23)+1)))) -> 31 | AD23: =IF(OR(H23="",AA23=""),"",IFERROR(INDEX('لیست‌ها'!$Q$3:$Q$53,MATCH(AA23,'لیست‌ها'!$P$3:$P$53,0))+IF(AB23<=6,(AB23-1)*31+AC23,IF(AB23<=11,186+(AB23-7)*30+AC23,336+AC23))-1,"")) -> 46163 | AE23: =IF(P23="","",VALUE(LEFT(P23,FIND("/",P23)-1))) | AF23: =IF(P23="","",VALUE(MID(P23,FIND("/",P23)+1,FIND("/",P23,FIND("/",P23)+1)-FIND("/",P23)-1))) | AG23: =IF(P23="","",VALUE(MID(P23,FIND("/",P23,FIND("/",P23)+1)+1,LEN(P23)-FIND("/",P23,FIND("/",P23)+1)))) | AH23: =IF(OR(P23="",AE23=""),"",IFERROR(INDEX('لیست‌ها'!$Q$3:$Q$53,MATCH(AE23,'لیست‌ها'!$P$3:$P$53,0))+IF(AF23<=6,(AF23-1)*31+AG23,IF(AF23<=11,186+(AF23-7)*30+AG23,336+AG23))-1,"")) | AI23: =IF(W23="","",W23&"-"&TEXT(X23,"00")) -> 1405-02 | AJ23: =IF(W23="","",W23*12+X23) -> 16862 | AK23: =IF(U23="تاخیر",V23+ROW()/100000,"") -> 132.00029
A24: =IF(B24="","",ROW()-3) -> 21 | B24: des\05\21 | C24: اقدام اصلاحی | D24: پایش فرآیندها و تجزیه و تحلیل | E24: رات 4 (بهمن ماه 1404) - MTBF | F24: مرضیه کاظم‌زاده | G24: مهندسی | H24: 1405/2/31 | L24: 1405/2/6 | M24: نظریه ریشه یاب | U24: =IF(B24="","",IF(OR(P24<>"",I24="می‌باشد"),"بسته",IF(AND(L24<>"",W24=""),"خطای فرمت تاریخ ایجاد",IF(AND(H24<>"",AA24=""),"خطای فرمت مهلت",IF(AND(H24<>"",AD24<>"",TODAY()>AD24),"تاخیر",IF(L24<>"","در حال انجام","")))))) -> تاخیر | V24: =IF(U24="تاخیر",TODAY()-AD24,IF(AND(U24="بسته",AH24<>"",AD24<>"",AH24>AD24),AH24-AD24,0)) -> 132 | W24: =IF(L24="","",VALUE(LEFT(L24,FIND("/",L24)-1))) -> 1405 | X24: =IF(L24="","",VALUE(MID(L24,FIND("/",L24)+1,FIND("/",L24,FIND("/",L24)+1)-FIND("/",L24)-1))) -> 2 | Y24: =IF(L24="","",VALUE(MID(L24,FIND("/",L24,FIND("/",L24)+1)+1,LEN(L24)-FIND("/",L24,FIND("/",L24)+1)))) -> 6 | Z24: =IF(OR(L24="",W24=""),"",IFERROR(INDEX('لیست‌ها'!$Q$3:$Q$53,MATCH(W24,'لیست‌ها'!$P$3:$P$53,0))+IF(X24<=6,(X24-1)*31+Y24,IF(X24<=11,186+(X24-7)*30+Y24,336+Y24))-1,"")) -> 46138 | AA24: =IF(H24="","",VALUE(LEFT(H24,FIND("/",H24)-1))) -> 1405 | AB24: =IF(H24="","",VALUE(MID(H24,FIND("/",H24)+1,FIND("/",H24,FIND("/",H24)+1)-FIND("/",H24)-1))) -> 2 | AC24: =IF(H24="","",VALUE(MID(H24,FIND("/",H24,FIND("/",H24)+1)+1,LEN(H24)-FIND("/",H24,FIND("/",H24)+1)))) -> 31 | AD24: =IF(OR(H24="",AA24=""),"",IFERROR(INDEX('لیست‌ها'!$Q$3:$Q$53,MATCH(AA24,'لیست‌ها'!$P$3:$P$53,0))+IF(AB24<=6,(AB24-1)*31+AC24,IF(AB24<=11,186+(AB24-7)*30+AC24,336+AC24))-1,"")) -> 46163 | AE24: =IF(P24="","",VALUE(LEFT(P24,FIND("/",P24)-1))) | AF24: =IF(P24="","",VALUE(MID(P24,FIND("/",P24)+1,FIND("/",P24,FIND("/",P24)+1)-FIND("/",P24)-1))) | AG24: =IF(P24="","",VALUE(MID(P24,FIND("/",P24,FIND("/",P24)+1)+1,LEN(P24)-FIND("/",P24,FIND("/",P24)+1)))) | AH24: =IF(OR(P24="",AE24=""),"",IFERROR(INDEX('لیست‌ها'!$Q$3:$Q$53,MATCH(AE24,'لیست‌ها'!$P$3:$P$53,0))+IF(AF24<=6,(AF24-1)*31+AG24,IF(AF24<=11,186+(AF24-7)*30+AG24,336+AG24))-1,"")) | AI24: =IF(W24="","",W24&"-"&TEXT(X24,"00")) -> 1405-02 | AJ24: =IF(W24="","",W24*12+X24) -> 16862 | AK24: =IF(U24="تاخیر",V24+ROW()/100000,"") -> 132.00028
A25: =IF(B25="","",ROW()-3) -> 22 | B25: des\05\22 | C25: اقدام اصلاحی | D25: پایش فرآیندها و تجزیه و تحلیل | E25: رات 5 (بهمن ماه 1404) - MTTR | F25: مرضیه کاظم‌زاده | G25: مهندسی | H25: 1405/2/31 | L25: 1405/2/6 | M25: نظریه ریشه یاب | U25: =IF(B25="","",IF(OR(P25<>"",I25="می‌باشد"),"بسته",IF(AND(L25<>"",W25=""),"خطای فرمت تاریخ ایجاد",IF(AND(H25<>"",AA25=""),"خطای فرمت مهلت",IF(AND(H25<>"",AD25<>"",TODAY()>AD25),"تاخیر",IF(L25<>"","در حال انجام","")))))) -> تاخیر | V25: =IF(U25="تاخیر",TODAY()-AD25,IF(AND(U25="بسته",AH25<>"",AD25<>"",AH25>AD25),AH25-AD25,0)) -> 132 | W25: =IF(L25="","",VALUE(LEFT(L25,FIND("/",L25)-1))) -> 1405 | X25: =IF(L25="","",VALUE(MID(L25,FIND("/",L25)+1,FIND("/",L25,FIND("/",L25)+1)-FIND("/",L25)-1))) -> 2 | Y25: =IF(L25="","",VALUE(MID(L25,FIND("/",L25,FIND("/",L25)+1)+1,LEN(L25)-FIND("/",L25,FIND("/",L25)+1)))) -> 6 | Z25: =IF(OR(L25="",W25=""),"",IFERROR(INDEX('لیست‌ها'!$Q$3:$Q$53,MATCH(W25,'لیست‌ها'!$P$3:$P$53,0))+IF(X25<=6,(X25-1)*31+Y25,IF(X25<=11,186+(X25-7)*30+Y25,336+Y25))-1,"")) -> 46138 | AA25: =IF(H25="","",VALUE(LEFT(H25,FIND("/",H25)-1))) -> 1405 | AB25: =IF(H25="","",VALUE(MID(H25,FIND("/",H25)+1,FIND("/",H25,FIND("/",H25)+1)-FIND("/",H25)-1))) -> 2 | AC25: =IF(H25="","",VALUE(MID(H25,FIND("/",H25,FIND("/",H25)+1)+1,LEN(H25)-FIND("/",H25,FIND("/",H25)+1)))) -> 31 | AD25: =IF(OR(H25="",AA25=""),"",IFERROR(INDEX('لیست‌ها'!$Q$3:$Q$53,MATCH(AA25,'لیست‌ها'!$P$3:$P$53,0))+IF(AB25<=6,(AB25-1)*31+AC25,IF(AB25<=11,186+(AB25-7)*30+AC25,336+AC25))-1,"")) -> 46163 | AE25: =IF(P25="","",VALUE(LEFT(P25,FIND("/",P25)-1))) | AF25: =IF(P25="","",VALUE(MID(P25,FIND("/",P25)+1,FIND("/",P25,FIND("/",P25)+1)-FIND("/",P25)-1))) | AG25: =IF(P25="","",VALUE(MID(P25,FIND("/",P25,FIND("/",P25)+1)+1,LEN(P25)-FIND("/",P25,FIND("/",P25)+1)))) | AH25: =IF(OR(P25="",AE25=""),"",IFERROR(INDEX('لیست‌ها'!$Q$3:$Q$53,MATCH(AE25,'لیست‌ها'!$P$3:$P$53,0))+IF(AF25<=6,(AF25-1)*31+AG25,IF(AF25<=11,186+(AF25-7)*30+AG25,336+AG25))-1,"")) | AI25: =IF(W25="","",W25&"-"&TEXT(X25,"00")) -> 1405-02 | AJ25: =IF(W25="","",W25*12+X25) -> 16862 | AK25: =IF(U25="تاخیر",V25+ROW()/100000,"") -> 132.00027
A26: =IF(B26="","",ROW()-3) -> 23 | B26: des\05\23 | C26: اقدام اصلاحی | D26: پایش فرآیندها و تجزیه و تحلیل | E26: رات 7 (بهمن ماه 1404) - MTBF | F26: مرضیه کاظم‌زاده | G26: مهندسی | H26: 1405/2/31 | L26: 1405/2/6 | M26: نظریه ریشه یاب | U26: =IF(B26="","",IF(OR(P26<>"",I26="می‌باشد"),"بسته",IF(AND(L26<>"",W26=""),"خطای فرمت تاریخ ایجاد",IF(AND(H26<>"",AA26=""),"خطای فرمت مهلت",IF(AND(H26<>"",AD26<>"",TODAY()>AD26),"تاخیر",IF(L26<>"","در حال انجام","")))))) -> تاخیر | V26: =IF(U26="تاخیر",TODAY()-AD26,IF(AND(U26="بسته",AH26<>"",AD26<>"",AH26>AD26),AH26-AD26,0)) -> 132 | W26: =IF(L26="","",VALUE(LEFT(L26,FIND("/",L26)-1))) -> 1405 | X26: =IF(L26="","",VALUE(MID(L26,FIND("/",L26)+1,FIND("/",L26,FIND("/",L26)+1)-FIND("/",L26)-1))) -> 2 | Y26: =IF(L26="","",VALUE(MID(L26,FIND("/",L26,FIND("/",L26)+1)+1,LEN(L26)-FIND("/",L26,FIND("/",L26)+1)))) -> 6 | Z26: =IF(OR(L26="",W26=""),"",IFERROR(INDEX('لیست‌ها'!$Q$3:$Q$53,MATCH(W26,'لیست‌ها'!$P$3:$P$53,0))+IF(X26<=6,(X26-1)*31+Y26,IF(X26<=11,186+(X26-7)*30+Y26,336+Y26))-1,"")) -> 46138 | AA26: =IF(H26="","",VALUE(LEFT(H26,FIND("/",H26)-1))) -> 1405 | AB26: =IF(H26="","",VALUE(MID(H26,FIND("/",H26)+1,FIND("/",H26,FIND("/",H26)+1)-FIND("/",H26)-1))) -> 2 | AC26: =IF(H26="","",VALUE(MID(H26,FIND("/",H26,FIND("/",H26)+1)+1,LEN(H26)-FIND("/",H26,FIND("/",H26)+1)))) -> 31 | AD26: =IF(OR(H26="",AA26=""),"",IFERROR(INDEX('لیست‌ها'!$Q$3:$Q$53,MATCH(AA26,'لیست‌ها'!$P$3:$P$53,0))+IF(AB26<=6,(AB26-1)*31+AC26,IF(AB26<=11,186+(AB26-7)*30+AC26,336+AC26))-1,"")) -> 46163 | AE26: =IF(P26="","",VALUE(LEFT(P26,FIND("/",P26)-1))) | AF26: =IF(P26="","",VALUE(MID(P26,FIND("/",P26)+1,FIND("/",P26,FIND("/",P26)+1)-FIND("/",P26)-1))) | AG26: =IF(P26="","",VALUE(MID(P26,FIND("/",P26,FIND("/",P26)+1)+1,LEN(P26)-FIND("/",P26,FIND("/",P26)+1)))) | AH26: =IF(OR(P26="",AE26=""),"",IFERROR(INDEX('لیست‌ها'!$Q$3:$Q$53,MATCH(AE26,'لیست‌ها'!$P$3:$P$53,0))+IF(AF26<=6,(AF26-1)*31+AG26,IF(AF26<=11,186+(AF26-7)*30+AG26,336+AG26))-1,"")) | AI26: =IF(W26="","",W26&"-"&TEXT(X26,"00")) -> 1405-02 | AJ26: =IF(W26="","",W26*12+X26) -> 16862 | AK26: =IF(U26="تاخیر",V26+ROW()/100000,"") -> 132.00026
A27: =IF(B27="","",ROW()-3) -> 24 | B27: des\05\24 | C27: اقدام اصلاحی | D27: پایش فرآیندها و تجزیه و تحلیل | E27: رات 8 - MTTR | F27: مرضیه کاظم‌زاده | G27: مهندسی | H27: 1405/1/31 | L27: 1405/2/6 | M27: نظریه ریشه یاب | U27: =IF(B27="","",IF(OR(P27<>"",I27="می‌باشد"),"بسته",IF(AND(L27<>"",W27=""),"خطای فرمت تاریخ ایجاد",IF(AND(H27<>"",AA27=""),"خطای فرمت مهلت",IF(AND(H27<>"",AD27<>"",TODAY()>AD27),"تاخیر",IF(L27<>"","در حال انجام","")))))) -> تاخیر | V27: =IF(U27="تاخیر",TODAY()-AD27,IF(AND(U27="بسته",AH27<>"",AD27<>"",AH27>AD27),AH27-AD27,0)) -> 163 | W27: =IF(L27="","",VALUE(LEFT(L27,FIND("/",L27)-1))) -> 1405 | X27: =IF(L27="","",VALUE(MID(L27,FIND("/",L27)+1,FIND("/",L27,FIND("/",L27)+1)-FIND("/",L27)-1))) -> 2 | Y27: =IF(L27="","",VALUE(MID(L27,FIND("/",L27,FIND("/",L27)+1)+1,LEN(L27)-FIND("/",L27,FIND("/",L27)+1)))) -> 6 | Z27: =IF(OR(L27="",W27=""),"",IFERROR(INDEX('لیست‌ها'!$Q$3:$Q$53,MATCH(W27,'لیست‌ها'!$P$3:$P$53,0))+IF(X27<=6,(X27-1)*31+Y27,IF(X27<=11,186+(X27-7)*30+Y27,336+Y27))-1,"")) -> 46138 | AA27: =IF(H27="","",VALUE(LEFT(H27,FIND("/",H27)-1))) -> 1405 | AB27: =IF(H27="","",VALUE(MID(H27,FIND("/",H27)+1,FIND("/",H27,FIND("/",H27)+1)-FIND("/",H27)-1))) -> 1 | AC27: =IF(H27="","",VALUE(MID(H27,FIND("/",H27,FIND("/",H27)+1)+1,LEN(H27)-FIND("/",H27,FIND("/",H27)+1)))) -> 31 | AD27: =IF(OR(H27="",AA27=""),"",IFERROR(INDEX('لیست‌ها'!$Q$3:$Q$53,MATCH(AA27,'لیست‌ها'!$P$3:$P$53,0))+IF(AB27<=6,(AB27-1)*31+AC27,IF(AB27<=11,186+(AB27-7)*30+AC27,336+AC27))-1,"")) -> 46132 | AE27: =IF(P27="","",VALUE(LEFT(P27,FIND("/",P27)-1))) | AF27: =IF(P27="","",VALUE(MID(P27,FIND("/",P27)+1,FIND("/",P27,FIND("/",P27)+1)-FIND("/",P27)-1))) | AG27: =IF(P27="","",VALUE(MID(P27,FIND("/",P27,FIND("/",P27)+1)+1,LEN(P27)-FIND("/",P27,FIND("/",P27)+1)))) | AH27: =IF(OR(P27="",AE27=""),"",IFERROR(INDEX('لیست‌ها'!$Q$3:$Q$53,MATCH(AE27,'لیست‌ها'!$P$3:$P$53,0))+IF(AF27<=6,(AF27-1)*31+AG27,IF(AF27<=11,186+(AF27-7)*30+AG27,336+AG27))-1,"")) | AI27: =IF(W27="","",W27&"-"&TEXT(X27,"00")) -> 1405-02 | AJ27: =IF(W27="","",W27*12+X27) -> 16862 | AK27: =IF(U27="تاخیر",V27+ROW()/100000,"") -> 163.00025
A28: =IF(B28="","",ROW()-3) -> 25 | B28: SALE\05\25 | C28: اقدام اصلاحی | D28: کلیم | E28: کلیم 5 قطعه سینی فن سمند در سایت فا... | F28: میلاد زارع | G28: بازرسی آزمون | H28: 1405/2/31 | I28: می‌باشد | L28: 1405/2/8 | M28: جهت اطلاع | U28: =IF(B28="","",IF(OR(P28<>"",I28="می‌باشد"),"بسته",IF(AND(L28<>"",W28=""),"خطای فرمت تاریخ ایجاد",IF(AND(H28<>"",AA28=""),"خطای فرمت مهلت",IF(AND(H28<>"",AD28<>"",TODAY()>AD28),"تاخیر",IF(L28<>"","در حال انجام","")))))) -> بسته | V28: =IF(U28="تاخیر",TODAY()-AD28,IF(AND(U28="بسته",AH28<>"",AD28<>"",AH28>AD28),AH28-AD28,0)) -> 0 | W28: =IF(L28="","",VALUE(LEFT(L28,FIND("/",L28)-1))) -> 1405 | X28: =IF(L28="","",VALUE(MID(L28,FIND("/",L28)+1,FIND("/",L28,FIND("/",L28)+1)-FIND("/",L28)-1))) -> 2 | Y28: =IF(L28="","",VALUE(MID(L28,FIND("/",L28,FIND("/",L28)+1)+1,LEN(L28)-FIND("/",L28,FIND("/",L28)+1)))) -> 8 | Z28: =IF(OR(L28="",W28=""),"",IFERROR(INDEX('لیست‌ها'!$Q$3:$Q$53,MATCH(W28,'لیست‌ها'!$P$3:$P$53,0))+IF(X28<=6,(X28-1)*31+Y28,IF(X28<=11,186+(X28-7)*30+Y28,336+Y28))-1,"")) -> 46140 | AA28: =IF(H28="","",VALUE(LEFT(H28,FIND("/",H28)-1))) -> 1405 | AB28: =IF(H28="","",VALUE(MID(H28,FIND("/",H28)+1,FIND("/",H28,FIND("/",H28)+1)-FIND("/",H28)-1))) -> 2 | AC28: =IF(H28="","",VALUE(MID(H28,FIND("/",H28,FIND("/",H28)+1)+1,LEN(H28)-FIND("/",H28,FIND("/",H28)+1)))) -> 31 | AD28: =IF(OR(H28="",AA28=""),"",IFERROR(INDEX('لیست‌ها'!$Q$3:$Q$53,MATCH(AA28,'لیست‌ها'!$P$3:$P$53,0))+IF(AB28<=6,(AB28-1)*31+AC28,IF(AB28<=11,186+(AB28-7)*30+AC28,336+AC28))-1,"")) -> 46163 | AE28: =IF(P28="","",VALUE(LEFT(P28,FIND("/",P28)-1))) | AF28: =IF(P28="","",VALUE(MID(P28,FIND("/",P28)+1,FIND("/",P28,FIND("/",P28)+1)-FIND("/",P28)-1))) | AG28: =IF(P28="","",VALUE(MID(P28,FIND("/",P28,FIND("/",P28)+1)+1,LEN(P28)-FIND("/",P28,FIND("/",P28)+1)))) | AH28: =IF(OR(P28="",AE28=""),"",IFERROR(INDEX('لیست‌ها'!$Q$3:$Q$53,MATCH(AE28,'لیست‌ها'!$P$3:$P$53,0))+IF(AF28<=6,(AF28-1)*31+AG28,IF(AF28<=11,186+(AF28-7)*30+AG28,336+AG28))-1,"")) | AI28: =IF(W28="","",W28&"-"&TEXT(X28,"00")) -> 1405-02 | AJ28: =IF(W28="","",W28*12+X28) -> 16862 | AK28: =IF(U28="تاخیر",V28+ROW()/100000,"")
A29: =IF(B29="","",ROW()-3) -> 26 | B29: SALE\05\26 | C29: اقدام اصلاحی | D29: کلیم | E29: کلیم 1 قطعه سینی زیرموتور 206 در سا... | F29: میلاد زارع | G29: بازرسی آزمون | H29: 1405/2/26 | I29: می‌باشد | L29: 1405/2/8 | M29: جهت اطلاع | U29: =IF(B29="","",IF(OR(P29<>"",I29="می‌باشد"),"بسته",IF(AND(L29<>"",W29=""),"خطای فرمت تاریخ ایجاد",IF(AND(H29<>"",AA29=""),"خطای فرمت مهلت",IF(AND(H29<>"",AD29<>"",TODAY()>AD29),"تاخیر",IF(L29<>"","در حال انجام","")))))) -> بسته | V29: =IF(U29="تاخیر",TODAY()-AD29,IF(AND(U29="بسته",AH29<>"",AD29<>"",AH29>AD29),AH29-AD29,0)) -> 0 | W29: =IF(L29="","",VALUE(LEFT(L29,FIND("/",L29)-1))) -> 1405 | X29: =IF(L29="","",VALUE(MID(L29,FIND("/",L29)+1,FIND("/",L29,FIND("/",L29)+1)-FIND("/",L29)-1))) -> 2 | Y29: =IF(L29="","",VALUE(MID(L29,FIND("/",L29,FIND("/",L29)+1)+1,LEN(L29)-FIND("/",L29,FIND("/",L29)+1)))) -> 8 | Z29: =IF(OR(L29="",W29=""),"",IFERROR(INDEX('لیست‌ها'!$Q$3:$Q$53,MATCH(W29,'لیست‌ها'!$P$3:$P$53,0))+IF(X29<=6,(X29-1)*31+Y29,IF(X29<=11,186+(X29-7)*30+Y29,336+Y29))-1,"")) -> 46140 | AA29: =IF(H29="","",VALUE(LEFT(H29,FIND("/",H29)-1))) -> 1405 | AB29: =IF(H29="","",VALUE(MID(H29,FIND("/",H29)+1,FIND("/",H29,FIND("/",H29)+1)-FIND("/",H29)-1))) -> 2 | AC29: =IF(H29="","",VALUE(MID(H29,FIND("/",H29,FIND("/",H29)+1)+1,LEN(H29)-FIND("/",H29,FIND("/",H29)+1)))) -> 26 | AD29: =IF(OR(H29="",AA29=""),"",IFERROR(INDEX('لیست‌ها'!$Q$3:$Q$53,MATCH(AA29,'لیست‌ها'!$P$3:$P$53,0))+IF(AB29<=6,(AB29-1)*31+AC29,IF(AB29<=11,186+(AB29-7)*30+AC29,336+AC29))-1,"")) -> 46158 | AE29: =IF(P29="","",VALUE(LEFT(P29,FIND("/",P29)-1))) | AF29: =IF(P29="","",VALUE(MID(P29,FIND("/",P29)+1,FIND("/",P29,FIND("/",P29)+1)-FIND("/",P29)-1))) | AG29: =IF(P29="","",VALUE(MID(P29,FIND("/",P29,FIND("/",P29)+1)+1,LEN(P29)-FIND("/",P29,FIND("/",P29)+1)))) | AH29: =IF(OR(P29="",AE29=""),"",IFERROR(INDEX('لیست‌ها'!$Q$3:$Q$53,MATCH(AE29,'لیست‌ها'!$P$3:$P$53,0))+IF(AF29<=6,(AF29-1)*31+AG29,IF(AF29<=11,186+(AF29-7)*30+AG29,336+AG29))-1,"")) | AI29: =IF(W29="","",W29&"-"&TEXT(X29,"00")) -> 1405-02 | AJ29: =IF(W29="","",W29*12+X29) -> 16862 | AK29: =IF(U29="تاخیر",V29+ROW()/100000,"")
A30: =IF(B30="","",ROW()-3) -> 27 | B30: SALE\05\27 | C30: اقدام اصلاحی | D30: کلیم | E30: کلیم 1 قطعه سینی نگهدارنده رک را در... | F30: میلاد زارع | G30: بازرسی آزمون | H30: 1405/2/31 | I30: می‌باشد | L30: 1405/2/8 | M30: جهت اطلاع | U30: =IF(B30="","",IF(OR(P30<>"",I30="می‌باشد"),"بسته",IF(AND(L30<>"",W30=""),"خطای فرمت تاریخ ایجاد",IF(AND(H30<>"",AA30=""),"خطای فرمت مهلت",IF(AND(H30<>"",AD30<>"",TODAY()>AD30),"تاخیر",IF(L30<>"","در حال انجام","")))))) -> بسته | V30: =IF(U30="تاخیر",TODAY()-AD30,IF(AND(U30="بسته",AH30<>"",AD30<>"",AH30>AD30),AH30-AD30,0)) -> 0 | W30: =IF(L30="","",VALUE(LEFT(L30,FIND("/",L30)-1))) -> 1405 | X30: =IF(L30="","",VALUE(MID(L30,FIND("/",L30)+1,FIND("/",L30,FIND("/",L30)+1)-FIND("/",L30)-1))) -> 2 | Y30: =IF(L30="","",VALUE(MID(L30,FIND("/",L30,FIND("/",L30)+1)+1,LEN(L30)-FIND("/",L30,FIND("/",L30)+1)))) -> 8 | Z30: =IF(OR(L30="",W30=""),"",IFERROR(INDEX('لیست‌ها'!$Q$3:$Q$53,MATCH(W30,'لیست‌ها'!$P$3:$P$53,0))+IF(X30<=6,(X30-1)*31+Y30,IF(X30<=11,186+(X30-7)*30+Y30,336+Y30))-1,"")) -> 46140 | AA30: =IF(H30="","",VALUE(LEFT(H30,FIND("/",H30)-1))) -> 1405 | AB30: =IF(H30="","",VALUE(MID(H30,FIND("/",H30)+1,FIND("/",H30,FIND("/",H30)+1)-FIND("/",H30)-1))) -> 2 | AC30: =IF(H30="","",VALUE(MID(H30,FIND("/",H30,FIND("/",H30)+1)+1,LEN(H30)-FIND("/",H30,FIND("/",H30)+1)))) -> 31 | AD30: =IF(OR(H30="",AA30=""),"",IFERROR(INDEX('لیست‌ها'!$Q$3:$Q$53,MATCH(AA30,'لیست‌ها'!$P$3:$P$53,0))+IF(AB30<=6,(AB30-1)*31+AC30,IF(AB30<=11,186+(AB30-7)*30+AC30,336+AC30))-1,"")) -> 46163 | AE30: =IF(P30="","",VALUE(LEFT(P30,FIND("/",P30)-1))) | AF30: =IF(P30="","",VALUE(MID(P30,FIND("/",P30)+1,FIND("/",P30,FIND("/",P30)+1)-FIND("/",P30)-1))) | AG30: =IF(P30="","",VALUE(MID(P30,FIND("/",P30,FIND("/",P30)+1)+1,LEN(P30)-FIND("/",P30,FIND("/",P30)+1)))) | AH30: =IF(OR(P30="",AE30=""),"",IFERROR(INDEX('لیست‌ها'!$Q$3:$Q$53,MATCH(AE30,'لیست‌ها'!$P$3:$P$53,0))+IF(AF30<=6,(AF30-1)*31+AG30,IF(AF30<=11,186+(AF30-7)*30+AG30,336+AG30))-1,"")) | AI30: =IF(W30="","",W30&"-"&TEXT(X30,"00")) -> 1405-02 | AJ30: =IF(W30="","",W30*12+X30) -> 16862 | AK30: =IF(U30="تاخیر",V30+ROW()/100000,"")
