Workbook

Sheet راهنما
B2: راهنمای فایل پایش اقدامات اصلاحی / پیشگیرانه
B4: ساختار ستون‌ها
B5: ستون‌های اول شیت «ورودی اقدامات» دقیقاً همان ستون‌های گرید سیستم هستند: شماره فرم، نوع، اصلاحی (منشأ)، موضوع عدم تطابق، درخواست‌کننده، نام فرآیند مرتبط، مهلت انجام اقدام، اثر بخشی، نظریه نهایی نماینده مدیریت، شماره اقدام مجدد، تاریخ ایجاد فرم، وضعیت (سیستم) و نسخه. ستون‌های واحد، تاریخ تکمیل، مسئول/نظریه ریشه‌یابی، مسئول اقدام و شرح اقدامات برای تحلیل تکمیلی اضافه شده‌اند.
B7: تاریخ‌ها
B8: همه تاریخ‌ها شمسی و به‌صورت متن سال/ماه/روز وارد می‌شوند (مثال 1404/7/4). تبدیل به میلادی برای محاسبه تاخیر به‌صورت خودکار و در ستون‌های پنهان (W تا AJ) انجام می‌شود.
B10: وضعیت پایش (خودکار)
B11: «بسته»: ستون اثر بخشی پر باشد یا تاریخ تکمیل ثبت شده باشد. «تاخیر»: مهلت گذشته و بسته نشده. «در حال انجام»: بقیه. این ستون با ستون «وضعیت (سیستم)» که مرحله گردش‌کار در سیستم است فرق دارد.
B13: اثر بخشی
B14: مقدارهای «می‌باشد»، «نمی‌باشد» و «تایید» مطابق مقادیر دیده‌شده در سیستم است و هر مقدار ثبت‌شده، اقدام را بسته می‌کند. اگر معنای «می‌باشد» در سیستم شما متفاوت است، فرمول ستون U را اصلاح کنید.
B16: لیست‌ها و داشبورد
B17: فهرست‌های کشویی از شیت «لیست‌ها» می‌آیند (ستون‌های P تا T پنهان و فقط برای تقویم شمسی است). داشبورد به‌صورت خودکار به‌روز می‌شود. ظرفیت فایل ۸۰۰ ردیف است.
B19: داشبورد مدیریتی
B20: بالای داشبورد یک جمله خلاصه خودکار (خلاصه مدیریتی)، شاخص‌های کلیدی، جدول «۱۰ اقدام با بیشترین تاخیر» برای پیگیری فوری و تفکیک تاخیرها بر اساس مدت (۱ تا ۳۰، ۳۱ تا ۶۰، ۶۱ تا ۹۰ و بیش از ۹۰ روز) اضافه شده است. این شیت برای چاپ/خروجی PDF تنظیم شده (Landscape، تناسب با عرض صفحه) — کافیست از منوی File در اکسل گزینه Export یا Print to PDF را روی همین شیت بزنید.

Sheet ورودی اقدامات
A1: پایش اقدامات اصلاحی / پیشگیرانه — ستون‌ها مطابق گرید سیستم «فرم اقدام اصلاحی/پیشگیرانه»
A2: خودکار | B2: ورودی | C2: ورودی | D2: ورودی | E2: ورودی | F2: ورودی | G2: ورودی | H2: ورودی | I2: ورودی | J2: ورودی | K2: ورودی | L2: ورودی | M2: ورودی | N2: ورودی | O2: ورودی | P2: ورودی | Q2: ورودی | R2: ورودی | S2: ورودی | T2: خودکار | U2: خودکار
A3: ردیف | B3: شماره فرم | C3: نوع | D3: اصلاحی (منشأ) | E3: موضوع عدم تطابق | F3: درخواست‌کننده | G3: نام فرآیند مرتبط | H3: مهلت انجام اقدام | I3: اثر بخشی | J3: نظریه نهایی نماینده مدیریت | K3: شماره اقدام مجدد | L3: تاریخ ایجاد فرم | M3: وضعیت (سیستم) | N3: واحد درخواست‌کننده | O3: تاریخ تکمیل اقدام | P3: مسئول ریشه‌یابی | Q3: نظریه ریشه‌یابی | R3: مسئول اقدام | S3: شرح اقدامات | T3: وضعیت پایش | U3: روزهای تاخیر
A4: 1 | B4: PL\05\1 | C4: اقدام اصلاحی | D4: سایر | E4: انحراف از مصرف مواد smc به میزان2.22درصد نسبت به حداکثر تعیین شده در bom قطعات در اسفند ماه سال 1404 | F4: حمید بیات:کارشناس برنامه ریزی تولید نور ایستا پلاستیک | G4: برنامه‌ریزی | H4: 1405/02/31 | I4: می‌باشد | J4: مورد تایید است | L4: 1405/01/19 | M4: نظریه نهایی نماینده مدیریت | N4: برنامه‌ریزی | O4: 1405/03/20 | P4: سید محمد رضا اجاقی دو گاهه:رئیس امور تولید نور ایستا پلاستیک | Q4: میانگین مصرف های ارائه شده استاندارد، صحیح نمی باشد و نیاز به بازنگری دارد | R4: سید محمد رضا اجاقی دو گاهه:رئیس امور تولید نور ایستا پلاستیک | S4: با اصلاح صحیح وزن های ارائه شده مهندسی مشکل رفع می گردد | T4: =IF(B4="","",IF(OR(I4<>"",O4<>""),"بسته",IF(AND(L4<>"",V4=""),"خطای فرمت تاریخ ایجاد",IF(AND(H4<>"",Z4=""),"خطای فرمت مهلت",IF(AND(H4<>"",AC4<>"",TODAY()>AC4),"تاخیر",IF(L4<>"","در حال انجام","")))))) -> بسته | U4: =IF(T4="تاخیر",TODAY()-AC4,IF(AND(T4="بسته",AG4<>"",AC4<>"",AG4>AC4),AG4-AC4,0)) -> 20 | V4: =IF(L4="","",VALUE(LEFT(L4,FIND("/",L4)-1))) -> 1405 | W4: =IF(L4="","",VALUE(MID(L4,FIND("/",L4)+1,FIND("/",L4,FIND("/",L4)+1)-FIND("/",L4)-1))) -> 1 | X4: =IF(L4="","",VALUE(MID(L4,FIND("/",L4,FIND("/",L4)+1)+1,LEN(L4)-FIND("/",L4,FIND("/",L4)+1)))) -> 19 | Y4: =IF(OR(L4="",V4=""),"",IFERROR(INDEX(لیست‌ها!$Q$3:$Q$53,MATCH(V4,لیست‌ها!$P$3:$P$53,0))+IF(W4<=6,(W4-1)*31+X4,IF(W4<=11,186+(W4-7)*30+X4,336+X4))-1,"")) -> 46120 | Z4: =IF(H4="","",VALUE(LEFT(H4,FIND("/",H4)-1))) -> 1405 | AA4: =IF(H4="","",VALUE(MID(H4,FIND("/",H4)+1,FIND("/",H4,FIND("/",H4)+1)-FIND("/",H4)-1))) -> 2 | AB4: =IF(H4="","",VALUE(MID(H4,FIND("/",H4,FIND("/",H4)+1)+1,LEN(H4)-FIND("/",H4,FIND("/",H4)+1)))) -> 31 | AC4: =IF(OR(H4="",Z4=""),"",IFERROR(INDEX(لیست‌ها!$Q$3:$Q$53,MATCH(Z4,لیست‌ها!$P$3:$P$53,0))+IF(AA4<=6,(AA4-1)*31+AB4,IF(AA4<=11,186+(AA4-7)*30+AB4,336+AB4))-1,"")) -> 46163 | AD4: =IF(O4="","",VALUE(LEFT(O4,FIND("/",O4)-1))) -> 1405 | AE4: =IF(O4="","",VALUE(MID(O4,FIND("/",O4)+1,FIND("/",O4,FIND("/",O4)+1)-FIND("/",O4)-1))) -> 3 | AF4: =IF(O4="","",VALUE(MID(O4,FIND("/",O4,FIND("/",O4)+1)+1,LEN(O4)-FIND("/",O4,FIND("/",O4)+1)))) -> 20 | AG4: =IF(OR(O4="",AD4=""),"",IFERROR(INDEX(لیست‌ها!$Q$3:$Q$53,MATCH(AD4,لیست‌ها!$P$3:$P$53,0))+IF(AE4<=6,(AE4-1)*31+AF4,IF(AE4<=11,186+(AE4-7)*30+AF4,336+AF4))-1,"")) -> 46183 | AH4: =IF(V4="","",V4&"-"&TEXT(W4,"00")) -> 1405-01 | AI4: =IF(V4="","",V4*12+W4) -> 16861 | AJ4: =IF(T4="تاخیر",U4+ROW()/100000,"")
A5: 2 | B5: SALE\05\2 | C5: اقدام اصلاحی | D5: کلیم | E5: کلیم 1 قطعه سینی فن سمند در سایت کرمانشاه به علت ترک خوردگی شماره فرم شکایت مشتری 1 | F5: میلاد زارع:کارشناس فروش شرکت نور ایستا پلاستیک | G5: بازرسی آزمون | H5: 1405/02/31 | I5: می‌باشد | J5: مورد تایید است | L5: 1405/01/22 | M5: نظریه نهایی نماینده مدیریت | N5: فروش | O5: 1405/03/21 | P5: سید محمد رضا اجاقی دو گاهه:رئیس امور تولید نور ایستا پلاستیک | Q5: به علت مشکل طرح بسته بندی می باشد | R5: سید محمد رضا اجاقی دو گاهه:رئیس امور تولید نور ایستا پلاستیک | S5: با تغییر طرح بسته بندی مشکل رفع می گردد | T5: =IF(B5="","",IF(OR(I5<>"",O5<>""),"بسته",IF(AND(L5<>"",V5=""),"خطای فرمت تاریخ ایجاد",IF(AND(H5<>"",Z5=""),"خطای فرمت مهلت",IF(AND(H5<>"",AC5<>"",TODAY()>AC5),"تاخیر",IF(L5<>"","در حال انجام","")))))) -> بسته | U5: =IF(T5="تاخیر",TODAY()-AC5,IF(AND(T5="بسته",AG5<>"",AC5<>"",AG5>AC5),AG5-AC5,0)) -> 21 | V5: =IF(L5="","",VALUE(LEFT(L5,FIND("/",L5)-1))) -> 1405 | W5: =IF(L5="","",VALUE(MID(L5,FIND("/",L5)+1,FIND("/",L5,FIND("/",L5)+1)-FIND("/",L5)-1))) -> 1 | X5: =IF(L5="","",VALUE(MID(L5,FIND("/",L5,FIND("/",L5)+1)+1,LEN(L5)-FIND("/",L5,FIND("/",L5)+1)))) -> 22 | Y5: =IF(OR(L5="",V5=""),"",IFERROR(INDEX(لیست‌ها!$Q$3:$Q$53,MATCH(V5,لیست‌ها!$P$3:$P$53,0))+IF(W5<=6,(W5-1)*31+X5,IF(W5<=11,186+(W5-7)*30+X5,336+X5))-1,"")) -> 46123 | Z5: =IF(H5="","",VALUE(LEFT(H5,FIND("/",H5)-1))) -> 1405 | AA5: =IF(H5="","",VALUE(MID(H5,FIND("/",H5)+1,FIND("/",H5,FIND("/",H5)+1)-FIND("/",H5)-1))) -> 2 | AB5: =IF(H5="","",VALUE(MID(H5,FIND("/",H5,FIND("/",H5)+1)+1,LEN(H5)-FIND("/",H5,FIND("/",H5)+1)))) -> 31 | AC5: =IF(OR(H5="",Z5=""),"",IFERROR(INDEX(لیست‌ها!$Q$3:$Q$53,MATCH(Z5,لیست‌ها!$P$3:$P$53,0))+IF(AA5<=6,(AA5-1)*31+AB5,IF(AA5<=11,186+(AA5-7)*30+AB5,336+AB5))-1,"")) -> 46163 | AD5: =IF(O5="","",VALUE(LEFT(O5,FIND("/",O5)-1))) -> 1405 | AE5: =IF(O5="","",VALUE(MID(O5,FIND("/",O5)+1,FIND("/",O5,FIND("/",O5)+1)-FIND("/",O5)-1))) -> 3 | AF5: =IF(O5="","",VALUE(MID(O5,FIND("/",O5,FIND("/",O5)+1)+1,LEN(O5)-FIND("/",O5,FIND("/",O5)+1)))) -> 21 | AG5: =IF(OR(O5="",AD5=""),"",IFERROR(INDEX(لیست‌ها!$Q$3:$Q$53,MATCH(AD5,لیست‌ها!$P$3:$P$53,0))+IF(AE5<=6,(AE5-1)*31+AF5,IF(AE5<=11,186+(AE5-7)*30+AF5,336+AF5))-1,"")) -> 46184 | AH5: =IF(V5="","",V5&"-"&TEXT(W5,"00")) -> 1405-01 | AI5: =IF(V5="","",V5*12+W5) -> 16861 | AJ5: =IF(T5="تاخیر",U5+ROW()/100000,"")
A6: 3 | B6: SALE\05\3 | C6: اقدام اصلاحی | D6: کلیم | E6: کلیم 1 قطعه سینی فن سمند در سایت تبریز به علت کسری بوش شماره فرم شکایت مشتری 2 | F6: میلاد زارع:کارشناس فروش شرکت نور ایستا پلاستیک | G6: بازرسی آزمون | H6: 1405/02/31 | I6: می‌باشد | J6: مورد تایید است | L6: 1405/01/23 | M6: نظریه نهایی نماینده مدیریت | N6: فروش | O6: 1405/03/21 | P6: سید محمد رضا اجاقی دو گاهه:رئیس امور تولید نور ایستا پلاستیک | Q6: به علت عدم خطاناپذیری وجود بوش می باشد | R6: سید محمد رضا اجاقی دو گاهه:رئیس امور تولید نور ایستا پلاستیک | S6: با خطا ناپذیر کردن کنترل بوش مشکل رفع می گردد | T6: =IF(B6="","",IF(OR(I6<>"",O6<>""),"بسته",IF(AND(L6<>"",V6=""),"خطای فرمت تاریخ ایجاد",IF(AND(H6<>"",Z6=""),"خطای فرمت مهلت",IF(AND(H6<>"",AC6<>"",TODAY()>AC6),"تاخیر",IF(L6<>"","در حال انجام","")))))) -> بسته | U6: =IF(T6="تاخیر",TODAY()-AC6,IF(AND(T6="بسته",AG6<>"",AC6<>"",AG6>AC6),AG6-AC6,0)) -> 21 | V6: =IF(L6="","",VALUE(LEFT(L6,FIND("/",L6)-1))) -> 1405 | W6: =IF(L6="","",VALUE(MID(L6,FIND("/",L6)+1,FIND("/",L6,FIND("/",L6)+1)-FIND("/",L6)-1))) -> 1 | X6: =IF(L6="","",VALUE(MID(L6,FIND("/",L6,FIND("/",L6)+1)+1,LEN(L6)-FIND("/",L6,FIND("/",L6)+1)))) -> 23 | Y6: =IF(OR(L6="",V6=""),"",IFERROR(INDEX(لیست‌ها!$Q$3:$Q$53,MATCH(V6,لیست‌ها!$P$3:$P$53,0))+IF(W6<=6,(W6-1)*31+X6,IF(W6<=11,186+(W6-7)*30+X6,336+X6))-1,"")) -> 46124 | Z6: =IF(H6="","",VALUE(LEFT(H6,FIND("/",H6)-1))) -> 1405 | AA6: =IF(H6="","",VALUE(MID(H6,FIND("/",H6)+1,FIND("/",H6,FIND("/",H6)+1)-FIND("/",H6)-1))) -> 2 | AB6: =IF(H6="","",VALUE(MID(H6,FIND("/",H6,FIND("/",H6)+1)+1,LEN(H6)-FIND("/",H6,FIND("/",H6)+1)))) -> 31 | AC6: =IF(OR(H6="",Z6=""),"",IFERROR(INDEX(لیست‌ها!$Q$3:$Q$53,MATCH(Z6,لیست‌ها!$P$3:$P$53,0))+IF(AA6<=6,(AA6-1)*31+AB6,IF(AA6<=11,186+(AA6-7)*30+AB6,336+AB6))-1,"")) -> 46163 | AD6: =IF(O6="","",VALUE(LEFT(O6,FIND("/",O6)-1))) -> 1405 | AE6: =IF(O6="","",VALUE(MID(O6,FIND("/",O6)+1,FIND("/",O6,FIND("/",O6)+1)-FIND("/",O6)-1))) -> 3 | AF6: =IF(O6="","",VALUE(MID(O6,FIND("/",O6,FIND("/",O6)+1)+1,LEN(O6)-FIND("/",O6,FIND("/",O6)+1)))) -> 21 | AG6: =IF(OR(O6="",AD6=""),"",IFERROR(INDEX(لیست‌ها!$Q$3:$Q$53,MATCH(AD6,لیست‌ها!$P$3:$P$53,0))+IF(AE6<=6,(AE6-1)*31+AF6,IF(AE6<=11,186+(AE6-7)*30+AF6,336+AF6))-1,"")) -> 46184 | AH6: =IF(V6="","",V6&"-"&TEXT(W6,"00")) -> 1405-01 | AI6: =IF(V6="","",V6*12+W6) -> 16861 | AJ6: =IF(T6="تاخیر",U6+ROW()/100000,"")
A7: 4 | B7: SALE\05\4 | C7: اقدام اصلاحی | D7: کلیم | E7: کلیم 6 قطعه سینی فن سمند در سایت تهران به علت شکستگی، ترک خوردگی و ایراد قطعه شماره فرم شکایت مشتری 3 | F7: میلاد زارع:کارشناس فروش شرکت نور ایستا پلاستیک | G7: بازرسی آزمون | H7: 1405/02/20 | J7: مورد تایید است | L7: 1405/01/24 | M7: نظریه نهایی نماینده مدیریت | N7: فروش | O7: 1405/02/21 | P7: سید محمد رضا اجاقی دو گاهه:رئیس امور تولید نور ایستا پلاستیک | Q7: به علت استحکام پایین مواد اولیه می باشد | R7: سید محمد رضا اجاقی دو گاهه:رئیس امور تولید نور ایستا پلاستیک | S7: با کنترل سخت گیرانه در ورودی مشکل رفع می گردد | T7: =IF(B7="","",IF(OR(I7<>"",O7<>""),"بسته",IF(AND(L7<>"",V7=""),"خطای فرمت تاریخ ایجاد",IF(AND(H7<>"",Z7=""),"خطای فرمت مهلت",IF(AND(H7<>"",AC7<>"",TODAY()>AC7),"تاخیر",IF(L7<>"","در حال انجام","")))))) -> بسته | U7: =IF(T7="تاخیر",TODAY()-AC7,IF(AND(T7="بسته",AG7<>"",AC7<>"",AG7>AC7),AG7-AC7,0)) -> 1 | V7: =IF(L7="","",VALUE(LEFT(L7,FIND("/",L7)-1))) -> 1405 | W7: =IF(L7="","",VALUE(MID(L7,FIND("/",L7)+1,FIND("/",L7,FIND("/",L7)+1)-FIND("/",L7)-1))) -> 1 | X7: =IF(L7="","",VALUE(MID(L7,FIND("/",L7,FIND("/",L7)+1)+1,LEN(L7)-FIND("/",L7,FIND("/",L7)+1)))) -> 24 | Y7: =IF(OR(L7="",V7=""),"",IFERROR(INDEX(لیست‌ها!$Q$3:$Q$53,MATCH(V7,لیست‌ها!$P$3:$P$53,0))+IF(W7<=6,(W7-1)*31+X7,IF(W7<=11,186+(W7-7)*30+X7,336+X7))-1,"")) -> 46125 | Z7: =IF(H7="","",VALUE(LEFT(H7,FIND("/",H7)-1))) -> 1405 | AA7: =IF(H7="","",VALUE(MID(H7,FIND("/",H7)+1,FIND("/",H7,FIND("/",H7)+1)-FIND("/",H7)-1))) -> 2 | AB7: =IF(H7="","",VALUE(MID(H7,FIND("/",H7,FIND("/",H7)+1)+1,LEN(H7)-FIND("/",H7,FIND("/",H7)+1)))) -> 20 | AC7: =IF(OR(H7="",Z7=""),"",IFERROR(INDEX(لیست‌ها!$Q$3:$Q$53,MATCH(Z7,لیست‌ها!$P$3:$P$53,0))+IF(AA7<=6,(AA7-1)*31+AB7,IF(AA7<=11,186+(AA7-7)*30+AB7,336+AB7))-1,"")) -> 46152 | AD7: =IF(O7="","",VALUE(LEFT(O7,FIND("/",O7)-1))) -> 1405 | AE7: =IF(O7="","",VALUE(MID(O7,FIND("/",O7)+1,FIND("/",O7,FIND("/",O7)+1)-FIND("/",O7)-1))) -> 2 | AF7: =IF(O7="","",VALUE(MID(O7,FIND("/",O7,FIND("/",O7)+1)+1,LEN(O7)-FIND("/",O7,FIND("/",O7)+1)))) -> 21 | AG7: =IF(OR(O7="",AD7=""),"",IFERROR(INDEX(لیست‌ها!$Q$3:$Q$53,MATCH(AD7,لیست‌ها!$P$3:$P$53,0))+IF(AE7<=6,(AE7-1)*31+AF7,IF(AE7<=11,186+(AE7-7)*30+AF7,336+AF7))-1,"")) -> 46153 | AH7: =IF(V7="","",V7&"-"&TEXT(W7,"00")) -> 1405-01 | AI7: =IF(V7="","",V7*12+W7) -> 16861 | AJ7: =IF(T7="تاخیر",U7+ROW()/100000,"")
A8: 5 | B8: SALE\05\5 | C8: اقدام اصلاحی | D8: کلیم | T8: =IF(B8="","",IF(OR(I8<>"",O8<>""),"بسته",IF(AND(L8<>"",V8=""),"خطای فرمت تاریخ ایجاد",IF(AND(H8<>"",Z8=""),"خطای فرمت مهلت",IF(AND(H8<>"",AC8<>"",TODAY()>AC8),"تاخیر",IF(L8<>"","در حال انجام","")))))) | U8: =IF(T8="تاخیر",TODAY()-AC8,IF(AND(T8="بسته",AG8<>"",AC8<>"",AG8>AC8),AG8-AC8,0)) -> 0 | V8: =IF(L8="","",VALUE(LEFT(L8,FIND("/",L8)-1))) | W8: =IF(L8="","",VALUE(MID(L8,FIND("/",L8)+1,FIND("/",L8,FIND("/",L8)+1)-FIND("/",L8)-1))) | X8: =IF(L8="","",VALUE(MID(L8,FIND("/",L8,FIND("/",L8)+1)+1,LEN(L8)-FIND("/",L8,FIND("/",L8)+1)))) | Y8: =IF(OR(L8="",V8=""),"",IFERROR(INDEX(لیست‌ها!$Q$3:$Q$53,MATCH(V8,لیست‌ها!$P$3:$P$53,0))+IF(W8<=6,(W8-1)*31+X8,IF(W8<=11,186+(W8-7)*30+X8,336+X8))-1,"")) | Z8: =IF(H8="","",VALUE(LEFT(H8,FIND("/",H8)-1))) | AA8: =IF(H8="","",VALUE(MID(H8,FIND("/",H8)+1,FIND("/",H8,FIND("/",H8)+1)-FIND("/",H8)-1))) | AB8: =IF(H8="","",VALUE(MID(H8,FIND("/",H8,FIND("/",H8)+1)+1,LEN(H8)-FIND("/",H8,FIND("/",H8)+1)))) | AC8: =IF(OR(H8="",Z8=""),"",IFERROR(INDEX(لیست‌ها!$Q$3:$Q$53,MATCH(Z8,لیست‌ها!$P$3:$P$53,0))+IF(AA8<=6,(AA8-1)*31+AB8,IF(AA8<=11,186+(AA8-7)*30+AB8,336+AB8))-1,"")) | AD8: =IF(O8="","",VALUE(LEFT(O8,FIND("/",O8)-1))) | AE8: =IF(O8="","",VALUE(MID(O8,FIND("/",O8)+1,FIND("/",O8,FIND("/",O8)+1)-FIND("/",O8)-1))) | AF8: =IF(O8="","",VALUE(MID(O8,FIND("/",O8,FIND("/",O8)+1)+1,LEN(O8)-FIND("/",O8,FIND("/",O8)+1)))) | AG8: =IF(OR(O8="",AD8=""),"",IFERROR(INDEX(لیست‌ها!$Q$3:$Q$53,MATCH(AD8,لیست‌ها!$P$3:$P$53,0))+IF(AE8<=6,(AE8-1)*31+AF8,IF(AE8<=11,186+(AE8-7)*30+AF8,336+AF8))-1,"")) | AH8: =IF(V8="","",V8&"-"&TEXT(W8,"00")) | AI8: =IF(V8="","",V8*12+W8) | AJ8: =IF(T8="تاخیر",U8+ROW()/100000,"")
A9: 6 | B9: SALE\05\6 | C9: اقدام اصلاحی | D9: کلیم | T9: =IF(B9="","",IF(OR(I9<>"",O9<>""),"بسته",IF(AND(L9<>"",V9=""),"خطای فرمت تاریخ ایجاد",IF(AND(H9<>"",Z9=""),"خطای فرمت مهلت",IF(AND(H9<>"",AC9<>"",TODAY()>AC9),"تاخیر",IF(L9<>"","در حال انجام","")))))) | U9: =IF(T9="تاخیر",TODAY()-AC9,IF(AND(T9="بسته",AG9<>"",AC9<>"",AG9>AC9),AG9-AC9,0)) -> 0 | V9: =IF(L9="","",VALUE(LEFT(L9,FIND("/",L9)-1))) | W9: =IF(L9="","",VALUE(MID(L9,FIND("/",L9)+1,FIND("/",L9,FIND("/",L9)+1)-FIND("/",L9)-1))) | X9: =IF(L9="","",VALUE(MID(L9,FIND("/",L9,FIND("/",L9)+1)+1,LEN(L9)-FIND("/",L9,FIND("/",L9)+1)))) | Y9: =IF(OR(L9="",V9=""),"",IFERROR(INDEX(لیست‌ها!$Q$3:$Q$53,MATCH(V9,لیست‌ها!$P$3:$P$53,0))+IF(W9<=6,(W9-1)*31+X9,IF(W9<=11,186+(W9-7)*30+X9,336+X9))-1,"")) | Z9: =IF(H9="","",VALUE(LEFT(H9,FIND("/",H9)-1))) | AA9: =IF(H9="","",VALUE(MID(H9,FIND("/",H9)+1,FIND("/",H9,FIND("/",H9)+1)-FIND("/",H9)-1))) | AB9: =IF(H9="","",VALUE(MID(H9,FIND("/",H9,FIND("/",H9)+1)+1,LEN(H9)-FIND("/",H9,FIND("/",H9)+1)))) | AC9: =IF(OR(H9="",Z9=""),"",IFERROR(INDEX(لیست‌ها!$Q$3:$Q$53,MATCH(Z9,لیست‌ها!$P$3:$P$53,0))+IF(AA9<=6,(AA9-1)*31+AB9,IF(AA9<=11,186+(AA9-7)*30+AB9,336+AB9))-1,"")) | AD9: =IF(O9="","",VALUE(LEFT(O9,FIND("/",O9)-1))) | AE9: =IF(O9="","",VALUE(MID(O9,FIND("/",O9)+1,FIND("/",O9,FIND("/",O9)+1)-FIND("/",O9)-1))) | AF9: =IF(O9="","",VALUE(MID(O9,FIND("/",O9,FIND("/",O9)+1)+1,LEN(O9)-FIND("/",O9,FIND("/",O9)+1)))) | AG9: =IF(OR(O9="",AD9=""),"",IFERROR(INDEX(لیست‌ها!$Q$3:$Q$53,MATCH(AD9,لیست‌ها!$P$3:$P$53,0))+IF(AE9<=6,(AE9-1)*31+AF9,IF(AE9<=11,186+(AE9-7)*30+AF9,336+AF9))-1,"")) | AH9: =IF(V9="","",V9&"-"&TEXT(W9,"00")) | AI9: =IF(V9="","",V9*12+W9) | AJ9: =IF(T9="تاخیر",U9+ROW()/100000,"")
A10: 7 | B10: SALE\05\7 | C10: اقدام اصلاحی | D10: کلیم | T10: =IF(B10="","",IF(OR(I10<>"",O10<>""),"بسته",IF(AND(L10<>"",V10=""),"خطای فرمت تاریخ ایجاد",IF(AND(H10<>"",Z10=""),"خطای فرمت مهلت",IF(AND(H10<>"",AC10<>"",TODAY()>AC10),"تاخیر",IF(L10<>"","در حال انجام","")))))) | U10: =IF(T10="تاخیر",TODAY()-AC10,IF(AND(T10="بسته",AG10<>"",AC10<>"",AG10>AC10),AG10-AC10,0)) -> 0 | V10: =IF(L10="","",VALUE(LEFT(L10,FIND("/",L10)-1))) | W10: =IF(L10="","",VALUE(MID(L10,FIND("/",L10)+1,FIND("/",L10,FIND("/",L10)+1)-FIND("/",L10)-1))) | X10: =IF(L10="","",VALUE(MID(L10,FIND("/",L10,FIND("/",L10)+1)+1,LEN(L10)-FIND("/",L10,FIND("/",L10)+1)))) | Y10: =IF(OR(L10="",V10=""),"",IFERROR(INDEX(لیست‌ها!$Q$3:$Q$53,MATCH(V10,لیست‌ها!$P$3:$P$53,0))+IF(W10<=6,(W10-1)*31+X10,IF(W10<=11,186+(W10-7)*30+X10,336+X10))-1,"")) | Z10: =IF(H10="","",VALUE(LEFT(H10,FIND("/",H10)-1))) | AA10: =IF(H10="","",VALUE(MID(H10,FIND("/",H10)+1,FIND("/",H10,FIND("/",H10)+1)-FIND("/",H10)-1))) | AB10: =IF(H10="","",VALUE(MID(H10,FIND("/",H10,FIND("/",H10)+1)+1,LEN(H10)-FIND("/",H10,FIND("/",H10)+1)))) | AC10: =IF(OR(H10="",Z10=""),"",IFERROR(INDEX(لیست‌ها!$Q$3:$Q$53,MATCH(Z10,لیست‌ها!$P$3:$P$53,0))+IF(AA10<=6,(AA10-1)*31+AB10,IF(AA10<=11,186+(AA10-7)*30+AB10,336+AB10))-1,"")) | AD10: =IF(O10="","",VALUE(LEFT(O10,FIND("/",O10)-1))) | AE10: =IF(O10="","",VALUE(MID(O10,FIND("/",O10)+1,FIND("/",O10,FIND("/",O10)+1)-FIND("/",O10)-1))) | AF10: =IF(O10="","",VALUE(MID(O10,FIND("/",O10,FIND("/",O10)+1)+1,LEN(O10)-FIND("/",O10,FIND("/",O10)+1)))) | AG10: =IF(OR(O10="",AD10=""),"",IFERROR(INDEX(لیست‌ها!$Q$3:$Q$53,MATCH(AD10,لیست‌ها!$P$3:$P$53,0))+IF(AE10<=6,(AE10-1)*31+AF10,IF(AE10<=11,186+(AE10-7)*30+AF10,336+AF10))-1,"")) | AH10: =IF(V10="","",V10&"-"&TEXT(W10,"00")) | AI10: =IF(V10="","",V10*12+W10) | AJ10: =IF(T10="تاخیر",U10+ROW()/100000,"")
A11: 8 | B11: SALE\05\8 | C11: اقدام اصلاحی | D11: کلیم | T11: =IF(B11="","",IF(OR(I11<>"",O11<>""),"بسته",IF(AND(L11<>"",V11=""),"خطای فرمت تاریخ ایجاد",IF(AND(H11<>"",Z11=""),"خطای فرمت مهلت",IF(AND(H11<>"",AC11<>"",TODAY()>AC11),"تاخیر",IF(L11<>"","در حال انجام","")))))) | U11: =IF(T11="تاخیر",TODAY()-AC11,IF(AND(T11="بسته",AG11<>"",AC11<>"",AG11>AC11),AG11-AC11,0)) -> 0 | V11: =IF(L11="","",VALUE(LEFT(L11,FIND("/",L11)-1))) | W11: =IF(L11="","",VALUE(MID(L11,FIND("/",L11)+1,FIND("/",L11,FIND("/",L11)+1)-FIND("/",L11)-1))) | X11: =IF(L11="","",VALUE(MID(L11,FIND("/",L11,FIND("/",L11)+1)+1,LEN(L11)-FIND("/",L11,FIND("/",L11)+1)))) | Y11: =IF(OR(L11="",V11=""),"",IFERROR(INDEX(لیست‌ها!$Q$3:$Q$53,MATCH(V11,لیست‌ها!$P$3:$P$53,0))+IF(W11<=6,(W11-1)*31+X11,IF(W11<=11,186+(W11-7)*30+X11,336+X11))-1,"")) | Z11: =IF(H11="","",VALUE(LEFT(H11,FIND("/",H11)-1))) | AA11: =IF(H11="","",VALUE(MID(H11,FIND("/",H11)+1,FIND("/",H11,FIND("/",H11)+1)-FIND("/",H11)-1))) | AB11: =IF(H11="","",VALUE(MID(H11,FIND("/",H11,FIND("/",H11)+1)+1,LEN(H11)-FIND("/",H11,FIND("/",H11)+1)))) | AC11: =IF(OR(H11="",Z11=""),"",IFERROR(INDEX(لیست‌ها!$Q$3:$Q$53,MATCH(Z11,لیست‌ها!$P$3:$P$53,0))+IF(AA11<=6,(AA11-1)*31+AB11,IF(AA11<=11,186+(AA11-7)*30+AB11,336+AB11))-1,"")) | AD11: =IF(O11="","",VALUE(LEFT(O11,FIND("/",O11)-1))) | AE11: =IF(O11="","",VALUE(MID(O11,FIND("/",O11)+1,FIND("/",O11,FIND("/",O11)+1)-FIND("/",O11)-1))) | AF11: =IF(O11="","",VALUE(MID(O11,FIND("/",O11,FIND("/",O11)+1)+1,LEN(O11)-FIND("/",O11,FIND("/",O11)+1)))) | AG11: =IF(OR(O11="",AD11=""),"",IFERROR(INDEX(لیست‌ها!$Q$3:$Q$53,MATCH(AD11,لیست‌ها!$P$3:$P$53,0))+IF(AE11<=6,(AE11-1)*31+AF11,IF(AE11<=11,186+(AE11-7)*30+AF11,336+AF11))-1,"")) | AH11: =IF(V11="","",V11&"-"&TEXT(W11,"00")) | AI11: =IF(V11="","",V11*12+W11) | AJ11: =IF(T11="تاخیر",U11+ROW()/100000,"")
A12: 9 | B12: SALE\05\9 | C12: اقدام اصلاحی | D12: کلیم | T12: =IF(B12="","",IF(OR(I12<>"",O12<>""),"بسته",IF(AND(L12<>"",V12=""),"خطای فرمت تاریخ ایجاد",IF(AND(H12<>"",Z12=""),"خطای فرمت مهلت",IF(AND(H12<>"",AC12<>"",TODAY()>AC12),"تاخیر",IF(L12<>"","در حال انجام","")))))) | U12: =IF(T12="تاخیر",TODAY()-AC12,IF(AND(T12="بسته",AG12<>"",AC12<>"",AG12>AC12),AG12-AC12,0)) -> 0 | V12: =IF(L12="","",VALUE(LEFT(L12,FIND("/",L12)-1))) | W12: =IF(L12="","",VALUE(MID(L12,FIND("/",L12)+1,FIND("/",L12,FIND("/",L12)+1)-FIND("/",L12)-1))) | X12: =IF(L12="","",VALUE(MID(L12,FIND("/",L12,FIND("/",L12)+1)+1,LEN(L12)-FIND("/",L12,FIND("/",L12)+1)))) | Y12: =IF(OR(L12="",V12=""),"",IFERROR(INDEX(لیست‌ها!$Q$3:$Q$53,MATCH(V12,لیست‌ها!$P$3:$P$53,0))+IF(W12<=6,(W12-1)*31+X12,IF(W12<=11,186+(W12-7)*30+X12,336+X12))-1,"")) | Z12: =IF(H12="","",VALUE(LEFT(H12,FIND("/",H12)-1))) | AA12: =IF(H12="","",VALUE(MID(H12,FIND("/",H12)+1,FIND("/",H12,FIND("/",H12)+1)-FIND("/",H12)-1))) | AB12: =IF(H12="","",VALUE(MID(H12,FIND("/",H12,FIND("/",H12)+1)+1,LEN(H12)-FIND("/",H12,FIND("/",H12)+1)))) | AC12: =IF(OR(H12="",Z12=""),"",IFERROR(INDEX(لیست‌ها!$Q$3:$Q$53,MATCH(Z12,لیست‌ها!$P$3:$P$53,0))+IF(AA12<=6,(AA12-1)*31+AB12,IF(AA12<=11,186+(AA12-7)*30+AB12,336+AB12))-1,"")) | AD12: =IF(O12="","",VALUE(LEFT(O12,FIND("/",O12)-1))) | AE12: =IF(O12="","",VALUE(MID(O12,FIND("/",O12)+1,FIND("/",O12,FIND("/",O12)+1)-FIND("/",O12)-1))) | AF12: =IF(O12="","",VALUE(MID(O12,FIND("/",O12,FIND("/",O12)+1)+1,LEN(O12)-FIND("/",O12,FIND("/",O12)+1)))) | AG12: =IF(OR(O12="",AD12=""),"",IFERROR(INDEX(لیست‌ها!$Q$3:$Q$53,MATCH(AD12,لیست‌ها!$P$3:$P$53,0))+IF(AE12<=6,(AE12-1)*31+AF12,IF(AE12<=11,186+(AE12-7)*30+AF12,336+AF12))-1,"")) | AH12: =IF(V12="","",V12&"-"&TEXT(W12,"00")) | AI12: =IF(V12="","",V12*12+W12) | AJ12: =IF(T12="تاخیر",U12+ROW()/100000,"")
A13: 10 | B13: SALE\05\10 | C13: اقدام اصلاحی | D13: کلیم | T13: =IF(B13="","",IF(OR(I13<>"",O13<>""),"بسته",IF(AND(L13<>"",V13=""),"خطای فرمت تاریخ ایجاد",IF(AND(H13<>"",Z13=""),"خطای فرمت مهلت",IF(AND(H13<>"",AC13<>"",TODAY()>AC13),"تاخیر",IF(L13<>"","در حال انجام","")))))) | U13: =IF(T13="تاخیر",TODAY()-AC13,IF(AND(T13="بسته",AG13<>"",AC13<>"",AG13>AC13),AG13-AC13,0)) -> 0 | V13: =IF(L13="","",VALUE(LEFT(L13,FIND("/",L13)-1))) | W13: =IF(L13="","",VALUE(MID(L13,FIND("/",L13)+1,FIND("/",L13,FIND("/",L13)+1)-FIND("/",L13)-1))) | X13: =IF(L13="","",VALUE(MID(L13,FIND("/",L13,FIND("/",L13)+1)+1,LEN(L13)-FIND("/",L13,FIND("/",L13)+1)))) | Y13: =IF(OR(L13="",V13=""),"",IFERROR(INDEX(لیست‌ها!$Q$3:$Q$53,MATCH(V13,لیست‌ها!$P$3:$P$53,0))+IF(W13<=6,(W13-1)*31+X13,IF(W13<=11,186+(W13-7)*30+X13,336+X13))-1,"")) | Z13: =IF(H13="","",VALUE(LEFT(H13,FIND("/",H13)-1))) | AA13: =IF(H13="","",VALUE(MID(H13,FIND("/",H13)+1,FIND("/",H13,FIND("/",H13)+1)-FIND("/",H13)-1))) | AB13: =IF(H13="","",VALUE(MID(H13,FIND("/",H13,FIND("/",H13)+1)+1,LEN(H13)-FIND("/",H13,FIND("/",H13)+1)))) | AC13: =IF(OR(H13="",Z13=""),"",IFERROR(INDEX(لیست‌ها!$Q$3:$Q$53,MATCH(Z13,لیست‌ها!$P$3:$P$53,0))+IF(AA13<=6,(AA13-1)*31+AB13,IF(AA13<=11,186+(AA13-7)*30+AB13,336+AB13))-1,"")) | AD13: =IF(O13="","",VALUE(LEFT(O13,FIND("/",O13)-1))) | AE13: =IF(O13="","",VALUE(MID(O13,FIND("/",O13)+1,FIND("/",O13,FIND("/",O13)+1)-FIND("/",O13)-1))) | AF13: =IF(O13="","",VALUE(MID(O13,FIND("/",O13,FIND("/",O13)+1)+1,LEN(O13)-FIND("/",O13,FIND("/",O13)+1)))) | AG13: =IF(OR(O13="",AD13=""),"",IFERROR(INDEX(لیست‌ها!$Q$3:$Q$53,MATCH(AD13,لیست‌ها!$P$3:$P$53,0))+IF(AE13<=6,(AE13-1)*31+AF13,IF(AE13<=11,186+(AE13-7)*30+AF13,336+AF13))-1,"")) | AH13: =IF(V13="","",V13&"-"&TEXT(W13,"00")) | AI13: =IF(V13="","",V13*12+W13) | AJ13: =IF(T13="تاخیر",U13+ROW()/100000,"")
A14: 11 | B14: SALE\05\11 | C14: اقدام اصلاحی | D14: کلیم | T14: =IF(B14="","",IF(OR(I14<>"",O14<>""),"بسته",IF(AND(L14<>"",V14=""),"خطای فرمت تاریخ ایجاد",IF(AND(H14<>"",Z14=""),"خطای فرمت مهلت",IF(AND(H14<>"",AC14<>"",TODAY()>AC14),"تاخیر",IF(L14<>"","در حال انجام","")))))) | U14: =IF(T14="تاخیر",TODAY()-AC14,IF(AND(T14="بسته",AG14<>"",AC14<>"",AG14>AC14),AG14-AC14,0)) -> 0 | V14: =IF(L14="","",VALUE(LEFT(L14,FIND("/",L14)-1))) | W14: =IF(L14="","",VALUE(MID(L14,FIND("/",L14)+1,FIND("/",L14,FIND("/",L14)+1)-FIND("/",L14)-1))) | X14: =IF(L14="","",VALUE(MID(L14,FIND("/",L14,FIND("/",L14)+1)+1,LEN(L14)-FIND("/",L14,FIND("/",L14)+1)))) | Y14: =IF(OR(L14="",V14=""),"",IFERROR(INDEX(لیست‌ها!$Q$3:$Q$53,MATCH(V14,لیست‌ها!$P$3:$P$53,0))+IF(W14<=6,(W14-1)*31+X14,IF(W14<=11,186+(W14-7)*30+X14,336+X14))-1,"")) | Z14: =IF(H14="","",VALUE(LEFT(H14,FIND("/",H14)-1))) | AA14: =IF(H14="","",VALUE(MID(H14,FIND("/",H14)+1,FIND("/",H14,FIND("/",H14)+1)-FIND("/",H14)-1))) | AB14: =IF(H14="","",VALUE(MID(H14,FIND("/",H14,FIND("/",H14)+1)+1,LEN(H14)-FIND("/",H14,FIND("/",H14)+1)))) | AC14: =IF(OR(H14="",Z14=""),"",IFERROR(INDEX(لیست‌ها!$Q$3:$Q$53,MATCH(Z14,لیست‌ها!$P$3:$P$53,0))+IF(AA14<=6,(AA14-1)*31+AB14,IF(AA14<=11,186+(AA14-7)*30+AB14,336+AB14))-1,"")) | AD14: =IF(O14="","",VALUE(LEFT(O14,FIND("/",O14)-1))) | AE14: =IF(O14="","",VALUE(MID(O14,FIND("/",O14)+1,FIND("/",O14,FIND("/",O14)+1)-FIND("/",O14)-1))) | AF14: =IF(O14="","",VALUE(MID(O14,FIND("/",O14,FIND("/",O14)+1)+1,LEN(O14)-FIND("/",O14,FIND("/",O14)+1)))) | AG14: =IF(OR(O14="",AD14=""),"",IFERROR(INDEX(لیست‌ها!$Q$3:$Q$53,MATCH(AD14,لیست‌ها!$P$3:$P$53,0))+IF(AE14<=6,(AE14-1)*31+AF14,IF(AE14<=11,186+(AE14-7)*30+AF14,336+AF14))-1,"")) | AH14: =IF(V14="","",V14&"-"&TEXT(W14,"00")) | AI14: =IF(V14="","",V14*12+W14) | AJ14: =IF(T14="تاخیر",U14+ROW()/100000,"")
A15: 12 | B15: SALE\05\12 | C15: اقدام اصلاحی | D15: کلیم | T15: =IF(B15="","",IF(OR(I15<>"",O15<>""),"بسته",IF(AND(L15<>"",V15=""),"خطای فرمت تاریخ ایجاد",IF(AND(H15<>"",Z15=""),"خطای فرمت مهلت",IF(AND(H15<>"",AC15<>"",TODAY()>AC15),"تاخیر",IF(L15<>"","در حال انجام","")))))) | U15: =IF(T15="تاخیر",TODAY()-AC15,IF(AND(T15="بسته",AG15<>"",AC15<>"",AG15>AC15),AG15-AC15,0)) -> 0 | V15: =IF(L15="","",VALUE(LEFT(L15,FIND("/",L15)-1))) | W15: =IF(L15="","",VALUE(MID(L15,FIND("/",L15)+1,FIND("/",L15,FIND("/",L15)+1)-FIND("/",L15)-1))) | X15: =IF(L15="","",VALUE(MID(L15,FIND("/",L15,FIND("/",L15)+1)+1,LEN(L15)-FIND("/",L15,FIND("/",L15)+1)))) | Y15: =IF(OR(L15="",V15=""),"",IFERROR(INDEX(لیست‌ها!$Q$3:$Q$53,MATCH(V15,لیست‌ها!$P$3:$P$53,0))+IF(W15<=6,(W15-1)*31+X15,IF(W15<=11,186+(W15-7)*30+X15,336+X15))-1,"")) | Z15: =IF(H15="","",VALUE(LEFT(H15,FIND("/",H15)-1))) | AA15: =IF(H15="","",VALUE(MID(H15,FIND("/",H15)+1,FIND("/",H15,FIND("/",H15)+1)-FIND("/",H15)-1))) | AB15: =IF(H15="","",VALUE(MID(H15,FIND("/",H15,FIND("/",H15)+1)+1,LEN(H15)-FIND("/",H15,FIND("/",H15)+1)))) | AC15: =IF(OR(H15="",Z15=""),"",IFERROR(INDEX(لیست‌ها!$Q$3:$Q$53,MATCH(Z15,لیست‌ها!$P$3:$P$53,0))+IF(AA15<=6,(AA15-1)*31+AB15,IF(AA15<=11,186+(AA15-7)*30+AB15,336+AB15))-1,"")) | AD15: =IF(O15="","",VALUE(LEFT(O15,FIND("/",O15)-1))) | AE15: =IF(O15="","",VALUE(MID(O15,FIND("/",O15)+1,FIND("/",O15,FIND("/",O15)+1)-FIND("/",O15)-1))) | AF15: =IF(O15="","",VALUE(MID(O15,FIND("/",O15,FIND("/",O15)+1)+1,LEN(O15)-FIND("/",O15,FIND("/",O15)+1)))) | AG15: =IF(OR(O15="",AD15=""),"",IFERROR(INDEX(لیست‌ها!$Q$3:$Q$53,MATCH(AD15,لیست‌ها!$P$3:$P$53,0))+IF(AE15<=6,(AE15-1)*31+AF15,IF(AE15<=11,186+(AE15-7)*30+AF15,336+AF15))-1,"")) | AH15: =IF(V15="","",V15&"-"&TEXT(W15,"00")) | AI15: =IF(V15="","",V15*12+W15) | AJ15: =IF(T15="تاخیر",U15+ROW()/100000,"")
A16: 13 | B16: SALE\05\13 | C16: اقدام اصلاحی | D16: کلیم | T16: =IF(B16="","",IF(OR(I16<>"",O16<>""),"بسته",IF(AND(L16<>"",V16=""),"خطای فرمت تاریخ ایجاد",IF(AND(H16<>"",Z16=""),"خطای فرمت مهلت",IF(AND(H16<>"",AC16<>"",TODAY()>AC16),"تاخیر",IF(L16<>"","در حال انجام","")))))) | U16: =IF(T16="تاخیر",TODAY()-AC16,IF(AND(T16="بسته",AG16<>"",AC16<>"",AG16>AC16),AG16-AC16,0)) -> 0 | V16: =IF(L16="","",VALUE(LEFT(L16,FIND("/",L16)-1))) | W16: =IF(L16="","",VALUE(MID(L16,FIND("/",L16)+1,FIND("/",L16,FIND("/",L16)+1)-FIND("/",L16)-1))) | X16: =IF(L16="","",VALUE(MID(L16,FIND("/",L16,FIND("/",L16)+1)+1,LEN(L16)-FIND("/",L16,FIND("/",L16)+1)))) | Y16: =IF(OR(L16="",V16=""),"",IFERROR(INDEX(لیست‌ها!$Q$3:$Q$53,MATCH(V16,لیست‌ها!$P$3:$P$53,0))+IF(W16<=6,(W16-1)*31+X16,IF(W16<=11,186+(W16-7)*30+X16,336+X16))-1,"")) | Z16: =IF(H16="","",VALUE(LEFT(H16,FIND("/",H16)-1))) | AA16: =IF(H16="","",VALUE(MID(H16,FIND("/",H16)+1,FIND("/",H16,FIND("/",H16)+1)-FIND("/",H16)-1))) | AB16: =IF(H16="","",VALUE(MID(H16,FIND("/",H16,FIND("/",H16)+1)+1,LEN(H16)-FIND("/",H16,FIND("/",H16)+1)))) | AC16: =IF(OR(H16="",Z16=""),"",IFERROR(INDEX(لیست‌ها!$Q$3:$Q$53,MATCH(Z16,لیست‌ها!$P$3:$P$53,0))+IF(AA16<=6,(AA16-1)*31+AB16,IF(AA16<=11,186+(AA16-7)*30+AB16,336+AB16))-1,"")) | AD16: =IF(O16="","",VALUE(LEFT(O16,FIND("/",O16)-1))) | AE16: =IF(O16="","",VALUE(MID(O16,FIND("/",O16)+1,FIND("/",O16,FIND("/",O16)+1)-FIND("/",O16)-1))) | AF16: =IF(O16="","",VALUE(MID(O16,FIND("/",O16,FIND("/",O16)+1)+1,LEN(O16)-FIND("/",O16,FIND("/",O16)+1)))) | AG16: =IF(OR(O16="",AD16=""),"",IFERROR(INDEX(لیست‌ها!$Q$3:$Q$53,MATCH(AD16,لیست‌ها!$P$3:$P$53,0))+IF(AE16<=6,(AE16-1)*31+AF16,IF(AE16<=11,186+(AE16-7)*30+AF16,336+AF16))-1,"")) | AH16: =IF(V16="","",V16&"-"&TEXT(W16,"00")) | AI16: =IF(V16="","",V16*12+W16) | AJ16: =IF(T16="تاخیر",U16+ROW()/100000,"")
A17: 14 | B17: PL\05\14 | C17: اقدام پیشگیرانه | D17: سایر | T17: =IF(B17="","",IF(OR(I17<>"",O17<>""),"بسته",IF(AND(L17<>"",V17=""),"خطای فرمت تاریخ ایجاد",IF(AND(H17<>"",Z17=""),"خطای فرمت مهلت",IF(AND(H17<>"",AC17<>"",TODAY()>AC17),"تاخیر",IF(L17<>"","در حال انجام","")))))) | U17: =IF(T17="تاخیر",TODAY()-AC17,IF(AND(T17="بسته",AG17<>"",AC17<>"",AG17>AC17),AG17-AC17,0)) -> 0 | V17: =IF(L17="","",VALUE(LEFT(L17,FIND("/",L17)-1))) | W17: =IF(L17="","",VALUE(MID(L17,FIND("/",L17)+1,FIND("/",L17,FIND("/",L17)+1)-FIND("/",L17)-1))) | X17: =IF(L17="","",VALUE(MID(L17,FIND("/",L17,FIND("/",L17)+1)+1,LEN(L17)-FIND("/",L17,FIND("/",L17)+1)))) | Y17: =IF(OR(L17="",V17=""),"",IFERROR(INDEX(لیست‌ها!$Q$3:$Q$53,MATCH(V17,لیست‌ها!$P$3:$P$53,0))+IF(W17<=6,(W17-1)*31+X17,IF(W17<=11,186+(W17-7)*30+X17,336+X17))-1,"")) | Z17: =IF(H17="","",VALUE(LEFT(H17,FIND("/",H17)-1))) | AA17: =IF(H17="","",VALUE(MID(H17,FIND("/",H17)+1,FIND("/",H17,FIND("/",H17)+1)-FIND("/",H17)-1))) | AB17: =IF(H17="","",VALUE(MID(H17,FIND("/",H17,FIND("/",H17)+1)+1,LEN(H17)-FIND("/",H17,FIND("/",H17)+1)))) | AC17: =IF(OR(H17="",Z17=""),"",IFERROR(INDEX(لیست‌ها!$Q$3:$Q$53,MATCH(Z17,لیست‌ها!$P$3:$P$53,0))+IF(AA17<=6,(AA17-1)*31+AB17,IF(AA17<=11,186+(AA17-7)*30+AB17,336+AB17))-1,"")) | AD17: =IF(O17="","",VALUE(LEFT(O17,FIND("/",O17)-1))) | AE17: =IF(O17="","",VALUE(MID(O17,FIND("/",O17)+1,FIND("/",O17,FIND("/",O17)+1)-FIND("/",O17)-1))) | AF17: =IF(O17="","",VALUE(MID(O17,FIND("/",O17,FIND("/",O17)+1)+1,LEN(O17)-FIND("/",O17,FIND("/",O17)+1)))) | AG17: =IF(OR(O17="",AD17=""),"",IFERROR(INDEX(لیست‌ها!$Q$3:$Q$53,MATCH(AD17,لیست‌ها!$P$3:$P$53,0))+IF(AE17<=6,(AE17-1)*31+AF17,IF(AE17<=11,186+(AE17-7)*30+AF17,336+AF17))-1,"")) | AH17: =IF(V17="","",V17&"-"&TEXT(W17,"00")) | AI17: =IF(V17="","",V17*12+W17) | AJ17: =IF(T17="تاخیر",U17+ROW()/100000,"")
A18: 15 | B18: PL\05\15 | C18: اقدام اصلاحی | D18: سایر | T18: =IF(B18="","",IF(OR(I18<>"",O18<>""),"بسته",IF(AND(L18<>"",V18=""),"خطای فرمت تاریخ ایجاد",IF(AND(H18<>"",Z18=""),"خطای فرمت مهلت",IF(AND(H18<>"",AC18<>"",TODAY()>AC18),"تاخیر",IF(L18<>"","در حال انجام","")))))) | U18: =IF(T18="تاخیر",TODAY()-AC18,IF(AND(T18="بسته",AG18<>"",AC18<>"",AG18>AC18),AG18-AC18,0)) -> 0 | V18: =IF(L18="","",VALUE(LEFT(L18,FIND("/",L18)-1))) | W18: =IF(L18="","",VALUE(MID(L18,FIND("/",L18)+1,FIND("/",L18,FIND("/",L18)+1)-FIND("/",L18)-1))) | X18: =IF(L18="","",VALUE(MID(L18,FIND("/",L18,FIND("/",L18)+1)+1,LEN(L18)-FIND("/",L18,FIND("/",L18)+1)))) | Y18: =IF(OR(L18="",V18=""),"",IFERROR(INDEX(لیست‌ها!$Q$3:$Q$53,MATCH(V18,لیست‌ها!$P$3:$P$53,0))+IF(W18<=6,(W18-1)*31+X18,IF(W18<=11,186+(W18-7)*30+X18,336+X18))-1,"")) | Z18: =IF(H18="","",VALUE(LEFT(H18,FIND("/",H18)-1))) | AA18: =IF(H18="","",VALUE(MID(H18,FIND("/",H18)+1,FIND("/",H18,FIND("/",H18)+1)-FIND("/",H18)-1))) | AB18: =IF(H18="","",VALUE(MID(H18,FIND("/",H18,FIND("/",H18)+1)+1,LEN(H18)-FIND("/",H18,FIND("/",H18)+1)))) | AC18: =IF(OR(H18="",Z18=""),"",IFERROR(INDEX(لیست‌ها!$Q$3:$Q$53,MATCH(Z18,لیست‌ها!$P$3:$P$53,0))+IF(AA18<=6,(AA18-1)*31+AB18,IF(AA18<=11,186+(AA18-7)*30+AB18,336+AB18))-1,"")) | AD18: =IF(O18="","",VALUE(LEFT(O18,FIND("/",O18)-1))) | AE18: =IF(O18="","",VALUE(MID(O18,FIND("/",O18)+1,FIND("/",O18,FIND("/",O18)+1)-FIND("/",O18)-1))) | AF18: =IF(O18="","",VALUE(MID(O18,FIND("/",O18,FIND("/",O18)+1)+1,LEN(O18)-FIND("/",O18,FIND("/",O18)+1)))) | AG18: =IF(OR(O18="",AD18=""),"",IFERROR(INDEX(لیست‌ها!$Q$3:$Q$53,MATCH(AD18,لیست‌ها!$P$3:$P$53,0))+IF(AE18<=6,(AE18-1)*31+AF18,IF(AE18<=11,186+(AE18-7)*30+AF18,336+AF18))-1,"")) | AH18: =IF(V18="","",V18&"-"&TEXT(W18,"00")) | AI18: =IF(V18="","",V18*12+W18) | AJ18: =IF(T18="تاخیر",U18+ROW()/100000,"")
A19: 16 | B19: des\05\16 | C19: اقدام اصلاحی | D19: پایش فرآیندها و تجزیه و تحلیل | T19: =IF(B19="","",IF(OR(I19<>"",O19<>""),"بسته",IF(AND(L19<>"",V19=""),"خطای فرمت تاریخ ایجاد",IF(AND(H19<>"",Z19=""),"خطای فرمت مهلت",IF(AND(H19<>"",AC19<>"",TODAY()>AC19),"تاخیر",IF(L19<>"","در حال انجام","")))))) | U19: =IF(T19="تاخیر",TODAY()-AC19,IF(AND(T19="بسته",AG19<>"",AC19<>"",AG19>AC19),AG19-AC19,0)) -> 0 | V19: =IF(L19="","",VALUE(LEFT(L19,FIND("/",L19)-1))) | W19: =IF(L19="","",VALUE(MID(L19,FIND("/",L19)+1,FIND("/",L19,FIND("/",L19)+1)-FIND("/",L19)-1))) | X19: =IF(L19="","",VALUE(MID(L19,FIND("/",L19,FIND("/",L19)+1)+1,LEN(L19)-FIND("/",L19,FIND("/",L19)+1)))) | Y19: =IF(OR(L19="",V19=""),"",IFERROR(INDEX(لیست‌ها!$Q$3:$Q$53,MATCH(V19,لیست‌ها!$P$3:$P$53,0))+IF(W19<=6,(W19-1)*31+X19,IF(W19<=11,186+(W19-7)*30+X19,336+X19))-1,"")) | Z19: =IF(H19="","",VALUE(LEFT(H19,FIND("/",H19)-1))) | AA19: =IF(H19="","",VALUE(MID(H19,FIND("/",H19)+1,FIND("/",H19,FIND("/",H19)+1)-FIND("/",H19)-1))) | AB19: =IF(H19="","",VALUE(MID(H19,FIND("/",H19,FIND("/",H19)+1)+1,LEN(H19)-FIND("/",H19,FIND("/",H19)+1)))) | AC19: =IF(OR(H19="",Z19=""),"",IFERROR(INDEX(لیست‌ها!$Q$3:$Q$53,MATCH(Z19,لیست‌ها!$P$3:$P$53,0))+IF(AA19<=6,(AA19-1)*31+AB19,IF(AA19<=11,186+(AA19-7)*30+AB19,336+AB19))-1,"")) | AD19: =IF(O19="","",VALUE(LEFT(O19,FIND("/",O19)-1))) | AE19: =IF(O19="","",VALUE(MID(O19,FIND("/",O19)+1,FIND("/",O19,FIND("/",O19)+1)-FIND("/",O19)-1))) | AF19: =IF(O19="","",VALUE(MID(O19,FIND("/",O19,FIND("/",O19)+1)+1,LEN(O19)-FIND("/",O19,FIND("/",O19)+1)))) | AG19: =IF(OR(O19="",AD19=""),"",IFERROR(INDEX(لیست‌ها!$Q$3:$Q$53,MATCH(AD19,لیست‌ها!$P$3:$P$53,0))+IF(AE19<=6,(AE19-1)*31+AF19,IF(AE19<=11,186+(AE19-7)*30+AF19,336+AF19))-1,"")) | AH19: =IF(V19="","",V19&"-"&TEXT(W19,"00")) | AI19: =IF(V19="","",V19*12+W19) | AJ19: =IF(T19="تاخیر",U19+ROW()/100000,"")
... A258: 255 | B258: PR\05\255 | C258: اقدام اصلاحی | D258: پایش فرآیندها و تجزیه و تحلیل | T258: =IF(B258="","",IF(OR(I258<>"",O258<>""),"بسته",IF(AND(L258<>"",V258=""),"خطای فرمت تاریخ ایجاد",IF(AND(H258<>"",Z258=""),"خطای فرمت مهلت",IF(AND(H258<>"",AC258<>"",TODAY()>AC258),"تاخیر",IF(L258<>"","در حال انجام","")))))) | U258: =IF(T258="تاخیر",TODAY()-AC258,IF(AND(T258="بسته",AG258<>"",AC258<>"",AG258>AC258),AG258-AC258,0)) -> 0 | V258: =IF(L258="","",VALUE(LEFT(L258,FIND("/",L258)-1))) | W258: =IF(L258="","",VALUE(MID(L258,FIND("/",L258)+1,FIND("/",L258,FIND("/",L258)+1)-FIND("/",L258)-1))) | X258: =IF(L258="","",VALUE(MID(L258,FIND("/",L258,FIND("/",L258)+1)+1,LEN(L258)-FIND("/",L258,FIND("/",L258)+1)))) | Y258: =IF(OR(L258="",V258=""),"",IFERROR(INDEX(لیست‌ها!$Q$3:$Q$53,MATCH(V258,لیست‌ها!$P$3:$P$53,0))+IF(W258<=6,(W258-1)*31+X258,IF(W258<=11,186+(W258-7)*30+X258,336+X258))-1,"")) | Z258: =IF(H258="","",VALUE(LEFT(H258,FIND("/",H258)-1))) | AA258: =IF(H258="","",VALUE(MID(H258,FIND("/",H258)+1,FIND("/",H258,FIND("/",H258)+1)-FIND("/",H258)-1))) | AB258: =IF(H258="","",VALUE(MID(H258,FIND("/",H258,FIND("/",H258)+1)+1,LEN(H258)-FIND("/",H258,FIND("/",H258)+1)))) | AC258: =IF(OR(H258="",Z258=""),"",IFERROR(INDEX(لیست‌ها!$Q$3:$Q$53,MATCH(Z258,لیست‌ها!$P$3:$P$53,0))+IF(AA258<=6,(AA258-1)*31+AB258,IF(AA258<=11,186+(AA258-7)*30+AB258,336+AB258))-1,"")) | AD258: =IF(O258="","",VALUE(LEFT(O258,FIND("/",O258)-1))) | AE258: =IF(O258="","",VALUE(MID(O258,FIND("/",O258)+1,FIND("/",O258,FIND("/",O258)+1)-FIND("/",O258)-1))) | AF258: =IF(O258="","",VALUE(MID(O258,FIND("/",O258,FIND("/",O258)+1)+1,LEN(O258)-FIND("/",O258,FIND("/",O258)+1)))) | AG258: =IF(OR(O258="",AD258=""),"",IFERROR(INDEX(لیست‌ها!$Q$3:$Q$53,MATCH(AD258,لیست‌ها!$P$3:$P$53,0))+IF(AE258<=6,(AE258-1)*31+AF258,IF(AE258<=11,186+(AE258-7)*30+AF258,336+AF258))-1,"")) | AH258: =IF(V258="","",V258&"-"&TEXT(W258,"00")) | AI258: =IF(V258="","",V258*12+W258) | AJ258: =IF(T258="تاخیر",U258+ROW()/100000,"")
A259: 256 | T259: =IF(B259="","",IF(OR(I259<>"",O259<>""),"بسته",IF(AND(L259<>"",V259=""),"خطای فرمت تاریخ ایجاد",IF(AND(H259<>"",Z259=""),"خطای فرمت مهلت",IF(AND(H259<>"",AC259<>"",TODAY()>AC259),"تاخیر",IF(L259<>"","در حال انجام","")))))) | U259: =IF(T259="تاخیر",TODAY()-AC259,IF(AND(T259="بسته",AG259<>"",AC259<>"",AG259>AC259),AG259-AC259,0)) -> 0 | V259: =IF(L259="","",VALUE(LEFT(L259,FIND("/",L259)-1))) | W259: =IF(L259="","",VALUE(MID(L259,FIND("/",L259)+1,FIND("/",L259,FIND("/",L259)+1)-FIND("/",L259)-1))) | X259: =IF(L259="","",VALUE(MID(L259,FIND("/",L259,FIND("/",L259)+1)+1,LEN(L259)-FIND("/",L259,FIND("/",L259)+1)))) | Y259: =IF(OR(L259="",V259=""),"",IFERROR(INDEX(لیست‌ها!$Q$3:$Q$53,MATCH(V259,لیست‌ها!$P$3:$P$53,0))+IF(W259<=6,(W259-1)*31+X259,IF(W259<=11,186+(W259-7)*30+X259,336+X259))-1,"")) | Z259: =IF(H259="","",VALUE(LEFT(H259,FIND("/",H259)-1))) | AA259: =IF(H259="","",VALUE(MID(H259,FIND("/",H259)+1,FIND("/",H259,FIND("/",H259)+1)-FIND("/",H259)-1))) | AB259: =IF(H259="","",VALUE(MID(H259,FIND("/",H259,FIND("/",H259)+1)+1,LEN(H259)-FIND("/",H259,FIND("/",H259)+1)))) | AC259: =IF(OR(H259="",Z259=""),"",IFERROR(INDEX(لیست‌ها!$Q$3:$Q$53,MATCH(Z259,لیست‌ها!$P$3:$P$53,0))+IF(AA259<=6,(AA259-1)*31+AB259,IF(AA259<=11,186+(AA259-7)*30+AB259,336+AB259))-1,"")) | AD259: =IF(O259="","",VALUE(LEFT(O259,FIND("/",O259)-1))) | AE259: =IF(O259="","",VALUE(MID(O259,FIND("/",O259)+1,FIND("/",O259,FIND("/",O259)+1)-FIND("/",O259)-1))) | AF259: =IF(O259="","",VALUE(MID(O259,FIND("/",O259,FIND("/",O259)+1)+1,LEN(O259)-FIND("/",O259,FIND("/",O259)+1)))) | AG259: =IF(OR(O259="",AD259=""),"",IFERROR(INDEX(لیست‌ها!$Q$3:$Q$53,MATCH(AD259,لیست‌ها!$P$3:$P$53,0))+IF(AE259<=6,(AE259-1)*31+AF259,IF(AE259<=11,186+(AE259-7)*30+AF259,336+AF259))-1,"")) | AH259: =IF(V259="","",V259&"-"&TEXT(W259,"00")) | AI259: =IF(V259="","",V259*12+W259) | AJ259: =IF(T259="تاخیر",U259+ROW()/100000,"")
A260: 257 | T260: =IF(B260="","",IF(OR(I260<>"",O260<>""),"بسته",IF(AND(L260<>"",V260=""),"خطای فرمت تاریخ ایجاد",IF(AND(H260<>"",Z260=""),"خطای فرمت مهلت",IF(AND(H260<>"",AC260<>"",TODAY()>AC260),"تاخیر",IF(L260<>"","در حال انجام","")))))) | U260: =IF(T260="تاخیر",TODAY()-AC260,IF(AND(T260="بسته",AG260<>"",AC260<>"",AG260>AC260),AG260-AC260,0)) -> 0 | V260: =IF(L260="","",VALUE(LEFT(L260,FIND("/",L260)-1))) | W260: =IF(L260="","",VALUE(MID(L260,FIND("/",L260)+1,FIND("/",L260,FIND("/",L260)+1)-FIND("/",L260)-1))) | X260: =IF(L260="","",VALUE(MID(L260,FIND("/",L260,FIND("/",L260)+1)+1,LEN(L260)-FIND("/",L260,FIND("/",L260)+1)))) | Y260: =IF(OR(L260="",V260=""),"",IFERROR(INDEX(لیست‌ها!$Q$3:$Q$53,MATCH(V260,لیست‌ها!$P$3:$P$53,0))+IF(W260<=6,(W260-1)*31+X260,IF(W260<=11,186+(W260-7)*30+X260,336+X260))-1,"")) | Z260: =IF(H260="","",VALUE(LEFT(H260,FIND("/",H260)-1))) | AA260: =IF(H260="","",VALUE(MID(H260,FIND("/",H260)+1,FIND("/",H260,FIND("/",H260)+1)-FIND("/",H260)-1))) | AB260: =IF(H260="","",VALUE(MID(H260,FIND("/",H260,FIND("/",H260)+1)+1,LEN(H260)-FIND("/",H260,FIND("/",H260)+1)))) | AC260: =IF(OR(H260="",Z260=""),"",IFERROR(INDEX(لیست‌ها!$Q$3:$Q$53,MATCH(Z260,لیست‌ها!$P$3:$P$53,0))+IF(AA260<=6,(AA260-1)*31+AB260,IF(AA260<=11,186+(AA260-7)*30+AB260,336+AB260))-1,"")) | AD260: =IF(O260="","",VALUE(LEFT(O260,FIND("/",O260)-1))) | AE260: =IF(O260="","",VALUE(MID(O260,FIND("/",O260)+1,FIND("/",O260,FIND("/",O260)+1)-FIND("/",O260)-1))) | AF260: =IF(O260="","",VALUE(MID(O260,FIND("/",O260,FIND("/",O260)+1)+1,LEN(O260)-FIND("/",O260,FIND("/",O260)+1)))) | AG260: =IF(OR(O260="",AD260=""),"",IFERROR(INDEX(لیست‌ها!$Q$3:$Q$53,MATCH(AD260,لیست‌ها!$P$3:$P$53,0))+IF(AE260<=6,(AE260-1)*31+AF260,IF(AE260<=11,186+(AE260-7)*30+AF260,336+AF260))-1,"")) | AH260: =IF(V260="","",V260&"-"&TEXT(W260,"00")) | AI260: =IF(V260="","",V260*12+W260) | AJ260: =IF(T260="تاخیر",U260+ROW()/100000,"")
A261: 258 | T261: =IF(B261="","",IF(OR(I261<>"",O261<>""),"بسته",IF(AND(L261<>"",V261=""),"خطای فرمت تاریخ ایجاد",IF(AND(H261<>"",Z261=""),"خطای فرمت مهلت",IF(AND(H261<>"",AC261<>"",TODAY()>AC261),"تاخیر",IF(L261<>"","در حال انجام","")))))) | U261: =IF(T261="تاخیر",TODAY()-AC261,IF(AND(T261="بسته",AG261<>"",AC261<>"",AG261>AC261),AG261-AC261,0)) -> 0 | V261: =IF(L261="","",VALUE(LEFT(L261,FIND("/",L261)-1))) | W261: =IF(L261="","",VALUE(MID(L261,FIND("/",L261)+1,FIND("/",L261,FIND("/",L261)+1)-FIND("/",L261)-1))) | X261: =IF(L261="","",VALUE(MID(L261,FIND("/",L261,FIND("/",L261)+1)+1,LEN(L261)-FIND("/",L261,FIND("/",L261)+1)))) | Y261: =IF(OR(L261="",V261=""),"",IFERROR(INDEX(لیست‌ها!$Q$3:$Q$53,MATCH(V261,لیست‌ها!$P$3:$P$53,0))+IF(W261<=6,(W261-1)*31+X261,IF(W261<=11,186+(W261-7)*30+X261,336+X261))-1,"")) | Z261: =IF(H261="","",VALUE(LEFT(H261,FIND("/",H261)-1))) | AA261: =IF(H261="","",VALUE(MID(H261,FIND("/",H261)+1,FIND("/",H261,FIND("/",H261)+1)-FIND("/",H261)-1))) | AB261: =IF(H261="","",VALUE(MID(H261,FIND("/",H261,FIND("/",H261)+1)+1,LEN(H261)-FIND("/",H261,FIND("/",H261)+1)))) | AC261: =IF(OR(H261="",Z261=""),"",IFERROR(INDEX(لیست‌ها!$Q$3:$Q$53,MATCH(Z261,لیست‌ها!$P$3:$P$53,0))+IF(AA261<=6,(AA261-1)*31+AB261,IF(AA261<=11,186+(AA261-7)*30+AB261,336+AB261))-1,"")) | AD261: =IF(O261="","",VALUE(LEFT(O261,FIND("/",O261)-1))) | AE261: =IF(O261="","",VALUE(MID(O261,FIND("/",O261)+1,FIND("/",O261,FIND("/",O261)+1)-FIND("/",O261)-1))) | AF261: =IF(O261="","",VALUE(MID(O261,FIND("/",O261,FIND("/",O261)+1)+1,LEN(O261)-FIND("/",O261,FIND("/",O261)+1)))) | AG261: =IF(OR(O261="",AD261=""),"",IFERROR(INDEX(لیست‌ها!$Q$3:$Q$53,MATCH(AD261,لیست‌ها!$P$3:$P$53,0))+IF(AE261<=6,(AE261-1)*31+AF261,IF(AE261<=11,186+(AE261-7)*30+AF261,336+AF261))-1,"")) | AH261: =IF(V261="","",V261&"-"&TEXT(W261,"00")) | AI261: =IF(V261="","",V261*12+W261) | AJ261: =IF(T261="تاخیر",U261+ROW()/100000,"")
A262: 259 | T262: =IF(B262="","",IF(OR(I262<>"",O262<>""),"بسته",IF(AND(L262<>"",V262=""),"خطای فرمت تاریخ ایجاد",IF(AND(H262<>"",Z262=""),"خطای فرمت مهلت",IF(AND(H262<>"",AC262<>"",TODAY()>AC262),"تاخیر",IF(L262<>"","در حال انجام","")))))) | U262: =IF(T262="تاخیر",TODAY()-AC262,IF(AND(T262="بسته",AG262<>"",AC262<>"",AG262>AC262),AG262-AC262,0)) -> 0 | V262: =IF(L262="","",VALUE(LEFT(L262,FIND("/",L262)-1))) | W262: =IF(L262="","",VALUE(MID(L262,FIND("/",L262)+1,FIND("/",L262,FIND("/",L262)+1)-FIND("/",L262)-1))) | X262: =IF(L262="","",VALUE(MID(L262,FIND("/",L262,FIND("/",L262)+1)+1,LEN(L262)-FIND("/",L262,FIND("/",L262)+1)))) | Y262: =IF(OR(L262="",V262=""),"",IFERROR(INDEX(لیست‌ها!$Q$3:$Q$53,MATCH(V262,لیست‌ها!$P$3:$P$53,0))+IF(W262<=6,(W262-1)*31+X262,IF(W262<=11,186+(W262-7)*30+X262,336+X262))-1,"")) | Z262: =IF(H262="","",VALUE(LEFT(H262,FIND("/",H262)-1))) | AA262: =IF(H262="","",VALUE(MID(H262,FIND("/",H262)+1,FIND("/",H262,FIND("/",H262)+1)-FIND("/",H262)-1))) | AB262: =IF(H262="","",VALUE(MID(H262,FIND("/",H262,FIND("/",H262)+1)+1,LEN(H262)-FIND("/",H262,FIND("/",H262)+1)))) | AC262: =IF(OR(H262="",Z262=""),"",IFERROR(INDEX(لیست‌ها!$Q$3:$Q$53,MATCH(Z262,لیست‌ها!$P$3:$P$53,0))+IF(AA262<=6,(AA262-1)*31+AB262,IF(AA262<=11,186+(AA262-7)*30+AB262,336+AB262))-1,"")) | AD262: =IF(O262="","",VALUE(LEFT(O262,FIND("/",O262)-1))) | AE262: =IF(O262="","",VALUE(MID(O262,FIND("/",O262)+1,FIND("/",O262,FIND("/",O262)+1)-FIND("/",O262)-1))) | AF262: =IF(O262="","",VALUE(MID(O262,FIND("/",O262,FIND("/",O262)+1)+1,LEN(O262)-FIND("/",O262,FIND("/",O262)+1)))) | AG262: =IF(OR(O262="",AD262=""),"",IFERROR(INDEX(لیست‌ها!$Q$3:$Q$53,MATCH(AD262,لیست‌ها!$P$3:$P$53,0))+IF(AE262<=6,(AE262-1)*31+AF262,IF(AE262<=11,186+(AE262-7)*30+AF262,336+AF262))-1,"")) | AH262: =IF(V262="","",V262&"-"&TEXT(W262,"00")) | AI262: =IF(V262="","",V262*12+W262) | AJ262: =IF(T262="تاخیر",U262+ROW()/100000,"")
A263: 260 | T263: =IF(B263="","",IF(OR(I263<>"",O263<>""),"بسته",IF(AND(L263<>"",V263=""),"خطای فرمت تاریخ ایجاد",IF(AND(H263<>"",Z263=""),"خطای فرمت مهلت",IF(AND(H263<>"",AC263<>"",TODAY()>AC263),"تاخیر",IF(L263<>"","در حال انجام","")))))) | U263: =IF(T263="تاخیر",TODAY()-AC263,IF(AND(T263="بسته",AG263<>"",AC263<>"",AG263>AC263),AG263-AC263,0)) -> 0 | V263: =IF(L263="","",VALUE(LEFT(L263,FIND("/",L263)-1))) | W263: =IF(L263="","",VALUE(MID(L263,FIND("/",L263)+1,FIND("/",L263,FIND("/",L263)+1)-FIND("/",L263)-1))) | X263: =IF(L263="","",VALUE(MID(L263,FIND("/",L263,FIND("/",L263)+1)+1,LEN(L263)-FIND("/",L263,FIND("/",L263)+1)))) | Y263: =IF(OR(L263="",V263=""),"",IFERROR(INDEX(لیست‌ها!$Q$3:$Q$53,MATCH(V263,لیست‌ها!$P$3:$P$53,0))+IF(W263<=6,(W263-1)*31+X263,IF(W263<=11,186+(W263-7)*30+X263,336+X263))-1,"")) | Z263: =IF(H263="","",VALUE(LEFT(H263,FIND("/",H263)-1))) | AA263: =IF(H263="","",VALUE(MID(H263,FIND("/",H263)+1,FIND("/",H263,FIND("/",H263)+1)-FIND("/",H263)-1))) | AB263: =IF(H263="","",VALUE(MID(H263,FIND("/",H263,FIND("/",H263)+1)+1,LEN(H263)-FIND("/",H263,FIND("/",H263)+1)))) | AC263: =IF(OR(H263="",Z263=""),"",IFERROR(INDEX(لیست‌ها!$Q$3:$Q$53,MATCH(Z263,لیست‌ها!$P$3:$P$53,0))+IF(AA263<=6,(AA263-1)*31+AB263,IF(AA263<=11,186+(AA263-7)*30+AB263,336+AB263))-1,"")) | AD263: =IF(O263="","",VALUE(LEFT(O263,FIND("/",O263)-1))) | AE263: =IF(O263="","",VALUE(MID(O263,FIND("/",O263)+1,FIND("/",O263,FIND("/",O263)+1)-FIND("/",O263)-1))) | AF263: =IF(O263="","",VALUE(MID(O263,FIND("/",O263,FIND("/",O263)+1)+1,LEN(O263)-FIND("/",O263,FIND("/",O263)+1)))) | AG263: =IF(OR(O263="",AD263=""),"",IFERROR(INDEX(لیست‌ها!$Q$3:$Q$53,MATCH(AD263,لیست‌ها!$P$3:$P$53,0))+IF(AE263<=6,(AE263-1)*31+AF263,IF(AE263<=11,186+(AE263-7)*30+AF263,336+AF263))-1,"")) | AH263: =IF(V263="","",V263&"-"&TEXT(W263,"00")) | AI263: =IF(V263="","",V263*12+W263) | AJ263: =IF(T263="تاخیر",U263+ROW()/100000,"")
A264: 261 | T264: =IF(B264="","",IF(OR(I264<>"",O264<>""),"بسته",IF(AND(L264<>"",V264=""),"خطای فرمت تاریخ ایجاد",IF(AND(H264<>"",Z264=""),"خطای فرمت مهلت",IF(AND(H264<>"",AC264<>"",TODAY()>AC264),"تاخیر",IF(L264<>"","در حال انجام","")))))) | U264: =IF(T264="تاخیر",TODAY()-AC264,IF(AND(T264="بسته",AG264<>"",AC264<>"",AG264>AC264),AG264-AC264,0)) -> 0 | V264: =IF(L264="","",VALUE(LEFT(L264,FIND("/",L264)-1))) | W264: =IF(L264="","",VALUE(MID(L264,FIND("/",L264)+1,FIND("/",L264,FIND("/",L264)+1)-FIND("/",L264)-1))) | X264: =IF(L264="","",VALUE(MID(L264,FIND("/",L264,FIND("/",L264)+1)+1,LEN(L264)-FIND("/",L264,FIND("/",L264)+1)))) | Y264: =IF(OR(L264="",V264=""),"",IFERROR(INDEX(لیست‌ها!$Q$3:$Q$53,MATCH(V264,لیست‌ها!$P$3:$P$53,0))+IF(W264<=6,(W264-1)*31+X264,IF(W264<=11,186+(W264-7)*30+X264,336+X264))-1,"")) | Z264: =IF(H264="","",VALUE(LEFT(H264,FIND("/",H264)-1))) | AA264: =IF(H264="","",VALUE(MID(H264,FIND("/",H264)+1,FIND("/",H264,FIND("/",H264)+1)-FIND("/",H264)-1))) | AB264: =IF(H264="","",VALUE(MID(H264,FIND("/",H264,FIND("/",H264)+1)+1,LEN(H264)-FIND("/",H264,FIND("/",H264)+1)))) | AC264: =IF(OR(H264="",Z264=""),"",IFERROR(INDEX(لیست‌ها!$Q$3:$Q$53,MATCH(Z264,لیست‌ها!$P$3:$P$53,0))+IF(AA264<=6,(AA264-1)*31+AB264,IF(AA264<=11,186+(AA264-7)*30+AB264,336+AB264))-1,"")) | AD264: =IF(O264="","",VALUE(LEFT(O264,FIND("/",O264)-1))) | AE264: =IF(O264="","",VALUE(MID(O264,FIND("/",O264)+1,FIND("/",O264,FIND("/",O264)+1)-FIND("/",O264)-1))) | AF264: =IF(O264="","",VALUE(MID(O264,FIND("/",O264,FIND("/",O264)+1)+1,LEN(O264)-FIND("/",O264,FIND("/",O264)+1)))) | AG264: =IF(OR(O264="",AD264=""),"",IFERROR(INDEX(لیست‌ها!$Q$3:$Q$53,MATCH(AD264,لیست‌ها!$P$3:$P$53,0))+IF(AE264<=6,(AE264-1)*31+AF264,IF(AE264<=11,186+(AE264-7)*30+AF264,336+AF264))-1,"")) | AH264: =IF(V264="","",V264&"-"&TEXT(W264,"00")) | AI264: =IF(V264="","",V264*12+W264) | AJ264: =IF(T264="تاخیر",U264+ROW()/100000,"")
A265: 262 | T265: =IF(B265="","",IF(OR(I265<>"",O265<>""),"بسته",IF(AND(L265<>"",V265=""),"خطای فرمت تاریخ ایجاد",IF(AND(H265<>"",Z265=""),"خطای فرمت مهلت",IF(AND(H265<>"",AC265<>"",TODAY()>AC265),"تاخیر",IF(L265<>"","در حال انجام","")))))) | U265: =IF(T265="تاخیر",TODAY()-AC265,IF(AND(T265="بسته",AG265<>"",AC265<>"",AG265>AC265),AG265-AC265,0)) -> 0 | V265: =IF(L265="","",VALUE(LEFT(L265,FIND("/",L265)-1))) | W265: =IF(L265="","",VALUE(MID(L265,FIND("/",L265)+1,FIND("/",L265,FIND("/",L265)+1)-FIND("/",L265)-1))) | X265: =IF(L265="","",VALUE(MID(L265,FIND("/",L265,FIND("/",L265)+1)+1,LEN(L265)-FIND("/",L265,FIND("/",L265)+1)))) | Y265: =IF(OR(L265="",V265=""),"",IFERROR(INDEX(لیست‌ها!$Q$3:$Q$53,MATCH(V265,لیست‌ها!$P$3:$P$53,0))+IF(W265<=6,(W265-1)*31+X265,IF(W265<=11,186+(W265-7)*30+X265,336+X265))-1,"")) | Z265: =IF(H265="","",VALUE(LEFT(H265,FIND("/",H265)-1))) | AA265: =IF(H265="","",VALUE(MID(H265,FIND("/",H265)+1,FIND("/",H265,FIND("/",H265)+1)-FIND("/",H265)-1))) | AB265: =IF(H265="","",VALUE(MID(H265,FIND("/",H265,FIND("/",H265)+1)+1,LEN(H265)-FIND("/",H265,FIND("/",H265)+1)))) | AC265: =IF(OR(H265="",Z265=""),"",IFERROR(INDEX(لیست‌ها!$Q$3:$Q$53,MATCH(Z265,لیست‌ها!$P$3:$P$53,0))+IF(AA265<=6,(AA265-1)*31+AB265,IF(AA265<=11,186+(AA265-7)*30+AB265,336+AB265))-1,"")) | AD265: =IF(O265="","",VALUE(LEFT(O265,FIND("/",O265)-1))) | AE265: =IF(O265="","",VALUE(MID(O265,FIND("/",O265)+1,FIND("/",O265,FIND("/",O265)+1)-FIND("/",O265)-1))) | AF265: =IF(O265="","",VALUE(MID(O265,FIND("/",O265,FIND("/",O265)+1)+1,LEN(O265)-FIND("/",O265,FIND("/",O265)+1)))) | AG265: =IF(OR(O265="",AD265=""),"",IFERROR(INDEX(لیست‌ها!$Q$3:$Q$53,MATCH(AD265,لیست‌ها!$P$3:$P$53,0))+IF(AE265<=6,(AE265-1)*31+AF265,IF(AE265<=11,186+(AE265-7)*30+AF265,336+AF265))-1,"")) | AH265: =IF(V265="","",V265&"-"&TEXT(W265,"00")) | AI265: =IF(V265="","",V265*12+W265) | AJ265: =IF(T265="تاخیر",U265+ROW()/100000,"")
A266: 263 | T266: =IF(B266="","",IF(OR(I266<>"",O266<>""),"بسته",IF(AND(L266<>"",V266=""),"خطای فرمت تاریخ ایجاد",IF(AND(H266<>"",Z266=""),"خطای فرمت مهلت",IF(AND(H266<>"",AC266<>"",TODAY()>AC266),"تاخیر",IF(L266<>"","در حال انجام","")))))) | U266: =IF(T266="تاخیر",TODAY()-AC266,IF(AND(T266="بسته",AG266<>"",AC266<>"",AG266>AC266),AG266-AC266,0)) -> 0 | V266: =IF(L266="","",VALUE(LEFT(L266,FIND("/",L266)-1))) | W266: =IF(L266="","",VALUE(MID(L266,FIND("/",L266)+1,FIND("/",L266,FIND("/",L266)+1)-FIND("/",L266)-1))) | X266: =IF(L266="","",VALUE(MID(L266,FIND("/",L266,FIND("/",L266)+1)+1,LEN(L266)-FIND("/",L266,FIND("/",L266)+1)))) | Y266: =IF(OR(L266="",V266=""),"",IFERROR(INDEX(لیست‌ها!$Q$3:$Q$53,MATCH(V266,لیست‌ها!$P$3:$P$53,0))+IF(W266<=6,(W266-1)*31+X266,IF(W266<=11,186+(W266-7)*30+X266,336+X266))-1,"")) | Z266: =IF(H266="","",VALUE(LEFT(H266,FIND("/",H266)-1))) | AA266: =IF(H266="","",VALUE(MID(H266,FIND("/",H266)+1,FIND("/",H266,FIND("/",H266)+1)-FIND("/",H266)-1))) | AB266: =IF(H266="","",VALUE(MID(H266,FIND("/",H266,FIND("/",H266)+1)+1,LEN(H266)-FIND("/",H266,FIND("/",H266)+1)))) | AC266: =IF(OR(H266="",Z266=""),"",IFERROR(INDEX(لیست‌ها!$Q$3:$Q$53,MATCH(Z266,لیست‌ها!$P$3:$P$53,0))+IF(AA266<=6,(AA266-1)*31+AB266,IF(AA266<=11,186+(AA266-7)*30+AB266,336+AB266))-1,"")) | AD266: =IF(O266="","",VALUE(LEFT(O266,FIND("/",O266)-1))) | AE266: =IF(O266="","",VALUE(MID(O266,FIND("/",O266)+1,FIND("/",O266,FIND("/",O266)+1)-FIND("/",O266)-1))) | AF266: =IF(O266="","",VALUE(MID(O266,FIND("/",O266,FIND("/",O266)+1)+1,LEN(O266)-FIND("/",O266,FIND("/",O266)+1)))) | AG266: =IF(OR(O266="",AD266=""),"",IFERROR(INDEX(لیست‌ها!$Q$3:$Q$53,MATCH(AD266,لیست‌ها!$P$3:$P$53,0))+IF(AE266<=6,(AE266-1)*31+AF266,IF(AE266<=11,186+(AE266-7)*30+AF266,336+AF266))-1,"")) | AH266: =IF(V266="","",V266&"-"&TEXT(W266,"00")) | AI266: =IF(V266="","",V266*12+W266) | AJ266: =IF(T266="تاخیر",U266+ROW()/100000,"")
A267: 264 | T267: =IF(B267="","",IF(OR(I267<>"",O267<>""),"بسته",IF(AND(L267<>"",V267=""),"خطای فرمت تاریخ ایجاد",IF(AND(H267<>"",Z267=""),"خطای فرمت مهلت",IF(AND(H267<>"",AC267<>"",TODAY()>AC267),"تاخیر",IF(L267<>"","در حال انجام","")))))) | U267: =IF(T267="تاخیر",TODAY()-AC267,IF(AND(T267="بسته",AG267<>"",AC267<>"",AG267>AC267),AG267-AC267,0)) -> 0 | V267: =IF(L267="","",VALUE(LEFT(L267,FIND("/",L267)-1))) | W267: =IF(L267="","",VALUE(MID(L267,FIND("/",L267)+1,FIND("/",L267,FIND("/",L267)+1)-FIND("/",L267)-1))) | X267: =IF(L267="","",VALUE(MID(L267,FIND("/",L267,FIND("/",L267)+1)+1,LEN(L267)-FIND("/",L267,FIND("/",L267)+1)))) | Y267: =IF(OR(L267="",V267=""),"",IFERROR(INDEX(لیست‌ها!$Q$3:$Q$53,MATCH(V267,لیست‌ها!$P$3:$P$53,0))+IF(W267<=6,(W267-1)*31+X267,IF(W267<=11,186+(W267-7)*30+X267,336+X267))-1,"")) | Z267: =IF(H267="","",VALUE(LEFT(H267,FIND("/",H267)-1))) | AA267: =IF(H267="","",VALUE(MID(H267,FIND("/",H267)+1,FIND("/",H267,FIND("/",H267)+1)-FIND("/",H267)-1))) | AB267: =IF(H267="","",VALUE(MID(H267,FIND("/",H267,FIND("/",H267)+1)+1,LEN(H267)-FIND("/",H267,FIND("/",H267)+1)))) | AC267: =IF(OR(H267="",Z267=""),"",IFERROR(INDEX(لیست‌ها!$Q$3:$Q$53,MATCH(Z267,لیست‌ها!$P$3:$P$53,0))+IF(AA267<=6,(AA267-1)*31+AB267,IF(AA267<=11,186+(AA267-7)*30+AB267,336+AB267))-1,"")) | AD267: =IF(O267="","",VALUE(LEFT(O267,FIND("/",O267)-1))) | AE267: =IF(O267="","",VALUE(MID(O267,FIND("/",O267)+1,FIND("/",O267,FIND("/",O267)+1)-FIND("/",O267)-1))) | AF267: =IF(O267="","",VALUE(MID(O267,FIND("/",O267,FIND("/",O267)+1)+1,LEN(O267)-FIND("/",O267,FIND("/",O267)+1)))) | AG267: =IF(OR(O267="",AD267=""),"",IFERROR(INDEX(لیست‌ها!$Q$3:$Q$53,MATCH(AD267,لیست‌ها!$P$3:$P$53,0))+IF(AE267<=6,(AE267-1)*31+AF267,IF(AE267<=11,186+(AE267-7)*30+AF267,336+AF267))-1,"")) | AH267: =IF(V267="","",V267&"-"&TEXT(W267,"00")) | AI267: =IF(V267="","",V267*12+W267) | AJ267: =IF(T267="تاخیر",U267+ROW()/100000,"")
A268: 265 | T268: =IF(B268="","",IF(OR(I268<>"",O268<>""),"بسته",IF(AND(L268<>"",V268=""),"خطای فرمت تاریخ ایجاد",IF(AND(H268<>"",Z268=""),"خطای فرمت مهلت",IF(AND(H268<>"",AC268<>"",TODAY()>AC268),"تاخیر",IF(L268<>"","در حال انجام","")))))) | U268: =IF(T268="تاخیر",TODAY()-AC268,IF(AND(T268="بسته",AG268<>"",AC268<>"",AG268>AC268),AG268-AC268,0)) -> 0 | V268: =IF(L268="","",VALUE(LEFT(L268,FIND("/",L268)-1))) | W268: =IF(L268="","",VALUE(MID(L268,FIND("/",L268)+1,FIND("/",L268,FIND("/",L268)+1)-FIND("/",L268)-1))) | X268: =IF(L268="","",VALUE(MID(L268,FIND("/",L268,FIND("/",L268)+1)+1,LEN(L268)-FIND("/",L268,FIND("/",L268)+1)))) | Y268: =IF(OR(L268="",V268=""),"",IFERROR(INDEX(لیست‌ها!$Q$3:$Q$53,MATCH(V268,لیست‌ها!$P$3:$P$53,0))+IF(W268<=6,(W268-1)*31+X268,IF(W268<=11,186+(W268-7)*30+X268,336+X268))-1,"")) | Z268: =IF(H268="","",VALUE(LEFT(H268,FIND("/",H268)-1))) | AA268: =IF(H268="","",VALUE(MID(H268,FIND("/",H268)+1,FIND("/",H268,FIND("/",H268)+1)-FIND("/",H268)-1))) | AB268: =IF(H268="","",VALUE(MID(H268,FIND("/",H268,FIND("/",H268)+1)+1,LEN(H268)-FIND("/",H268,FIND("/",H268)+1)))) | AC268: =IF(OR(H268="",Z268=""),"",IFERROR(INDEX(لیست‌ها!$Q$3:$Q$53,MATCH(Z268,لیست‌ها!$P$3:$P$53,0))+IF(AA268<=6,(AA268-1)*31+AB268,IF(AA268<=11,186+(AA268-7)*30+AB268,336+AB268))-1,"")) | AD268: =IF(O268="","",VALUE(LEFT(O268,FIND("/",O268)-1))) | AE268: =IF(O268="","",VALUE(MID(O268,FIND("/",O268)+1,FIND("/",O268,FIND("/",O268)+1)-FIND("/",O268)-1))) | AF268: =IF(O268="","",VALUE(MID(O268,FIND("/",O268,FIND("/",O268)+1)+1,LEN(O268)-FIND("/",O268,FIND("/",O268)+1)))) | AG268: =IF(OR(O268="",AD268=""),"",IFERROR(INDEX(لیست‌ها!$Q$3:$Q$53,MATCH(AD268,لیست‌ها!$P$3:$P$53,0))+IF(AE268<=6,(AE268-1)*31+AF268,IF(AE268<=11,186+(AE268-7)*30+AF268,336+AF268))-1,"")) | AH268: =IF(V268="","",V268&"-"&TEXT(W268,"00")) | AI268: =IF(V268="","",V268*12+W268) | AJ268: =IF(T268="تاخیر",U268+ROW()/100000,"")
A269: 266 | T269: =IF(B269="","",IF(OR(I269<>"",O269<>""),"بسته",IF(AND(L269<>"",V269=""),"خطای فرمت تاریخ ایجاد",IF(AND(H269<>"",Z269=""),"خطای فرمت مهلت",IF(AND(H269<>"",AC269<>"",TODAY()>AC269),"تاخیر",IF(L269<>"","در حال انجام","")))))) | U269: =IF(T269="تاخیر",TODAY()-AC269,IF(AND(T269="بسته",AG269<>"",AC269<>"",AG269>AC269),AG269-AC269,0)) -> 0 | V269: =IF(L269="","",VALUE(LEFT(L269,FIND("/",L269)-1))) | W269: =IF(L269="","",VALUE(MID(L269,FIND("/",L269)+1,FIND("/",L269,FIND("/",L269)+1)-FIND("/",L269)-1))) | X269: =IF(L269="","",VALUE(MID(L269,FIND("/",L269,FIND("/",L269)+1)+1,LEN(L269)-FIND("/",L269,FIND("/",L269)+1)))) | Y269: =IF(OR(L269="",V269=""),"",IFERROR(INDEX(لیست‌ها!$Q$3:$Q$53,MATCH(V269,لیست‌ها!$P$3:$P$53,0))+IF(W269<=6,(W269-1)*31+X269,IF(W269<=11,186+(W269-7)*30+X269,336+X269))-1,"")) | Z269: =IF(H269="","",VALUE(LEFT(H269,FIND("/",H269)-1))) | AA269: =IF(H269="","",VALUE(MID(H269,FIND("/",H269)+1,FIND("/",H269,FIND("/",H269)+1)-FIND("/",H269)-1))) | AB269: =IF(H269="","",VALUE(MID(H269,FIND("/",H269,FIND("/",H269)+1)+1,LEN(H269)-FIND("/",H269,FIND("/",H269)+1)))) | AC269: =IF(OR(H269="",Z269=""),"",IFERROR(INDEX(لیست‌ها!$Q$3:$Q$53,MATCH(Z269,لیست‌ها!$P$3:$P$53,0))+IF(AA269<=6,(AA269-1)*31+AB269,IF(AA269<=11,186+(AA269-7)*30+AB269,336+AB269))-1,"")) | AD269: =IF(O269="","",VALUE(LEFT(O269,FIND("/",O269)-1))) | AE269: =IF(O269="","",VALUE(MID(O269,FIND("/",O269)+1,FIND("/",O269,FIND("/",O269)+1)-FIND("/",O269)-1))) | AF269: =IF(O269="","",VALUE(MID(O269,FIND("/",O269,FIND("/",O269)+1)+1,LEN(O269)-FIND("/",O269,FIND("/",O269)+1)))) | AG269: =IF(OR(O269="",AD269=""),"",IFERROR(INDEX(لیست‌ها!$Q$3:$Q$53,MATCH(AD269,لیست‌ها!$P$3:$P$53,0))+IF(AE269<=6,(AE269-1)*31+AF269,IF(AE269<=11,186+(AE269-7)*30+AF269,336+AF269))-1,"")) | AH269: =IF(V269="","",V269&"-"&TEXT(W269,"00")) | AI269: =IF(V269="","",V269*12+W269) | AJ269: =IF(T269="تاخیر",U269+ROW()/100000,"")
A270: 267 | T270: =IF(B270="","",IF(OR(I270<>"",O270<>""),"بسته",IF(AND(L270<>"",V270=""),"خطای فرمت تاریخ ایجاد",IF(AND(H270<>"",Z270=""),"خطای فرمت مهلت",IF(AND(H270<>"",AC270<>"",TODAY()>AC270),"تاخیر",IF(L270<>"","در حال انجام","")))))) | U270: =IF(T270="تاخیر",TODAY()-AC270,IF(AND(T270="بسته",AG270<>"",AC270<>"",AG270>AC270),AG270-AC270,0)) -> 0 | V270: =IF(L270="","",VALUE(LEFT(L270,FIND("/",L270)-1))) | W270: =IF(L270="","",VALUE(MID(L270,FIND("/",L270)+1,FIND("/",L270,FIND("/",L270)+1)-FIND("/",L270)-1))) | X270: =IF(L270="","",VALUE(MID(L270,FIND("/",L270,FIND("/",L270)+1)+1,LEN(L270)-FIND("/",L270,FIND("/",L270)+1)))) | Y270: =IF(OR(L270="",V270=""),"",IFERROR(INDEX(لیست‌ها!$Q$3:$Q$53,MATCH(V270,لیست‌ها!$P$3:$P$53,0))+IF(W270<=6,(W270-1)*31+X270,IF(W270<=11,186+(W270-7)*30+X270,336+X270))-1,"")) | Z270: =IF(H270="","",VALUE(LEFT(H270,FIND("/",H270)-1))) | AA270: =IF(H270="","",VALUE(MID(H270,FIND("/",H270)+1,FIND("/",H270,FIND("/",H270)+1)-FIND("/",H270)-1))) | AB270: =IF(H270="","",VALUE(MID(H270,FIND("/",H270,FIND("/",H270)+1)+1,LEN(H270)-FIND("/",H270,FIND("/",H270)+1)))) | AC270: =IF(OR(H270="",Z270=""),"",IFERROR(INDEX(لیست‌ها!$Q$3:$Q$53,MATCH(Z270,لیست‌ها!$P$3:$P$53,0))+IF(AA270<=6,(AA270-1)*31+AB270,IF(AA270<=11,186+(AA270-7)*30+AB270,336+AB270))-1,"")) | AD270: =IF(O270="","",VALUE(LEFT(O270,FIND("/",O270)-1))) | AE270: =IF(O270="","",VALUE(MID(O270,FIND("/",O270)+1,FIND("/",O270,FIND("/",O270)+1)-FIND("/",O270)-1))) | AF270: =IF(O270="","",VALUE(MID(O270,FIND("/",O270,FIND("/",O270)+1)+1,LEN(O270)-FIND("/",O270,FIND("/",O270)+1)))) | AG270: =IF(OR(O270="",AD270=""),"",IFERROR(INDEX(لیست‌ها!$Q$3:$Q$53,MATCH(AD270,لیست‌ها!$P$3:$P$53,0))+IF(AE270<=6,(AE270-1)*31+AF270,IF(AE270<=11,186+(AE270-7)*30+AF270,336+AF270))-1,"")) | AH270: =IF(V270="","",V270&"-"&TEXT(W270,"00")) | AI270: =IF(V270="","",V270*12+W270) | AJ270: =IF(T270="تاخیر",U270+ROW()/100000,"")
